# Shell: exterior walls, floor slabs and columns
# generated by tools/build_functions.py -- do not edit by hand


# ground floor walls
fill ~-11 ~1 ~-26 ~5 ~4 ~-26 minecraft:white_concrete
fill ~-11 ~1 ~-10 ~5 ~4 ~-10 minecraft:white_concrete
fill ~-11 ~1 ~-26 ~-11 ~4 ~-10 minecraft:white_concrete
fill ~5 ~1 ~-26 ~5 ~4 ~-10 minecraft:white_concrete

# dark trim band at the top of the ground floor
fill ~-11 ~4 ~-26 ~5 ~4 ~-26 minecraft:polished_blackstone
fill ~-11 ~4 ~-10 ~5 ~4 ~-10 minecraft:polished_blackstone
fill ~-11 ~4 ~-26 ~-11 ~4 ~-10 minecraft:polished_blackstone
fill ~5 ~4 ~-26 ~5 ~4 ~-10 minecraft:polished_blackstone

# first floor slab (= ground floor ceiling) + overhang
fill ~-12 ~5 ~-27 ~6 ~5 ~-8 minecraft:smooth_quartz
fill ~-10 ~5 ~-25 ~4 ~5 ~-11 minecraft:quartz_block

# upper floor walls
fill ~-11 ~6 ~-26 ~5 ~9 ~-26 minecraft:white_concrete
fill ~-11 ~6 ~-10 ~5 ~9 ~-10 minecraft:white_concrete
fill ~-11 ~6 ~-26 ~-11 ~9 ~-10 minecraft:white_concrete
fill ~5 ~6 ~-26 ~5 ~9 ~-10 minecraft:white_concrete
fill ~-11 ~9 ~-26 ~5 ~9 ~-26 minecraft:polished_blackstone
fill ~-11 ~9 ~-10 ~5 ~9 ~-10 minecraft:polished_blackstone
fill ~-11 ~9 ~-26 ~-11 ~9 ~-10 minecraft:polished_blackstone
fill ~5 ~9 ~-26 ~5 ~9 ~-10 minecraft:polished_blackstone

# roof deck + overhang lip
fill ~-12 ~10 ~-27 ~6 ~10 ~-8 minecraft:smooth_quartz
fill ~-10 ~10 ~-25 ~4 ~10 ~-11 minecraft:quartz_block

# corner columns run the full height
fill ~-11 ~1 ~-26 ~-11 ~9 ~-26 minecraft:quartz_pillar
fill ~-11 ~1 ~-10 ~-11 ~9 ~-10 minecraft:quartz_pillar
fill ~5 ~1 ~-26 ~5 ~9 ~-26 minecraft:quartz_pillar
fill ~5 ~1 ~-10 ~5 ~9 ~-10 minecraft:quartz_pillar

# porch columns holding the balcony
fill ~-10 ~1 ~-8 ~-10 ~4 ~-8 minecraft:quartz_pillar
setblock ~-10 ~4 ~-8 minecraft:chiseled_quartz_block
fill ~-6 ~1 ~-8 ~-6 ~4 ~-8 minecraft:quartz_pillar
setblock ~-6 ~4 ~-8 minecraft:chiseled_quartz_block
fill ~ ~1 ~-8 ~ ~4 ~-8 minecraft:quartz_pillar
setblock ~ ~4 ~-8 minecraft:chiseled_quartz_block
fill ~4 ~1 ~-8 ~4 ~4 ~-8 minecraft:quartz_pillar
setblock ~4 ~4 ~-8 minecraft:chiseled_quartz_block

# gold cornice detail
setblock ~-12 ~10 ~-27 minecraft:gold_block
setblock ~-12 ~10 ~-8 minecraft:gold_block
setblock ~6 ~10 ~-27 minecraft:gold_block
setblock ~6 ~10 ~-8 minecraft:gold_block
