# Glazing: floor to ceiling windows, doors, balcony
# generated by tools/build_functions.py -- do not edit by hand


# ground floor front windows
fill ~-9 ~2 ~-10 ~-5 ~3 ~-10 minecraft:glass
fill ~-1 ~2 ~-10 ~3 ~3 ~-10 minecraft:glass

# front entrance: double doors under a gold arch
fill ~-4 ~1 ~-10 ~-2 ~3 ~-10 minecraft:air
fill ~-4 ~3 ~-10 ~-2 ~3 ~-10 minecraft:gold_block
setblock ~-4 ~1 ~-10 minecraft:dark_oak_door ["direction":1,"door_hinge_bit":false,"open_bit":false,"upper_block_bit":false]
setblock ~-4 ~2 ~-10 minecraft:dark_oak_door ["direction":1,"door_hinge_bit":false,"open_bit":false,"upper_block_bit":true]
setblock ~-3 ~1 ~-10 minecraft:dark_oak_door ["direction":1,"door_hinge_bit":false,"open_bit":false,"upper_block_bit":false]
setblock ~-3 ~2 ~-10 minecraft:dark_oak_door ["direction":1,"door_hinge_bit":false,"open_bit":false,"upper_block_bit":true]
setblock ~-2 ~1 ~-10 minecraft:glass
setblock ~-2 ~2 ~-10 minecraft:glass

# east side glass wall facing the pool + patio door
fill ~5 ~2 ~-17 ~5 ~3 ~-11 minecraft:glass
fill ~5 ~1 ~-15 ~5 ~2 ~-14 minecraft:air
setblock ~5 ~1 ~-15 minecraft:dark_oak_door ["direction":0,"door_hinge_bit":false,"open_bit":false,"upper_block_bit":false]
setblock ~5 ~2 ~-15 minecraft:dark_oak_door ["direction":0,"door_hinge_bit":false,"open_bit":false,"upper_block_bit":true]
setblock ~5 ~1 ~-14 minecraft:dark_oak_door ["direction":0,"door_hinge_bit":false,"open_bit":false,"upper_block_bit":false]
setblock ~5 ~2 ~-14 minecraft:dark_oak_door ["direction":0,"door_hinge_bit":false,"open_bit":false,"upper_block_bit":true]

# west and north ground floor windows
fill ~-11 ~2 ~-17 ~-11 ~3 ~-12 minecraft:glass
fill ~-1 ~2 ~-26 ~3 ~3 ~-26 minecraft:glass
fill ~-9 ~2 ~-26 ~-6 ~3 ~-26 minecraft:glass

# upper floor: panoramic glazing
fill ~-9 ~6 ~-10 ~3 ~8 ~-10 minecraft:glass
fill ~5 ~6 ~-24 ~5 ~8 ~-12 minecraft:glass
fill ~-11 ~6 ~-24 ~-11 ~8 ~-12 minecraft:glass
fill ~-9 ~6 ~-26 ~3 ~7 ~-26 minecraft:glass

# balcony over the porch + doors out to it
fill ~-10 ~5 ~-9 ~4 ~5 ~-8 minecraft:smooth_quartz
fill ~-4 ~6 ~-10 ~-2 ~7 ~-10 minecraft:air
setblock ~-4 ~6 ~-10 minecraft:dark_oak_door ["direction":1,"door_hinge_bit":false,"open_bit":false,"upper_block_bit":false]
setblock ~-4 ~7 ~-10 minecraft:dark_oak_door ["direction":1,"door_hinge_bit":false,"open_bit":false,"upper_block_bit":true]
setblock ~-3 ~6 ~-10 minecraft:dark_oak_door ["direction":1,"door_hinge_bit":false,"open_bit":false,"upper_block_bit":false]
setblock ~-3 ~7 ~-10 minecraft:dark_oak_door ["direction":1,"door_hinge_bit":false,"open_bit":false,"upper_block_bit":true]
setblock ~-2 ~6 ~-10 minecraft:glass
setblock ~-2 ~7 ~-10 minecraft:glass

# balcony railing
fill ~-10 ~6 ~-8 ~4 ~6 ~-8 minecraft:glass_pane
fill ~-10 ~6 ~-9 ~-10 ~6 ~-8 minecraft:glass_pane
fill ~4 ~6 ~-9 ~4 ~6 ~-8 minecraft:glass_pane
