# Roof terrace: hot tub, pergola, sun loungers, railing
# generated by tools/build_functions.py -- do not edit by hand


# glass railing all the way round the roof
fill ~-12 ~11 ~-27 ~6 ~11 ~-27 minecraft:glass_pane
fill ~-12 ~11 ~-8 ~6 ~11 ~-8 minecraft:glass_pane
fill ~-12 ~11 ~-27 ~-12 ~11 ~-8 minecraft:glass_pane
fill ~6 ~11 ~-27 ~6 ~11 ~-8 minecraft:glass_pane
fill ~-12 ~11 ~-27 ~-12 ~12 ~-27 minecraft:quartz_pillar
setblock ~-12 ~13 ~-27 minecraft:sea_lantern
fill ~-12 ~11 ~-8 ~-12 ~12 ~-8 minecraft:quartz_pillar
setblock ~-12 ~13 ~-8 minecraft:sea_lantern
fill ~6 ~11 ~-27 ~6 ~12 ~-27 minecraft:quartz_pillar
setblock ~6 ~13 ~-27 minecraft:sea_lantern
fill ~6 ~11 ~-8 ~6 ~12 ~-8 minecraft:quartz_pillar
setblock ~6 ~13 ~-8 minecraft:sea_lantern

# stair housing so the roof access is covered and nobody falls down the shaft
fill ~-6 ~11 ~-24 ~-3 ~13 ~-24 minecraft:white_concrete
fill ~-6 ~11 ~-17 ~-3 ~13 ~-17 minecraft:white_concrete
fill ~-6 ~11 ~-24 ~-6 ~13 ~-17 minecraft:white_concrete
fill ~-3 ~11 ~-24 ~-3 ~13 ~-17 minecraft:white_concrete
fill ~-6 ~14 ~-24 ~-3 ~14 ~-17 minecraft:smooth_quartz
fill ~-5 ~11 ~-17 ~-4 ~12 ~-17 minecraft:air
fill ~-6 ~12 ~-24 ~-3 ~12 ~-24 minecraft:glass
setblock ~-5 ~13 ~-21 minecraft:sea_lantern

# hot tub
fill ~ ~11 ~-16 ~3 ~11 ~-13 minecraft:smooth_quartz
fill ~1 ~11 ~-15 ~2 ~11 ~-14 minecraft:water
setblock ~ ~11 ~-16 minecraft:sea_lantern
setblock ~3 ~11 ~-13 minecraft:sea_lantern
setblock ~4 ~11 ~-15 minecraft:quartz_stairs ["weirdo_direction":0,"upside_down_bit":false]
setblock ~4 ~11 ~-14 minecraft:quartz_stairs ["weirdo_direction":0,"upside_down_bit":false]

# pergola lounge
fill ~-9 ~11 ~-16 ~-9 ~13 ~-16 minecraft:dark_oak_fence
fill ~-9 ~11 ~-12 ~-9 ~13 ~-12 minecraft:dark_oak_fence
fill ~-6 ~11 ~-16 ~-6 ~13 ~-16 minecraft:dark_oak_fence
fill ~-6 ~11 ~-12 ~-6 ~13 ~-12 minecraft:dark_oak_fence
fill ~-9 ~14 ~-16 ~-6 ~14 ~-12 minecraft:dark_oak_fence
fill ~-9 ~11 ~-15 ~-6 ~11 ~-13 minecraft:light_gray_carpet
setblock ~-8 ~11 ~-14 minecraft:quartz_stairs ["weirdo_direction":3,"upside_down_bit":false]
setblock ~-7 ~11 ~-14 minecraft:quartz_stairs ["weirdo_direction":3,"upside_down_bit":false]
setblock ~-8 ~11 ~-15 minecraft:quartz_slab

# planters and deck lighting
setblock ~-10 ~11 ~-24 minecraft:smooth_quartz
setblock ~-10 ~12 ~-24 minecraft:oak_leaves
setblock ~-10 ~11 ~-20 minecraft:smooth_quartz
setblock ~-10 ~12 ~-20 minecraft:oak_leaves
setblock ~4 ~11 ~-24 minecraft:smooth_quartz
setblock ~4 ~12 ~-24 minecraft:oak_leaves
setblock ~4 ~11 ~-20 minecraft:smooth_quartz
setblock ~4 ~12 ~-20 minecraft:oak_leaves
setblock ~-10 ~11 ~-11 minecraft:smooth_quartz
setblock ~-10 ~12 ~-11 minecraft:oak_leaves
setblock ~4 ~11 ~-11 minecraft:smooth_quartz
setblock ~4 ~12 ~-11 minecraft:oak_leaves
setblock ~-9 ~10 ~-25 minecraft:sea_lantern
setblock ~3 ~10 ~-25 minecraft:sea_lantern
setblock ~-9 ~10 ~-10 minecraft:sea_lantern
setblock ~3 ~10 ~-10 minecraft:sea_lantern
setblock ~-3 ~10 ~-10 minecraft:sea_lantern
