# East wing: swimming pool, deck, loungers
# generated by tools/build_functions.py -- do not edit by hand


# pool deck
fill ~6 ~-1 ~-27 ~14 ~-1 ~-8 minecraft:smooth_quartz
fill ~6 ~-2 ~-27 ~14 ~-2 ~-8 minecraft:polished_blackstone

# pool basin
fill ~8 ~-5 ~-23 ~13 ~-1 ~-13 minecraft:quartz_block
fill ~9 ~-4 ~-22 ~12 ~-1 ~-14 minecraft:water

# underwater lighting
setblock ~8 ~-3 ~-21 minecraft:sea_lantern
setblock ~13 ~-3 ~-21 minecraft:sea_lantern
setblock ~8 ~-3 ~-18 minecraft:sea_lantern
setblock ~13 ~-3 ~-18 minecraft:sea_lantern
setblock ~8 ~-3 ~-15 minecraft:sea_lantern
setblock ~13 ~-3 ~-15 minecraft:sea_lantern
setblock ~11 ~-5 ~-18 minecraft:gold_block

# pool ladder + diving board
fill ~9 ~-4 ~-14 ~9 ~-1 ~-14 minecraft:ladder ["facing_direction":2]
fill ~10 ~ ~-25 ~11 ~ ~-24 minecraft:quartz_slab

# sun loungers and parasols along the west edge of the deck
setblock ~6 ~ ~-21 minecraft:quartz_stairs ["weirdo_direction":0,"upside_down_bit":false]
setblock ~7 ~ ~-21 minecraft:quartz_slab
setblock ~6 ~ ~-18 minecraft:quartz_stairs ["weirdo_direction":0,"upside_down_bit":false]
setblock ~7 ~ ~-18 minecraft:quartz_slab
setblock ~6 ~ ~-15 minecraft:quartz_stairs ["weirdo_direction":0,"upside_down_bit":false]
setblock ~7 ~ ~-15 minecraft:quartz_slab
fill ~6 ~ ~-20 ~6 ~1 ~-20 minecraft:dark_oak_fence
fill ~6 ~2 ~-21 ~7 ~2 ~-19 minecraft:white_concrete
fill ~6 ~ ~-16 ~6 ~1 ~-16 minecraft:dark_oak_fence
fill ~6 ~2 ~-17 ~7 ~2 ~-15 minecraft:white_concrete

# outdoor bar
fill ~7 ~ ~-12 ~12 ~ ~-12 minecraft:smooth_quartz
fill ~7 ~1 ~-12 ~12 ~1 ~-12 minecraft:quartz_slab
setblock ~8 ~ ~-11 minecraft:barrel
setblock ~10 ~ ~-11 minecraft:brewing_stand
setblock ~12 ~ ~-11 minecraft:barrel
fill ~7 ~2 ~-12 ~12 ~2 ~-12 minecraft:sea_lantern

# deck lighting
fill ~7 ~ ~-25 ~7 ~2 ~-25 minecraft:quartz_pillar
setblock ~7 ~3 ~-25 minecraft:sea_lantern
fill ~14 ~ ~-25 ~14 ~2 ~-25 minecraft:quartz_pillar
setblock ~14 ~3 ~-25 minecraft:sea_lantern
fill ~14 ~ ~-10 ~14 ~2 ~-10 minecraft:quartz_pillar
setblock ~14 ~3 ~-10 minecraft:sea_lantern
fill ~7 ~ ~-10 ~7 ~2 ~-10 minecraft:quartz_pillar
setblock ~7 ~3 ~-10 minecraft:sea_lantern
