# Grounds: driveway, fountain, gardens, perimeter wall
# generated by tools/build_functions.py -- do not edit by hand


# driveway and front path
fill ~-4 ~-1 ~-7 ~-2 ~-1 ~-1 minecraft:smooth_quartz
fill ~-1 ~-1 ~-5 ~5 ~-1 ~-2 minecraft:polished_blackstone

# fountain
fill ~-10 ~-1 ~-6 ~-6 ~-1 ~-2 minecraft:smooth_quartz
fill ~-10 ~ ~-6 ~-6 ~ ~-6 minecraft:quartz_block
fill ~-10 ~ ~-2 ~-6 ~ ~-2 minecraft:quartz_block
fill ~-10 ~ ~-6 ~-10 ~ ~-2 minecraft:quartz_block
fill ~-6 ~ ~-6 ~-6 ~ ~-2 minecraft:quartz_block
fill ~-9 ~ ~-5 ~-7 ~ ~-3 minecraft:water
fill ~-8 ~ ~-4 ~-8 ~2 ~-4 minecraft:quartz_pillar
setblock ~-8 ~3 ~-4 minecraft:sea_lantern
setblock ~-8 ~1 ~-4 minecraft:chiseled_quartz_block

# perimeter wall with gold posts, gate left open at the front
fill ~-15 ~ ~-31 ~15 ~ ~-31 minecraft:quartz_block
fill ~-15 ~ ~-1 ~15 ~ ~-1 minecraft:quartz_block
fill ~-15 ~ ~-31 ~-15 ~ ~-1 minecraft:quartz_block
fill ~15 ~ ~-31 ~15 ~ ~-1 minecraft:quartz_block
fill ~-15 ~1 ~-31 ~15 ~1 ~-31 minecraft:glass_pane
fill ~-15 ~1 ~-1 ~15 ~1 ~-1 minecraft:glass_pane
fill ~-15 ~1 ~-31 ~-15 ~1 ~-1 minecraft:glass_pane
fill ~15 ~1 ~-31 ~15 ~1 ~-1 minecraft:glass_pane
fill ~-4 ~ ~-1 ~-2 ~1 ~-1 minecraft:air
fill ~-15 ~ ~-31 ~-15 ~2 ~-31 minecraft:quartz_pillar
setblock ~-15 ~3 ~-31 minecraft:gold_block
fill ~-15 ~ ~-1 ~-15 ~2 ~-1 minecraft:quartz_pillar
setblock ~-15 ~3 ~-1 minecraft:gold_block
fill ~15 ~ ~-31 ~15 ~2 ~-31 minecraft:quartz_pillar
setblock ~15 ~3 ~-31 minecraft:gold_block
fill ~15 ~ ~-1 ~15 ~2 ~-1 minecraft:quartz_pillar
setblock ~15 ~3 ~-1 minecraft:gold_block
fill ~-5 ~ ~-1 ~-5 ~2 ~-1 minecraft:quartz_pillar
setblock ~-5 ~3 ~-1 minecraft:sea_lantern
fill ~-1 ~ ~-1 ~-1 ~2 ~-1 minecraft:quartz_pillar
setblock ~-1 ~3 ~-1 minecraft:sea_lantern

# hedges and trees
fill ~-13 ~ ~-7 ~-6 ~ ~-7 minecraft:oak_leaves
fill ~ ~ ~-7 ~5 ~ ~-7 minecraft:oak_leaves
fill ~-1 ~ ~-30 ~13 ~ ~-30 minecraft:oak_leaves
fill ~-12 ~ ~-4 ~-12 ~4 ~-4 minecraft:oak_log
fill ~-14 ~2 ~-6 ~-10 ~3 ~-2 minecraft:oak_leaves keep
fill ~-13 ~4 ~-5 ~-11 ~4 ~-3 minecraft:oak_leaves keep
setblock ~-12 ~5 ~-4 minecraft:oak_leaves
fill ~-12 ~ ~-4 ~-12 ~4 ~-4 minecraft:oak_log
fill ~-13 ~ ~-14 ~-13 ~4 ~-14 minecraft:oak_log
fill ~-15 ~2 ~-16 ~-11 ~3 ~-12 minecraft:oak_leaves keep
fill ~-14 ~4 ~-15 ~-12 ~4 ~-13 minecraft:oak_leaves keep
setblock ~-13 ~5 ~-14 minecraft:oak_leaves
fill ~-13 ~ ~-14 ~-13 ~4 ~-14 minecraft:oak_log
fill ~-13 ~ ~-21 ~-13 ~4 ~-21 minecraft:oak_log
fill ~-15 ~2 ~-23 ~-11 ~3 ~-19 minecraft:oak_leaves keep
fill ~-14 ~4 ~-22 ~-12 ~4 ~-20 minecraft:oak_leaves keep
setblock ~-13 ~5 ~-21 minecraft:oak_leaves
fill ~-13 ~ ~-21 ~-13 ~4 ~-21 minecraft:oak_log
fill ~-12 ~ ~-29 ~-12 ~4 ~-29 minecraft:oak_log
fill ~-14 ~2 ~-31 ~-10 ~3 ~-27 minecraft:oak_leaves keep
fill ~-13 ~4 ~-30 ~-11 ~4 ~-28 minecraft:oak_leaves keep
setblock ~-12 ~5 ~-29 minecraft:oak_leaves
fill ~-12 ~ ~-29 ~-12 ~4 ~-29 minecraft:oak_log
fill ~10 ~ ~-29 ~10 ~4 ~-29 minecraft:oak_log
fill ~8 ~2 ~-31 ~12 ~3 ~-27 minecraft:oak_leaves keep
fill ~9 ~4 ~-30 ~11 ~4 ~-28 minecraft:oak_leaves keep
setblock ~10 ~5 ~-29 minecraft:oak_leaves
fill ~10 ~ ~-29 ~10 ~4 ~-29 minecraft:oak_log

# path lamps
fill ~-5 ~ ~-6 ~-5 ~2 ~-6 minecraft:quartz_pillar
setblock ~-5 ~3 ~-6 minecraft:sea_lantern
fill ~-1 ~ ~-6 ~-1 ~2 ~-6 minecraft:quartz_pillar
setblock ~-1 ~3 ~-6 minecraft:sea_lantern
fill ~-5 ~ ~-3 ~-5 ~2 ~-3 minecraft:quartz_pillar
setblock ~-5 ~3 ~-3 minecraft:sea_lantern
fill ~-1 ~ ~-3 ~-1 ~2 ~-3 minecraft:quartz_pillar
setblock ~-1 ~3 ~-3 minecraft:sea_lantern

# back garden seating
fill ~-9 ~-1 ~-30 ~-3 ~-1 ~-28 minecraft:smooth_quartz
setblock ~-7 ~ ~-29 minecraft:quartz_stairs ["weirdo_direction":2,"upside_down_bit":false]
setblock ~-6 ~ ~-29 minecraft:quartz_stairs ["weirdo_direction":2,"upside_down_bit":false]
setblock ~-5 ~ ~-29 minecraft:quartz_stairs ["weirdo_direction":2,"upside_down_bit":false]
setblock ~-4 ~ ~-29 minecraft:campfire
