fill ~-5 ~1 ~-4 ~5 ~8 ~4 air
fill ~-5 ~-4 ~-4 ~5 ~0 ~4 cobblestone
fill ~-5 ~1 ~-4 ~5 ~5 ~4 stone_bricks hollow
fill ~-5 ~1 ~-4 ~-5 ~4 ~-4 oak_log
fill ~-5 ~1 ~4 ~-5 ~4 ~4 oak_log
fill ~5 ~1 ~-4 ~5 ~4 ~-4 oak_log
fill ~5 ~1 ~4 ~5 ~4 ~4 oak_log
fill ~-6 ~6 ~-5 ~6 ~6 ~5 dark_oak_planks
fill ~-1 ~1 ~-4 ~1 ~2 ~-4 air
setblock ~ ~1 ~-4 oak_door["direction"=0,"upper_block_bit"=false]
setblock ~ ~2 ~-4 oak_door["direction"=0,"upper_block_bit"=true]
setblock ~-5 ~2 ~-1 glass_pane
setblock ~-5 ~2 ~1 glass_pane
setblock ~5 ~2 ~-1 glass_pane
setblock ~5 ~2 ~1 glass_pane
setblock ~-1 ~2 ~-4 glass_pane
setblock ~1 ~2 ~-4 glass_pane
setblock ~-1 ~2 ~4 glass_pane
setblock ~1 ~2 ~4 glass_pane
setblock ~-4 ~4 ~-3 glowstone
setblock ~-4 ~4 ~3 glowstone
setblock ~4 ~4 ~-3 glowstone
setblock ~4 ~4 ~3 glowstone
setblock ~-3 ~1 ~2 bed["direction"=0,"head_piece_bit"=false]
setblock ~-3 ~1 ~3 bed["direction"=0,"head_piece_bit"=true]
setblock ~0 ~1 ~2 bed["direction"=0,"head_piece_bit"=false]
setblock ~0 ~1 ~3 bed["direction"=0,"head_piece_bit"=true]
setblock ~3 ~1 ~2 bed["direction"=0,"head_piece_bit"=false]
setblock ~3 ~1 ~3 bed["direction"=0,"head_piece_bit"=true]
setblock ~-4 ~1 ~-3 chest
setblock ~4 ~1 ~-3 chest
setblock ~ ~1 ~-3 crafting_table
