fill ~-4 ~1 ~-4 ~4 ~8 ~4 air
fill ~-4 ~-4 ~-4 ~4 ~0 ~4 cobblestone
fill ~-4 ~1 ~-4 ~4 ~5 ~4 quartz_block hollow
fill ~-4 ~1 ~-4 ~-4 ~4 ~-4 oak_log
fill ~-4 ~1 ~4 ~-4 ~4 ~4 oak_log
fill ~4 ~1 ~-4 ~4 ~4 ~-4 oak_log
fill ~4 ~1 ~4 ~4 ~4 ~4 oak_log
fill ~-5 ~6 ~-5 ~5 ~6 ~5 red_wool
fill ~-1 ~1 ~-4 ~1 ~2 ~-4 air
setblock ~ ~1 ~-4 oak_door["direction"=0,"upper_block_bit"=false]
setblock ~ ~2 ~-4 oak_door["direction"=0,"upper_block_bit"=true]
setblock ~-4 ~2 ~-1 glass_pane
setblock ~-4 ~2 ~1 glass_pane
setblock ~4 ~2 ~-1 glass_pane
setblock ~4 ~2 ~1 glass_pane
setblock ~-1 ~2 ~-4 glass_pane
setblock ~1 ~2 ~-4 glass_pane
setblock ~-1 ~2 ~4 glass_pane
setblock ~1 ~2 ~4 glass_pane
setblock ~-3 ~4 ~-3 glowstone
setblock ~-3 ~4 ~3 glowstone
setblock ~3 ~4 ~-3 glowstone
setblock ~3 ~4 ~3 glowstone
setblock ~-2 ~1 ~1 bed["direction"=0,"head_piece_bit"=false]
setblock ~-2 ~1 ~2 bed["direction"=0,"head_piece_bit"=true]
setblock ~2 ~1 ~1 bed["direction"=0,"head_piece_bit"=false]
setblock ~2 ~1 ~2 bed["direction"=0,"head_piece_bit"=true]
setblock ~ ~1 ~3 brewing_stand
setblock ~-3 ~1 ~-2 cauldron
setblock ~3 ~1 ~-2 chest
