fill ~-38 ~-3 ~-38 ~38 ~0 ~-38 stone_bricks
fill ~-38 ~-3 ~38 ~38 ~0 ~38 stone_bricks
fill ~-38 ~-3 ~-37 ~-38 ~0 ~37 stone_bricks
fill ~38 ~-3 ~-37 ~38 ~0 ~37 stone_bricks
fill ~-38 ~1 ~-38 ~38 ~5 ~-38 stone_bricks
fill ~-38 ~1 ~38 ~38 ~5 ~38 stone_bricks
fill ~-38 ~1 ~-37 ~-38 ~5 ~37 stone_bricks
fill ~38 ~1 ~-37 ~38 ~5 ~37 stone_bricks
fill ~-38 ~6 ~-38 ~38 ~6 ~-38 cobblestone_wall
fill ~-38 ~6 ~38 ~38 ~6 ~38 cobblestone_wall
fill ~-38 ~6 ~-37 ~-38 ~6 ~37 cobblestone_wall
fill ~38 ~6 ~-37 ~38 ~6 ~37 cobblestone_wall
fill ~-3 ~1 ~-38 ~3 ~4 ~-38 air
setblock ~-30 ~7 ~-38 glowstone
setblock ~-30 ~7 ~38 glowstone
setblock ~-15 ~7 ~-38 glowstone
setblock ~-15 ~7 ~38 glowstone
setblock ~0 ~7 ~-38 glowstone
setblock ~0 ~7 ~38 glowstone
setblock ~15 ~7 ~-38 glowstone
setblock ~15 ~7 ~38 glowstone
setblock ~30 ~7 ~-38 glowstone
setblock ~30 ~7 ~38 glowstone
setblock ~-38 ~7 ~-30 glowstone
setblock ~38 ~7 ~-30 glowstone
setblock ~-38 ~7 ~-15 glowstone
setblock ~38 ~7 ~-15 glowstone
setblock ~-38 ~7 ~0 glowstone
setblock ~38 ~7 ~0 glowstone
setblock ~-38 ~7 ~15 glowstone
setblock ~38 ~7 ~15 glowstone
setblock ~-38 ~7 ~30 glowstone
setblock ~38 ~7 ~30 glowstone
