# part_79.mcfunction - generated by tools/gen_mansion.py, do not edit
# Relative coordinates only; run via execute positioned <x> <y> <z>
# (continued: 19 security room + secret room A)
setblock ~8 ~-9 ~-19 minecraft:chest["minecraft:cardinal_direction":"south"]
setblock ~8 ~-8 ~-19 minecraft:iron_block
setblock ~10 ~-9 ~-19 minecraft:chest["minecraft:cardinal_direction":"south"]
setblock ~10 ~-8 ~-19 minecraft:iron_block
setblock ~12 ~-9 ~-19 minecraft:chest["minecraft:cardinal_direction":"south"]
setblock ~12 ~-8 ~-19 minecraft:iron_block
setblock ~14 ~-9 ~-19 minecraft:chest["minecraft:cardinal_direction":"south"]
setblock ~14 ~-8 ~-19 minecraft:iron_block
setblock ~9 ~-9 ~-16 minecraft:ender_chest
setblock ~13 ~-9 ~-16 minecraft:beacon
setblock ~11 ~-9 ~-17 myc:control_panel
fill ~8 ~-9 ~-20 ~14 ~-9 ~-20 minecraft:netherite_block
setblock ~11 ~-4 ~-17 minecraft:sea_lantern
setblock ~8 ~-4 ~-15 minecraft:redstone_lamp
setblock ~11 ~-4 ~-15 minecraft:redstone_lamp
setblock ~14 ~-4 ~-15 minecraft:redstone_lamp
setblock ~7 ~-4 ~-10 minecraft:sea_lantern
setblock ~11 ~-4 ~-10 minecraft:sea_lantern
setblock ~15 ~-4 ~-10 minecraft:sea_lantern
setblock ~7 ~-4 ~-5 minecraft:redstone_lamp
setblock ~11 ~-4 ~-5 minecraft:redstone_lamp
setblock ~15 ~-4 ~-5 minecraft:redstone_lamp
setblock ~6 ~-7 ~-4 myc:alarm_light
setblock ~16 ~-7 ~-12 myc:alarm_light
# --- 20 laboratory + secret room B ---
fill ~-16 ~-10 ~-24 ~-6 ~-10 ~-13 minecraft:calcite
fill ~-16 ~-3 ~-24 ~-6 ~-3 ~-13 minecraft:calcite
fill ~-16 ~-9 ~-13 ~-6 ~-4 ~-13 minecraft:polished_deepslate
fill ~-16 ~-9 ~-24 ~-6 ~-4 ~-24 minecraft:polished_deepslate
fill ~-16 ~-9 ~-24 ~-16 ~-4 ~-13 minecraft:polished_deepslate
fill ~-6 ~-9 ~-24 ~-6 ~-4 ~-13 minecraft:polished_deepslate
fill ~-6 ~-9 ~-18 ~-6 ~-7 ~-16 minecraft:air
setblock ~-6 ~-9 ~-17 minecraft:iron_door["direction":3,"door_hinge_bit":false,"open_bit":false,"upper_block_bit":false]
setblock ~-6 ~-8 ~-17 minecraft:iron_door["direction":3,"door_hinge_bit":false,"open_bit":false,"upper_block_bit":true]
# Clean-room cladding
fill ~-16 ~-4 ~-23 ~-7 ~-4 ~-14 myc:clean_panel
fill ~-16 ~-9 ~-23 ~-16 ~-7 ~-14 myc:lab_panel
# Benches with brewing and analysis
fill ~-15 ~-9 ~-16 ~-9 ~-9 ~-16 minecraft:calcite
fill ~-15 ~-8 ~-16 ~-9 ~-8 ~-16 minecraft:quartz_slab
setblock ~-14 ~-8 ~-16 minecraft:brewing_stand
setblock ~-12 ~-8 ~-16 minecraft:brewing_stand
setblock ~-10 ~-8 ~-16 minecraft:brewing_stand
setblock ~-15 ~-8 ~-16 minecraft:cauldron["cauldron_liquid":"water","fill_level":6]
setblock ~-9 ~-8 ~-16 myc:lab_panel
fill ~-15 ~-9 ~-19 ~-9 ~-9 ~-19 minecraft:calcite
fill ~-15 ~-8 ~-19 ~-9 ~-8 ~-19 minecraft:quartz_slab
setblock ~-14 ~-8 ~-19 minecraft:brewing_stand
setblock ~-12 ~-8 ~-19 minecraft:brewing_stand
setblock ~-10 ~-8 ~-19 minecraft:brewing_stand
setblock ~-15 ~-8 ~-19 minecraft:cauldron["cauldron_liquid":"water","fill_level":6]
setblock ~-9 ~-8 ~-19 myc:lab_panel
fill ~-15 ~-9 ~-22 ~-9 ~-9 ~-22 minecraft:calcite
fill ~-15 ~-8 ~-22 ~-9 ~-8 ~-22 minecraft:quartz_slab
setblock ~-14 ~-8 ~-22 minecraft:brewing_stand
setblock ~-12 ~-8 ~-22 minecraft:brewing_stand
setblock ~-10 ~-8 ~-22 minecraft:brewing_stand
setblock ~-15 ~-8 ~-22 minecraft:cauldron["cauldron_liquid":"water","fill_level":6]
setblock ~-9 ~-8 ~-22 myc:lab_panel
setblock ~-14 ~-9 ~-17 minecraft:dark_oak_stairs["weirdo_direction":3,"upside_down_bit":false]
setblock ~-12 ~-9 ~-17 minecraft:dark_oak_stairs["weirdo_direction":3,"upside_down_bit":false]
setblock ~-10 ~-9 ~-17 minecraft:dark_oak_stairs["weirdo_direction":3,"upside_down_bit":false]
setblock ~-14 ~-9 ~-20 minecraft:dark_oak_stairs["weirdo_direction":3,"upside_down_bit":false]
setblock ~-12 ~-9 ~-20 minecraft:dark_oak_stairs["weirdo_direction":3,"upside_down_bit":false]
setblock ~-10 ~-9 ~-20 minecraft:dark_oak_stairs["weirdo_direction":3,"upside_down_bit":false]
# Analysis wall and control
fill ~-15 ~-8 ~-24 ~-9 ~-5 ~-24 minecraft:black_concrete
fill ~-14 ~-7 ~-24 ~-10 ~-6 ~-24 myc:screen
setblock ~-15 ~-8 ~-24 myc:control_panel
setblock ~-8 ~-8 ~-24 myc:lab_panel
setblock ~-8 ~-9 ~-14 minecraft:stonecutter_block
setblock ~-8 ~-9 ~-15 minecraft:composter
setblock ~-8 ~-9 ~-16 minecraft:cartography_table
# Specimen storage
setblock ~-16 ~-9 ~-22 minecraft:barrel["facing_direction":5,"open_bit":false]
setblock ~-16 ~-9 ~-20 minecraft:barrel["facing_direction":5,"open_bit":false]
# SECRET ROOM B - hidden behind the lab's specimen wall
fill ~-16 ~-10 ~-25 ~-10 ~-10 ~-25 minecraft:deepslate_tiles
fill ~-16 ~-3 ~-25 ~-10 ~-3 ~-25 minecraft:deepslate_tiles
fill ~-16 ~-9 ~-25 ~-10 ~-4 ~-25 minecraft:deepslate_bricks
fill ~-16 ~-9 ~-25 ~-10 ~-4 ~-25 minecraft:deepslate_bricks
fill ~-16 ~-9 ~-25 ~-16 ~-4 ~-25 minecraft:deepslate_bricks
fill ~-10 ~-9 ~-25 ~-10 ~-4 ~-25 minecraft:deepslate_bricks
fill ~-13 ~-9 ~-24 ~-12 ~-8 ~-24 minecraft:air
setblock ~-13 ~-9 ~-24 minecraft:iron_door["direction":2,"door_hinge_bit":false,"open_bit":false,"upper_block_bit":false]
setblock ~-13 ~-8 ~-24 minecraft:iron_door["direction":2,"door_hinge_bit":false,"open_bit":false,"upper_block_bit":true]
setblock ~-11 ~-8 ~-24 minecraft:stone_button["facing_direction":3]
setblock ~-14 ~-9 ~-24 minecraft:barrier
setblock ~-15 ~-9 ~-25 minecraft:chest["minecraft:cardinal_direction":"south"]
setblock ~-11 ~-9 ~-25 myc:lab_panel
setblock ~-13 ~-8 ~-25 myc:screen
setblock ~-15 ~-4 ~-22 minecraft:sea_lantern
setblock ~-12 ~-4 ~-22 minecraft:sea_lantern
setblock ~-9 ~-4 ~-22 minecraft:sea_lantern
setblock ~-15 ~-4 ~-15 minecraft:redstone_lamp
setblock ~-12 ~-4 ~-15 minecraft:redstone_lamp
setblock ~-9 ~-4 ~-15 minecraft:redstone_lamp
setblock ~-7 ~-7 ~-16 minecraft:soul_lantern["hanging":false]
setblock ~-7 ~-7 ~-20 minecraft:soul_lantern["hanging":false]
setblock ~-6 ~-7 ~-14 myc:alarm_light
setblock ~-16 ~-7 ~-24 myc:alarm_light
# --- 21 bunker access shaft + quarters ---
# Armoured shaft from the basement down to the bunker
fill ~-1 ~-15 ~-20 ~1 ~-11 ~-18 minecraft:air
setblock ~ ~-21 ~-18 minecraft:ladder["facing_direction":3]
setblock ~ ~-20 ~-18 minecraft:ladder["facing_direction":3]
setblock ~ ~-19 ~-18 minecraft:ladder["facing_direction":3]
setblock ~ ~-18 ~-18 minecraft:ladder["facing_direction":3]
setblock ~ ~-17 ~-18 minecraft:ladder["facing_direction":3]
setblock ~ ~-16 ~-18 minecraft:ladder["facing_direction":3]
setblock ~ ~-15 ~-18 minecraft:ladder["facing_direction":3]
setblock ~ ~-14 ~-18 minecraft:ladder["facing_direction":3]
setblock ~ ~-13 ~-18 minecraft:ladder["facing_direction":3]
setblock ~ ~-12 ~-18 minecraft:ladder["facing_direction":3]
setblock ~ ~-11 ~-18 minecraft:ladder["facing_direction":3]
fill ~-1 ~-10 ~-20 ~1 ~-10 ~-18 minecraft:air
# Bunker spine corridor
fill ~-1 ~-22 ~-19 ~1 ~-22 ~-5 minecraft:deepslate_tiles
fill ~-2 ~-21 ~-19 ~-2 ~-19 ~-5 myc:clean_panel
fill ~2 ~-21 ~-19 ~2 ~-19 ~-5 myc:clean_panel
setblock ~ ~-16 ~-18 minecraft:redstone_lamp
setblock ~ ~-16 ~-15 minecraft:redstone_lamp
setblock ~ ~-16 ~-12 minecraft:redstone_lamp
setblock ~ ~-16 ~-9 minecraft:redstone_lamp
setblock ~ ~-16 ~-6 minecraft:redstone_lamp
setblock ~-2 ~-19 ~-17 myc:alarm_light
setblock ~2 ~-19 ~-17 myc:alarm_light
setblock ~-2 ~-19 ~-12 myc:alarm_light
setblock ~2 ~-19 ~-12 myc:alarm_light
setblock ~-2 ~-19 ~-7 myc:alarm_light
setblock ~2 ~-19 ~-7 myc:alarm_light
# Living quarters
fill ~-13 ~-22 ~-13 ~-3 ~-22 ~-5 minecraft:deepslate_tiles
fill ~-13 ~-15 ~-13 ~-3 ~-15 ~-5 minecraft:deepslate_tiles
fill ~-13 ~-21 ~-5 ~-3 ~-16 ~-5 minecraft:polished_deepslate
fill ~-13 ~-21 ~-13 ~-3 ~-16 ~-13 minecraft:polished_deepslate
fill ~-13 ~-21 ~-13 ~-13 ~-16 ~-5 minecraft:polished_deepslate
fill ~-3 ~-21 ~-13 ~-3 ~-16 ~-5 minecraft:polished_deepslate
fill ~-3 ~-21 ~-10 ~-3 ~-19 ~-8 minecraft:air
fill ~-12 ~-21 ~-8 ~-11 ~-21 ~-6 minecraft:light_gray_wool
fill ~-12 ~-21 ~-6 ~-11 ~-21 ~-6 minecraft:gray_wool
fill ~-12 ~-20 ~-5 ~-11 ~-20 ~-5 minecraft:dark_oak_planks
fill ~-12 ~-21 ~-5 ~-11 ~-21 ~-5 minecraft:dark_oak_planks
fill ~-8 ~-21 ~-8 ~-7 ~-21 ~-6 minecraft:light_gray_wool
fill ~-8 ~-21 ~-6 ~-7 ~-21 ~-6 minecraft:gray_wool
fill ~-8 ~-20 ~-5 ~-7 ~-20 ~-5 minecraft:dark_oak_planks
fill ~-8 ~-21 ~-5 ~-7 ~-21 ~-5 minecraft:dark_oak_planks
setblock ~-13 ~-21 ~-6 minecraft:lantern["hanging":false]
fill ~-12 ~-21 ~-11 ~-11 ~-21 ~-9 minecraft:light_gray_wool
fill ~-12 ~-21 ~-9 ~-11 ~-21 ~-9 minecraft:gray_wool
fill ~-12 ~-20 ~-8 ~-11 ~-20 ~-8 minecraft:dark_oak_planks
fill ~-12 ~-21 ~-8 ~-11 ~-21 ~-8 minecraft:dark_oak_planks
fill ~-8 ~-21 ~-11 ~-7 ~-21 ~-9 minecraft:light_gray_wool
fill ~-8 ~-21 ~-9 ~-7 ~-21 ~-9 minecraft:gray_wool
fill ~-8 ~-20 ~-8 ~-7 ~-20 ~-8 minecraft:dark_oak_planks
fill ~-8 ~-21 ~-8 ~-7 ~-21 ~-8 minecraft:dark_oak_planks
setblock ~-13 ~-21 ~-9 minecraft:lantern["hanging":false]
fill ~-12 ~-21 ~-14 ~-11 ~-21 ~-12 minecraft:light_gray_wool
fill ~-12 ~-21 ~-12 ~-11 ~-21 ~-12 minecraft:gray_wool
fill ~-12 ~-20 ~-11 ~-11 ~-20 ~-11 minecraft:dark_oak_planks
fill ~-12 ~-21 ~-11 ~-11 ~-21 ~-11 minecraft:dark_oak_planks
fill ~-8 ~-21 ~-14 ~-7 ~-21 ~-12 minecraft:light_gray_wool
fill ~-8 ~-21 ~-12 ~-7 ~-21 ~-12 minecraft:gray_wool
fill ~-8 ~-20 ~-11 ~-7 ~-20 ~-11 minecraft:dark_oak_planks
fill ~-8 ~-21 ~-11 ~-7 ~-21 ~-11 minecraft:dark_oak_planks
setblock ~-13 ~-21 ~-12 minecraft:lantern["hanging":false]
setblock ~-6 ~-21 ~-8 minecraft:dark_oak_fence
setblock ~-6 ~-21 ~-7 minecraft:dark_oak_fence
setblock ~-5 ~-21 ~-8 minecraft:dark_oak_fence
setblock ~-5 ~-21 ~-7 minecraft:dark_oak_fence
fill ~-6 ~-20 ~-8 ~-5 ~-20 ~-7 minecraft:quartz_slab
setblock ~-6 ~-21 ~-9 minecraft:dark_oak_stairs["weirdo_direction":3,"upside_down_bit":false]
setblock ~-5 ~-21 ~-9 minecraft:dark_oak_stairs["weirdo_direction":3,"upside_down_bit":false]
setblock ~-4 ~-21 ~-12 minecraft:crafting_table
setblock ~-4 ~-21 ~-11 minecraft:furnace["minecraft:cardinal_direction":"west"]
setblock ~-12 ~-16 ~-7 minecraft:sea_lantern
setblock ~-9 ~-16 ~-7 minecraft:sea_lantern
setblock ~-6 ~-16 ~-7 minecraft:sea_lantern
setblock ~-12 ~-16 ~-12 minecraft:redstone_lamp
setblock ~-9 ~-16 ~-12 minecraft:redstone_lamp
setblock ~-6 ~-16 ~-12 minecraft:redstone_lamp
# Emergency supplies store
fill ~-13 ~-22 ~-19 ~-3 ~-22 ~-14 minecraft:deepslate_tiles
fill ~-13 ~-15 ~-19 ~-3 ~-15 ~-14 minecraft:deepslate_tiles
fill ~-13 ~-21 ~-14 ~-3 ~-16 ~-14 minecraft:polished_deepslate
fill ~-13 ~-21 ~-19 ~-3 ~-16 ~-19 minecraft:polished_deepslate
fill ~-13 ~-21 ~-19 ~-13 ~-16 ~-14 minecraft:polished_deepslate
fill ~-3 ~-21 ~-19 ~-3 ~-16 ~-14 minecraft:polished_deepslate
fill ~-3 ~-21 ~-17 ~-3 ~-19 ~-15 minecraft:air
setblock ~-12 ~-21 ~-16 minecraft:barrel["facing_direction":1,"open_bit":false]
setblock ~-12 ~-20 ~-16 minecraft:barrel["facing_direction":1,"open_bit":false]
