# part_73.mcfunction - generated by tools/gen_mansion.py, do not edit
# Relative coordinates only; run via execute positioned <x> <y> <z>
# (continued: 05 second floor shell)
fill ~-19 ~15 ~-27 ~19 ~15 ~ minecraft:dark_oak_planks
fill ~-19 ~16 ~-27 ~19 ~22 ~-27 minecraft:white_concrete
fill ~-19 ~16 ~ ~19 ~22 ~ minecraft:white_concrete
fill ~-19 ~16 ~-27 ~-19 ~22 ~ minecraft:white_concrete
fill ~19 ~16 ~-27 ~19 ~22 ~ minecraft:white_concrete
fill ~-19 ~23 ~-27 ~19 ~23 ~ minecraft:polished_deepslate
fill ~-19 ~17 ~-24 ~-19 ~20 ~-3 minecraft:gray_stained_glass
fill ~-19 ~17 ~-24 ~-19 ~20 ~-24 minecraft:polished_blackstone
fill ~-19 ~17 ~-20 ~-19 ~20 ~-20 minecraft:polished_blackstone
fill ~-19 ~17 ~-16 ~-19 ~20 ~-16 minecraft:polished_blackstone
fill ~-19 ~17 ~-12 ~-19 ~20 ~-12 minecraft:polished_blackstone
fill ~-19 ~17 ~-8 ~-19 ~20 ~-8 minecraft:polished_blackstone
fill ~-19 ~17 ~-4 ~-19 ~20 ~-4 minecraft:polished_blackstone
fill ~19 ~17 ~-24 ~19 ~20 ~-3 minecraft:gray_stained_glass
fill ~19 ~17 ~-24 ~19 ~20 ~-24 minecraft:polished_blackstone
fill ~19 ~17 ~-20 ~19 ~20 ~-20 minecraft:polished_blackstone
fill ~19 ~17 ~-16 ~19 ~20 ~-16 minecraft:polished_blackstone
fill ~19 ~17 ~-12 ~19 ~20 ~-12 minecraft:polished_blackstone
fill ~19 ~17 ~-8 ~19 ~20 ~-8 minecraft:polished_blackstone
fill ~19 ~17 ~-4 ~19 ~20 ~-4 minecraft:polished_blackstone
fill ~-17 ~17 ~-27 ~17 ~20 ~-27 minecraft:gray_stained_glass
fill ~-17 ~17 ~-27 ~-17 ~20 ~-27 minecraft:polished_blackstone
fill ~-13 ~17 ~-27 ~-13 ~20 ~-27 minecraft:polished_blackstone
fill ~-9 ~17 ~-27 ~-9 ~20 ~-27 minecraft:polished_blackstone
fill ~-5 ~17 ~-27 ~-5 ~20 ~-27 minecraft:polished_blackstone
fill ~-1 ~17 ~-27 ~-1 ~20 ~-27 minecraft:polished_blackstone
fill ~3 ~17 ~-27 ~3 ~20 ~-27 minecraft:polished_blackstone
fill ~7 ~17 ~-27 ~7 ~20 ~-27 minecraft:polished_blackstone
fill ~11 ~17 ~-27 ~11 ~20 ~-27 minecraft:polished_blackstone
fill ~15 ~17 ~-27 ~15 ~20 ~-27 minecraft:polished_blackstone
fill ~-17 ~17 ~ ~17 ~20 ~ minecraft:gray_stained_glass
fill ~-17 ~17 ~ ~-17 ~20 ~ minecraft:polished_blackstone
fill ~-13 ~17 ~ ~-13 ~20 ~ minecraft:polished_blackstone
fill ~-9 ~17 ~ ~-9 ~20 ~ minecraft:polished_blackstone
fill ~-5 ~17 ~ ~-5 ~20 ~ minecraft:polished_blackstone
fill ~-1 ~17 ~ ~-1 ~20 ~ minecraft:polished_blackstone
fill ~3 ~17 ~ ~3 ~20 ~ minecraft:polished_blackstone
fill ~7 ~17 ~ ~7 ~20 ~ minecraft:polished_blackstone
fill ~11 ~17 ~ ~11 ~20 ~ minecraft:polished_blackstone
fill ~15 ~17 ~ ~15 ~20 ~ minecraft:polished_blackstone
# --- 06 roof deck + parapet ---
fill ~-19 ~23 ~-27 ~19 ~23 ~ minecraft:smooth_stone
fill ~-17 ~23 ~-25 ~17 ~23 ~-2 minecraft:deepslate_tiles
fill ~-19 ~24 ~-27 ~19 ~24 ~-27 minecraft:polished_blackstone
fill ~-19 ~24 ~ ~19 ~24 ~ minecraft:polished_blackstone
fill ~-19 ~24 ~-27 ~-19 ~24 ~ minecraft:polished_blackstone
fill ~19 ~24 ~-27 ~19 ~24 ~ minecraft:polished_blackstone
# Glass parapet above the solid upstand
fill ~-19 ~25 ~-27 ~-19 ~26 ~-27 minecraft:light_gray_stained_glass_pane
fill ~-19 ~25 ~ ~-19 ~26 ~ minecraft:light_gray_stained_glass_pane
fill ~-17 ~25 ~-27 ~-17 ~26 ~-27 minecraft:light_gray_stained_glass_pane
fill ~-17 ~25 ~ ~-17 ~26 ~ minecraft:light_gray_stained_glass_pane
fill ~-15 ~25 ~-27 ~-15 ~26 ~-27 minecraft:light_gray_stained_glass_pane
fill ~-15 ~25 ~ ~-15 ~26 ~ minecraft:light_gray_stained_glass_pane
fill ~-13 ~25 ~-27 ~-13 ~26 ~-27 minecraft:light_gray_stained_glass_pane
fill ~-13 ~25 ~ ~-13 ~26 ~ minecraft:light_gray_stained_glass_pane
fill ~-11 ~25 ~-27 ~-11 ~26 ~-27 minecraft:light_gray_stained_glass_pane
fill ~-11 ~25 ~ ~-11 ~26 ~ minecraft:light_gray_stained_glass_pane
fill ~-9 ~25 ~-27 ~-9 ~26 ~-27 minecraft:light_gray_stained_glass_pane
fill ~-9 ~25 ~ ~-9 ~26 ~ minecraft:light_gray_stained_glass_pane
fill ~-7 ~25 ~-27 ~-7 ~26 ~-27 minecraft:light_gray_stained_glass_pane
fill ~-7 ~25 ~ ~-7 ~26 ~ minecraft:light_gray_stained_glass_pane
fill ~-5 ~25 ~-27 ~-5 ~26 ~-27 minecraft:light_gray_stained_glass_pane
fill ~-5 ~25 ~ ~-5 ~26 ~ minecraft:light_gray_stained_glass_pane
fill ~-3 ~25 ~-27 ~-3 ~26 ~-27 minecraft:light_gray_stained_glass_pane
fill ~-3 ~25 ~ ~-3 ~26 ~ minecraft:light_gray_stained_glass_pane
fill ~-1 ~25 ~-27 ~-1 ~26 ~-27 minecraft:light_gray_stained_glass_pane
fill ~-1 ~25 ~ ~-1 ~26 ~ minecraft:light_gray_stained_glass_pane
fill ~1 ~25 ~-27 ~1 ~26 ~-27 minecraft:light_gray_stained_glass_pane
fill ~1 ~25 ~ ~1 ~26 ~ minecraft:light_gray_stained_glass_pane
fill ~3 ~25 ~-27 ~3 ~26 ~-27 minecraft:light_gray_stained_glass_pane
fill ~3 ~25 ~ ~3 ~26 ~ minecraft:light_gray_stained_glass_pane
fill ~5 ~25 ~-27 ~5 ~26 ~-27 minecraft:light_gray_stained_glass_pane
fill ~5 ~25 ~ ~5 ~26 ~ minecraft:light_gray_stained_glass_pane
fill ~7 ~25 ~-27 ~7 ~26 ~-27 minecraft:light_gray_stained_glass_pane
fill ~7 ~25 ~ ~7 ~26 ~ minecraft:light_gray_stained_glass_pane
fill ~9 ~25 ~-27 ~9 ~26 ~-27 minecraft:light_gray_stained_glass_pane
fill ~9 ~25 ~ ~9 ~26 ~ minecraft:light_gray_stained_glass_pane
fill ~11 ~25 ~-27 ~11 ~26 ~-27 minecraft:light_gray_stained_glass_pane
fill ~11 ~25 ~ ~11 ~26 ~ minecraft:light_gray_stained_glass_pane
fill ~13 ~25 ~-27 ~13 ~26 ~-27 minecraft:light_gray_stained_glass_pane
fill ~13 ~25 ~ ~13 ~26 ~ minecraft:light_gray_stained_glass_pane
fill ~15 ~25 ~-27 ~15 ~26 ~-27 minecraft:light_gray_stained_glass_pane
fill ~15 ~25 ~ ~15 ~26 ~ minecraft:light_gray_stained_glass_pane
fill ~17 ~25 ~-27 ~17 ~26 ~-27 minecraft:light_gray_stained_glass_pane
fill ~17 ~25 ~ ~17 ~26 ~ minecraft:light_gray_stained_glass_pane
fill ~19 ~25 ~-27 ~19 ~26 ~-27 minecraft:light_gray_stained_glass_pane
fill ~19 ~25 ~ ~19 ~26 ~ minecraft:light_gray_stained_glass_pane
fill ~-19 ~25 ~-27 ~-19 ~26 ~-27 minecraft:light_gray_stained_glass_pane
fill ~19 ~25 ~-27 ~19 ~26 ~-27 minecraft:light_gray_stained_glass_pane
fill ~-19 ~25 ~-25 ~-19 ~26 ~-25 minecraft:light_gray_stained_glass_pane
fill ~19 ~25 ~-25 ~19 ~26 ~-25 minecraft:light_gray_stained_glass_pane
fill ~-19 ~25 ~-23 ~-19 ~26 ~-23 minecraft:light_gray_stained_glass_pane
fill ~19 ~25 ~-23 ~19 ~26 ~-23 minecraft:light_gray_stained_glass_pane
fill ~-19 ~25 ~-21 ~-19 ~26 ~-21 minecraft:light_gray_stained_glass_pane
fill ~19 ~25 ~-21 ~19 ~26 ~-21 minecraft:light_gray_stained_glass_pane
fill ~-19 ~25 ~-19 ~-19 ~26 ~-19 minecraft:light_gray_stained_glass_pane
fill ~19 ~25 ~-19 ~19 ~26 ~-19 minecraft:light_gray_stained_glass_pane
fill ~-19 ~25 ~-17 ~-19 ~26 ~-17 minecraft:light_gray_stained_glass_pane
fill ~19 ~25 ~-17 ~19 ~26 ~-17 minecraft:light_gray_stained_glass_pane
fill ~-19 ~25 ~-15 ~-19 ~26 ~-15 minecraft:light_gray_stained_glass_pane
fill ~19 ~25 ~-15 ~19 ~26 ~-15 minecraft:light_gray_stained_glass_pane
fill ~-19 ~25 ~-13 ~-19 ~26 ~-13 minecraft:light_gray_stained_glass_pane
fill ~19 ~25 ~-13 ~19 ~26 ~-13 minecraft:light_gray_stained_glass_pane
fill ~-19 ~25 ~-11 ~-19 ~26 ~-11 minecraft:light_gray_stained_glass_pane
fill ~19 ~25 ~-11 ~19 ~26 ~-11 minecraft:light_gray_stained_glass_pane
fill ~-19 ~25 ~-9 ~-19 ~26 ~-9 minecraft:light_gray_stained_glass_pane
fill ~19 ~25 ~-9 ~19 ~26 ~-9 minecraft:light_gray_stained_glass_pane
fill ~-19 ~25 ~-7 ~-19 ~26 ~-7 minecraft:light_gray_stained_glass_pane
fill ~19 ~25 ~-7 ~19 ~26 ~-7 minecraft:light_gray_stained_glass_pane
fill ~-19 ~25 ~-5 ~-19 ~26 ~-5 minecraft:light_gray_stained_glass_pane
fill ~19 ~25 ~-5 ~19 ~26 ~-5 minecraft:light_gray_stained_glass_pane
fill ~-19 ~25 ~-3 ~-19 ~26 ~-3 minecraft:light_gray_stained_glass_pane
fill ~19 ~25 ~-3 ~19 ~26 ~-3 minecraft:light_gray_stained_glass_pane
fill ~-19 ~25 ~-1 ~-19 ~26 ~-1 minecraft:light_gray_stained_glass_pane
fill ~19 ~25 ~-1 ~19 ~26 ~-1 minecraft:light_gray_stained_glass_pane
# Plant room / stair head
fill ~-4 ~24 ~-26 ~4 ~24 ~-20 minecraft:light_gray_concrete
fill ~-4 ~27 ~-26 ~4 ~27 ~-20 minecraft:light_gray_concrete
fill ~-4 ~24 ~-26 ~4 ~27 ~-26 minecraft:light_gray_concrete
fill ~-4 ~24 ~-20 ~4 ~27 ~-20 minecraft:light_gray_concrete
fill ~-4 ~24 ~-26 ~-4 ~27 ~-20 minecraft:light_gray_concrete
fill ~4 ~24 ~-26 ~4 ~27 ~-20 minecraft:light_gray_concrete
fill ~-1 ~24 ~-20 ~1 ~26 ~-20 minecraft:air
# --- 07 entrance hall + feature staircase ---
# Double-height hall: cut the first floor away over the hall
fill ~-6 ~7 ~-12 ~6 ~7 ~-1 minecraft:air
fill ~-6 ~-1 ~-12 ~6 ~-1 ~-1 minecraft:deepslate_tiles
fill ~-7 ~1 ~-2 ~-7 ~14 ~-2 minecraft:quartz_block["chisel_type":"lines"]
setblock ~-7 ~15 ~-2 minecraft:polished_blackstone_slab
fill ~-7 ~1 ~-11 ~-7 ~14 ~-11 minecraft:quartz_block["chisel_type":"lines"]
setblock ~-7 ~15 ~-11 minecraft:polished_blackstone_slab
fill ~7 ~1 ~-2 ~7 ~14 ~-2 minecraft:quartz_block["chisel_type":"lines"]
setblock ~7 ~15 ~-2 minecraft:polished_blackstone_slab
fill ~7 ~1 ~-11 ~7 ~14 ~-11 minecraft:quartz_block["chisel_type":"lines"]
setblock ~7 ~15 ~-11 minecraft:polished_blackstone_slab
# Feature staircase, ground -> first, three flights wide
setblock ~-3 ~1 ~-4 minecraft:quartz_stairs["weirdo_direction":3,"upside_down_bit":false]
setblock ~-3 ~2 ~-5 minecraft:quartz_stairs["weirdo_direction":3,"upside_down_bit":false]
setblock ~-3 ~3 ~-6 minecraft:quartz_stairs["weirdo_direction":3,"upside_down_bit":false]
setblock ~-3 ~4 ~-7 minecraft:quartz_stairs["weirdo_direction":3,"upside_down_bit":false]
setblock ~-3 ~5 ~-8 minecraft:quartz_stairs["weirdo_direction":3,"upside_down_bit":false]
setblock ~-3 ~6 ~-9 minecraft:quartz_stairs["weirdo_direction":3,"upside_down_bit":false]
setblock ~-3 ~7 ~-10 minecraft:quartz_stairs["weirdo_direction":3,"upside_down_bit":false]
setblock ~-2 ~1 ~-4 minecraft:quartz_stairs["weirdo_direction":3,"upside_down_bit":false]
setblock ~-2 ~2 ~-5 minecraft:quartz_stairs["weirdo_direction":3,"upside_down_bit":false]
setblock ~-2 ~3 ~-6 minecraft:quartz_stairs["weirdo_direction":3,"upside_down_bit":false]
setblock ~-2 ~4 ~-7 minecraft:quartz_stairs["weirdo_direction":3,"upside_down_bit":false]
setblock ~-2 ~5 ~-8 minecraft:quartz_stairs["weirdo_direction":3,"upside_down_bit":false]
setblock ~-2 ~6 ~-9 minecraft:quartz_stairs["weirdo_direction":3,"upside_down_bit":false]
setblock ~-2 ~7 ~-10 minecraft:quartz_stairs["weirdo_direction":3,"upside_down_bit":false]
setblock ~-1 ~1 ~-4 minecraft:quartz_stairs["weirdo_direction":3,"upside_down_bit":false]
setblock ~-1 ~2 ~-5 minecraft:quartz_stairs["weirdo_direction":3,"upside_down_bit":false]
setblock ~-1 ~3 ~-6 minecraft:quartz_stairs["weirdo_direction":3,"upside_down_bit":false]
setblock ~-1 ~4 ~-7 minecraft:quartz_stairs["weirdo_direction":3,"upside_down_bit":false]
setblock ~-1 ~5 ~-8 minecraft:quartz_stairs["weirdo_direction":3,"upside_down_bit":false]
setblock ~-1 ~6 ~-9 minecraft:quartz_stairs["weirdo_direction":3,"upside_down_bit":false]
setblock ~-1 ~7 ~-10 minecraft:quartz_stairs["weirdo_direction":3,"upside_down_bit":false]
setblock ~ ~1 ~-4 minecraft:quartz_stairs["weirdo_direction":3,"upside_down_bit":false]
setblock ~ ~2 ~-5 minecraft:quartz_stairs["weirdo_direction":3,"upside_down_bit":false]
setblock ~ ~3 ~-6 minecraft:quartz_stairs["weirdo_direction":3,"upside_down_bit":false]
setblock ~ ~4 ~-7 minecraft:quartz_stairs["weirdo_direction":3,"upside_down_bit":false]
setblock ~ ~5 ~-8 minecraft:quartz_stairs["weirdo_direction":3,"upside_down_bit":false]
setblock ~ ~6 ~-9 minecraft:quartz_stairs["weirdo_direction":3,"upside_down_bit":false]
setblock ~ ~7 ~-10 minecraft:quartz_stairs["weirdo_direction":3,"upside_down_bit":false]
setblock ~1 ~1 ~-4 minecraft:quartz_stairs["weirdo_direction":3,"upside_down_bit":false]
setblock ~1 ~2 ~-5 minecraft:quartz_stairs["weirdo_direction":3,"upside_down_bit":false]
setblock ~1 ~3 ~-6 minecraft:quartz_stairs["weirdo_direction":3,"upside_down_bit":false]
setblock ~1 ~4 ~-7 minecraft:quartz_stairs["weirdo_direction":3,"upside_down_bit":false]
setblock ~1 ~5 ~-8 minecraft:quartz_stairs["weirdo_direction":3,"upside_down_bit":false]
setblock ~1 ~6 ~-9 minecraft:quartz_stairs["weirdo_direction":3,"upside_down_bit":false]
setblock ~1 ~7 ~-10 minecraft:quartz_stairs["weirdo_direction":3,"upside_down_bit":false]
setblock ~2 ~1 ~-4 minecraft:quartz_stairs["weirdo_direction":3,"upside_down_bit":false]
setblock ~2 ~2 ~-5 minecraft:quartz_stairs["weirdo_direction":3,"upside_down_bit":false]
setblock ~2 ~3 ~-6 minecraft:quartz_stairs["weirdo_direction":3,"upside_down_bit":false]
setblock ~2 ~4 ~-7 minecraft:quartz_stairs["weirdo_direction":3,"upside_down_bit":false]
setblock ~2 ~5 ~-8 minecraft:quartz_stairs["weirdo_direction":3,"upside_down_bit":false]
setblock ~2 ~6 ~-9 minecraft:quartz_stairs["weirdo_direction":3,"upside_down_bit":false]
setblock ~2 ~7 ~-10 minecraft:quartz_stairs["weirdo_direction":3,"upside_down_bit":false]
setblock ~3 ~1 ~-4 minecraft:quartz_stairs["weirdo_direction":3,"upside_down_bit":false]
setblock ~3 ~2 ~-5 minecraft:quartz_stairs["weirdo_direction":3,"upside_down_bit":false]
setblock ~3 ~3 ~-6 minecraft:quartz_stairs["weirdo_direction":3,"upside_down_bit":false]
setblock ~3 ~4 ~-7 minecraft:quartz_stairs["weirdo_direction":3,"upside_down_bit":false]
setblock ~3 ~5 ~-8 minecraft:quartz_stairs["weirdo_direction":3,"upside_down_bit":false]
setblock ~3 ~6 ~-9 minecraft:quartz_stairs["weirdo_direction":3,"upside_down_bit":false]
setblock ~3 ~7 ~-10 minecraft:quartz_stairs["weirdo_direction":3,"upside_down_bit":false]
