# part_78.mcfunction - generated by tools/gen_mansion.py, do not edit
# Relative coordinates only; run via execute positioned <x> <y> <z>
# (continued: 16 rooftop terrace)
setblock ~-10 ~23 ~-3 minecraft:calcite
setblock ~-10 ~24 ~-3 minecraft:podzol
setblock ~-10 ~25 ~-3 minecraft:flowering_azalea
setblock ~-4 ~23 ~-3 minecraft:calcite
setblock ~-4 ~24 ~-3 minecraft:podzol
setblock ~-4 ~25 ~-3 minecraft:flowering_azalea
setblock ~2 ~23 ~-3 minecraft:calcite
setblock ~2 ~24 ~-3 minecraft:podzol
setblock ~2 ~25 ~-3 minecraft:flowering_azalea
setblock ~8 ~23 ~-3 minecraft:calcite
setblock ~8 ~24 ~-3 minecraft:podzol
setblock ~8 ~25 ~-3 minecraft:flowering_azalea
setblock ~14 ~23 ~-3 minecraft:calcite
setblock ~14 ~24 ~-3 minecraft:podzol
setblock ~14 ~25 ~-3 minecraft:flowering_azalea
setblock ~-15 ~24 ~-18 minecraft:redstone_lamp
setblock ~-10 ~24 ~-18 minecraft:redstone_lamp
setblock ~-5 ~24 ~-18 minecraft:redstone_lamp
setblock ~ ~24 ~-18 minecraft:redstone_lamp
setblock ~5 ~24 ~-18 minecraft:redstone_lamp
setblock ~10 ~24 ~-18 minecraft:redstone_lamp
setblock ~15 ~24 ~-18 minecraft:redstone_lamp
setblock ~-6 ~25 ~-19 myc:alarm_light
setblock ~6 ~25 ~-19 myc:alarm_light
# --- 17 basement core + stair ---
# Stair down from the utility corridor
fill ~-2 ~-3 ~-24 ~ ~-2 ~-22 minecraft:air
setblock ~-2 ~-9 ~-18 minecraft:polished_deepslate_stairs["weirdo_direction":2,"upside_down_bit":false]
setblock ~-2 ~-8 ~-17 minecraft:polished_deepslate_stairs["weirdo_direction":2,"upside_down_bit":false]
setblock ~-2 ~-7 ~-16 minecraft:polished_deepslate_stairs["weirdo_direction":2,"upside_down_bit":false]
setblock ~-2 ~-6 ~-15 minecraft:polished_deepslate_stairs["weirdo_direction":2,"upside_down_bit":false]
setblock ~-2 ~-5 ~-14 minecraft:polished_deepslate_stairs["weirdo_direction":2,"upside_down_bit":false]
setblock ~-2 ~-4 ~-13 minecraft:polished_deepslate_stairs["weirdo_direction":2,"upside_down_bit":false]
setblock ~-2 ~-3 ~-12 minecraft:polished_deepslate_stairs["weirdo_direction":2,"upside_down_bit":false]
setblock ~-1 ~-9 ~-18 minecraft:polished_deepslate_stairs["weirdo_direction":2,"upside_down_bit":false]
setblock ~-1 ~-8 ~-17 minecraft:polished_deepslate_stairs["weirdo_direction":2,"upside_down_bit":false]
setblock ~-1 ~-7 ~-16 minecraft:polished_deepslate_stairs["weirdo_direction":2,"upside_down_bit":false]
setblock ~-1 ~-6 ~-15 minecraft:polished_deepslate_stairs["weirdo_direction":2,"upside_down_bit":false]
setblock ~-1 ~-5 ~-14 minecraft:polished_deepslate_stairs["weirdo_direction":2,"upside_down_bit":false]
setblock ~-1 ~-4 ~-13 minecraft:polished_deepslate_stairs["weirdo_direction":2,"upside_down_bit":false]
setblock ~-1 ~-3 ~-12 minecraft:polished_deepslate_stairs["weirdo_direction":2,"upside_down_bit":false]
setblock ~ ~-9 ~-18 minecraft:polished_deepslate_stairs["weirdo_direction":2,"upside_down_bit":false]
setblock ~ ~-8 ~-17 minecraft:polished_deepslate_stairs["weirdo_direction":2,"upside_down_bit":false]
setblock ~ ~-7 ~-16 minecraft:polished_deepslate_stairs["weirdo_direction":2,"upside_down_bit":false]
setblock ~ ~-6 ~-15 minecraft:polished_deepslate_stairs["weirdo_direction":2,"upside_down_bit":false]
setblock ~ ~-5 ~-14 minecraft:polished_deepslate_stairs["weirdo_direction":2,"upside_down_bit":false]
setblock ~ ~-4 ~-13 minecraft:polished_deepslate_stairs["weirdo_direction":2,"upside_down_bit":false]
setblock ~ ~-3 ~-12 minecraft:polished_deepslate_stairs["weirdo_direction":2,"upside_down_bit":false]
fill ~-2 ~-1 ~-24 ~ ~-1 ~-22 minecraft:air
# Central basement corridor
fill ~-4 ~-10 ~-22 ~4 ~-10 ~-4 minecraft:deepslate_tiles
fill ~-4 ~-4 ~-22 ~4 ~-4 ~-4 myc:clean_panel
setblock ~-4 ~-6 ~-21 minecraft:redstone_lamp
setblock ~4 ~-6 ~-21 minecraft:redstone_lamp
setblock ~-4 ~-6 ~-18 minecraft:redstone_lamp
setblock ~4 ~-6 ~-18 minecraft:redstone_lamp
setblock ~-4 ~-6 ~-15 minecraft:redstone_lamp
setblock ~4 ~-6 ~-15 minecraft:redstone_lamp
setblock ~-4 ~-6 ~-12 minecraft:redstone_lamp
setblock ~4 ~-6 ~-12 minecraft:redstone_lamp
setblock ~-4 ~-6 ~-9 minecraft:redstone_lamp
setblock ~4 ~-6 ~-9 minecraft:redstone_lamp
setblock ~-4 ~-6 ~-6 minecraft:redstone_lamp
setblock ~4 ~-6 ~-6 minecraft:redstone_lamp
setblock ~-4 ~-7 ~-20 myc:alarm_light
setblock ~4 ~-7 ~-20 myc:alarm_light
setblock ~-4 ~-7 ~-12 myc:alarm_light
setblock ~4 ~-7 ~-12 myc:alarm_light
setblock ~-4 ~-7 ~-6 myc:alarm_light
setblock ~4 ~-7 ~-6 myc:alarm_light
# Corridor cladding
fill ~-5 ~-9 ~-22 ~-5 ~-7 ~-4 myc:clean_panel
fill ~5 ~-9 ~-22 ~5 ~-7 ~-4 myc:clean_panel
# --- 18 server room ---
fill ~-16 ~-10 ~-12 ~-6 ~-10 ~-3 minecraft:deepslate_tiles
fill ~-16 ~-3 ~-12 ~-6 ~-3 ~-3 minecraft:deepslate_tiles
fill ~-16 ~-9 ~-3 ~-6 ~-4 ~-3 minecraft:polished_deepslate
fill ~-16 ~-9 ~-12 ~-6 ~-4 ~-12 minecraft:polished_deepslate
fill ~-16 ~-9 ~-12 ~-16 ~-4 ~-3 minecraft:polished_deepslate
fill ~-6 ~-9 ~-12 ~-6 ~-4 ~-3 minecraft:polished_deepslate
fill ~-6 ~-9 ~-8 ~-6 ~-7 ~-6 minecraft:air
setblock ~-6 ~-9 ~-7 minecraft:iron_door["direction":3,"door_hinge_bit":false,"open_bit":false,"upper_block_bit":false]
setblock ~-6 ~-8 ~-7 minecraft:iron_door["direction":3,"door_hinge_bit":false,"open_bit":false,"upper_block_bit":true]
# Raised access floor
fill ~-15 ~-10 ~-11 ~-7 ~-10 ~-4 minecraft:black_concrete
# Four cold-aisle rack rows
fill ~-15 ~-9 ~-11 ~-15 ~-7 ~-11 myc:server_rack
fill ~-15 ~-9 ~-10 ~-15 ~-7 ~-10 myc:server_rack
fill ~-15 ~-9 ~-9 ~-15 ~-7 ~-9 myc:server_rack
fill ~-15 ~-9 ~-8 ~-15 ~-7 ~-8 myc:server_rack
fill ~-15 ~-9 ~-7 ~-15 ~-7 ~-7 myc:server_rack
fill ~-15 ~-9 ~-6 ~-15 ~-7 ~-6 myc:server_rack
fill ~-15 ~-9 ~-5 ~-15 ~-7 ~-5 myc:server_rack
setblock ~-15 ~-6 ~-11 minecraft:black_stained_glass_pane
setblock ~-15 ~-6 ~-5 minecraft:black_stained_glass_pane
fill ~-13 ~-9 ~-11 ~-13 ~-7 ~-11 myc:server_rack
fill ~-13 ~-9 ~-10 ~-13 ~-7 ~-10 myc:server_rack
fill ~-13 ~-9 ~-9 ~-13 ~-7 ~-9 myc:server_rack
fill ~-13 ~-9 ~-8 ~-13 ~-7 ~-8 myc:server_rack
fill ~-13 ~-9 ~-7 ~-13 ~-7 ~-7 myc:server_rack
fill ~-13 ~-9 ~-6 ~-13 ~-7 ~-6 myc:server_rack
fill ~-13 ~-9 ~-5 ~-13 ~-7 ~-5 myc:server_rack
setblock ~-13 ~-6 ~-11 minecraft:black_stained_glass_pane
setblock ~-13 ~-6 ~-5 minecraft:black_stained_glass_pane
fill ~-10 ~-9 ~-11 ~-10 ~-7 ~-11 myc:server_rack
fill ~-10 ~-9 ~-10 ~-10 ~-7 ~-10 myc:server_rack
fill ~-10 ~-9 ~-9 ~-10 ~-7 ~-9 myc:server_rack
fill ~-10 ~-9 ~-8 ~-10 ~-7 ~-8 myc:server_rack
fill ~-10 ~-9 ~-7 ~-10 ~-7 ~-7 myc:server_rack
fill ~-10 ~-9 ~-6 ~-10 ~-7 ~-6 myc:server_rack
fill ~-10 ~-9 ~-5 ~-10 ~-7 ~-5 myc:server_rack
setblock ~-10 ~-6 ~-11 minecraft:black_stained_glass_pane
setblock ~-10 ~-6 ~-5 minecraft:black_stained_glass_pane
fill ~-8 ~-9 ~-11 ~-8 ~-7 ~-11 myc:server_rack
fill ~-8 ~-9 ~-10 ~-8 ~-7 ~-10 myc:server_rack
fill ~-8 ~-9 ~-9 ~-8 ~-7 ~-9 myc:server_rack
fill ~-8 ~-9 ~-8 ~-8 ~-7 ~-8 myc:server_rack
fill ~-8 ~-9 ~-7 ~-8 ~-7 ~-7 myc:server_rack
fill ~-8 ~-9 ~-6 ~-8 ~-7 ~-6 myc:server_rack
fill ~-8 ~-9 ~-5 ~-8 ~-7 ~-5 myc:server_rack
setblock ~-8 ~-6 ~-11 minecraft:black_stained_glass_pane
setblock ~-8 ~-6 ~-5 minecraft:black_stained_glass_pane
# Aisle containment and cable trays
setblock ~-14 ~-6 ~-11 minecraft:black_stained_glass_pane
setblock ~-14 ~-6 ~-9 minecraft:black_stained_glass_pane
setblock ~-14 ~-6 ~-7 minecraft:black_stained_glass_pane
setblock ~-14 ~-6 ~-5 minecraft:black_stained_glass_pane
setblock ~-9 ~-6 ~-11 minecraft:black_stained_glass_pane
setblock ~-9 ~-6 ~-9 minecraft:black_stained_glass_pane
setblock ~-9 ~-6 ~-7 minecraft:black_stained_glass_pane
setblock ~-9 ~-6 ~-5 minecraft:black_stained_glass_pane
fill ~-16 ~-6 ~-11 ~-16 ~-6 ~-4 myc:clean_panel
# Ops console
fill ~-16 ~-9 ~-3 ~-12 ~-9 ~-3 minecraft:polished_blackstone
fill ~-16 ~-8 ~-3 ~-12 ~-8 ~-3 minecraft:quartz_slab
fill ~-16 ~-8 ~-3 ~-12 ~-5 ~-3 minecraft:black_concrete
fill ~-15 ~-7 ~-3 ~-13 ~-6 ~-3 myc:screen
setblock ~-16 ~-8 ~-3 myc:control_panel
setblock ~-14 ~-9 ~-4 minecraft:dark_oak_stairs["weirdo_direction":3,"upside_down_bit":false]
# Power and cooling plant
setblock ~-16 ~-9 ~-11 minecraft:beacon
setblock ~-16 ~-9 ~-10 minecraft:beacon
setblock ~-16 ~-9 ~-8 minecraft:observer["minecraft:facing_direction":"east"]
setblock ~-15 ~-4 ~-11 minecraft:sea_lantern
setblock ~-12 ~-4 ~-11 minecraft:sea_lantern
setblock ~-9 ~-4 ~-11 minecraft:sea_lantern
setblock ~-15 ~-4 ~-5 minecraft:redstone_lamp
setblock ~-12 ~-4 ~-5 minecraft:redstone_lamp
setblock ~-9 ~-4 ~-5 minecraft:redstone_lamp
setblock ~-6 ~-7 ~-4 myc:alarm_light
# --- 19 security room + secret room A ---
fill ~6 ~-10 ~-12 ~16 ~-10 ~-3 minecraft:deepslate_tiles
fill ~6 ~-3 ~-12 ~16 ~-3 ~-3 minecraft:deepslate_tiles
fill ~6 ~-9 ~-3 ~16 ~-4 ~-3 minecraft:polished_deepslate
fill ~6 ~-9 ~-12 ~16 ~-4 ~-12 minecraft:polished_deepslate
fill ~6 ~-9 ~-12 ~6 ~-4 ~-3 minecraft:polished_deepslate
fill ~16 ~-9 ~-12 ~16 ~-4 ~-3 minecraft:polished_deepslate
fill ~6 ~-9 ~-8 ~6 ~-7 ~-6 minecraft:air
setblock ~6 ~-9 ~-7 minecraft:iron_door["direction":3,"door_hinge_bit":false,"open_bit":false,"upper_block_bit":false]
setblock ~6 ~-8 ~-7 minecraft:iron_door["direction":3,"door_hinge_bit":false,"open_bit":false,"upper_block_bit":true]
# Camera monitor wall - 3 high, 9 wide
fill ~6 ~-8 ~-4 ~16 ~-4 ~-4 minecraft:black_concrete
fill ~7 ~-7 ~-4 ~15 ~-5 ~-4 myc:screen
# Control desk with panels
fill ~7 ~-9 ~-6 ~15 ~-9 ~-6 minecraft:polished_blackstone
fill ~7 ~-8 ~-6 ~15 ~-8 ~-6 minecraft:quartz_slab
setblock ~8 ~-8 ~-6 myc:control_panel
setblock ~11 ~-8 ~-6 myc:control_panel
setblock ~14 ~-8 ~-6 myc:control_panel
setblock ~9 ~-8 ~-6 myc:screen
setblock ~10 ~-8 ~-6 myc:screen
setblock ~12 ~-8 ~-6 myc:screen
setblock ~13 ~-8 ~-6 myc:screen
setblock ~8 ~-9 ~-7 minecraft:dark_oak_stairs["weirdo_direction":3,"upside_down_bit":false]
setblock ~11 ~-9 ~-7 minecraft:dark_oak_stairs["weirdo_direction":3,"upside_down_bit":false]
setblock ~14 ~-9 ~-7 minecraft:dark_oak_stairs["weirdo_direction":3,"upside_down_bit":false]
# Equipment bays
fill ~16 ~-9 ~-11 ~16 ~-7 ~-11 myc:server_rack
fill ~16 ~-9 ~-10 ~16 ~-7 ~-10 myc:server_rack
fill ~16 ~-9 ~-9 ~16 ~-7 ~-9 myc:server_rack
setblock ~7 ~-9 ~-11 minecraft:trapped_chest["minecraft:cardinal_direction":"south"]
setblock ~8 ~-9 ~-11 minecraft:chest["minecraft:cardinal_direction":"south"]
setblock ~16 ~-9 ~-4 minecraft:lever["lever_direction":"west","open_bit":false]
# SECRET ROOM A - behind the monitor wall, entered by a hidden door
fill ~7 ~-10 ~-20 ~15 ~-10 ~-14 minecraft:deepslate_tiles
fill ~7 ~-3 ~-20 ~15 ~-3 ~-14 minecraft:deepslate_tiles
fill ~7 ~-9 ~-14 ~15 ~-4 ~-14 minecraft:deepslate_bricks
fill ~7 ~-9 ~-20 ~15 ~-4 ~-20 minecraft:deepslate_bricks
fill ~7 ~-9 ~-20 ~7 ~-4 ~-14 minecraft:deepslate_bricks
fill ~15 ~-9 ~-20 ~15 ~-4 ~-14 minecraft:deepslate_bricks
# Hidden door: flush deepslate panel with a concealed button
fill ~11 ~-9 ~-13 ~12 ~-8 ~-13 minecraft:air
setblock ~11 ~-9 ~-13 minecraft:iron_door["direction":2,"door_hinge_bit":false,"open_bit":false,"upper_block_bit":false]
setblock ~11 ~-8 ~-13 minecraft:iron_door["direction":2,"door_hinge_bit":false,"open_bit":false,"upper_block_bit":true]
setblock ~13 ~-8 ~-13 minecraft:stone_button["facing_direction":3]
setblock ~10 ~-9 ~-13 minecraft:barrier
# Vault contents
