# part_75.mcfunction - generated by tools/gen_mansion.py, do not edit
# Relative coordinates only; run via execute positioned <x> <y> <z>
# (continued: 10 guest bathroom + utility)
fill ~-3 ~-1 ~-26 ~3 ~-1 ~-13 minecraft:deepslate_tiles
setblock ~-2 ~6 ~-25 minecraft:redstone_lamp
setblock ~1 ~6 ~-25 minecraft:redstone_lamp
setblock ~ ~4 ~-25 myc:alarm_light
# --- 11 master bedroom + wardrobe + en-suite ---
fill ~-18 ~7 ~-13 ~-8 ~7 ~-1 minecraft:dark_oak_planks
fill ~-19 ~8 ~-13 ~-7 ~14 ~-13 minecraft:white_concrete
fill ~-19 ~8 ~-1 ~-7 ~14 ~-1 minecraft:white_concrete
fill ~-19 ~8 ~-13 ~-19 ~14 ~-1 minecraft:white_concrete
fill ~-7 ~8 ~-13 ~-7 ~14 ~-1 minecraft:white_concrete
fill ~-7 ~8 ~-6 ~-7 ~10 ~-4 minecraft:air
# Bed platform and headboard
fill ~-15 ~7 ~-10 ~-10 ~7 ~-5 minecraft:light_gray_wool
fill ~-13 ~8 ~-9 ~-12 ~8 ~-6 minecraft:white_wool
fill ~-13 ~8 ~-6 ~-12 ~8 ~-6 minecraft:light_gray_wool
fill ~-13 ~9 ~-5 ~-12 ~9 ~-5 minecraft:dark_oak_planks
fill ~-13 ~8 ~-5 ~-12 ~8 ~-5 minecraft:dark_oak_planks
fill ~-14 ~8 ~-3 ~-11 ~10 ~-3 myc:clean_panel
setblock ~-14 ~9 ~-4 minecraft:lantern["hanging":false]
setblock ~-11 ~9 ~-4 minecraft:lantern["hanging":false]
# Seating and media
setblock ~-17 ~8 ~-11 minecraft:dark_oak_stairs["weirdo_direction":2,"upside_down_bit":false]
setblock ~-16 ~8 ~-11 minecraft:dark_oak_stairs["weirdo_direction":2,"upside_down_bit":false]
setblock ~-15 ~8 ~-11 minecraft:dark_oak_stairs["weirdo_direction":2,"upside_down_bit":false]
setblock ~-14 ~8 ~-11 minecraft:dark_oak_stairs["weirdo_direction":2,"upside_down_bit":false]
setblock ~-13 ~8 ~-11 minecraft:dark_oak_stairs["weirdo_direction":2,"upside_down_bit":false]
setblock ~-18 ~8 ~-11 minecraft:gray_wool
setblock ~-12 ~8 ~-11 minecraft:gray_wool
fill ~-17 ~9 ~-13 ~-11 ~13 ~-13 minecraft:black_concrete
fill ~-16 ~10 ~-13 ~-12 ~12 ~-13 myc:screen
setblock ~-17 ~8 ~-8 minecraft:dark_oak_fence
setblock ~-17 ~8 ~-7 minecraft:dark_oak_fence
setblock ~-16 ~8 ~-8 minecraft:dark_oak_fence
setblock ~-16 ~8 ~-7 minecraft:dark_oak_fence
fill ~-17 ~9 ~-8 ~-16 ~9 ~-7 minecraft:quartz_slab
fill ~-16 ~7 ~-9 ~-11 ~7 ~-4 minecraft:gray_carpet
# Walk-in wardrobe
fill ~-18 ~7 ~-19 ~-13 ~7 ~-14 minecraft:dark_oak_planks
fill ~-18 ~15 ~-19 ~-13 ~15 ~-14 minecraft:dark_oak_planks
fill ~-18 ~8 ~-19 ~-13 ~14 ~-19 minecraft:light_gray_concrete
fill ~-18 ~8 ~-14 ~-13 ~14 ~-14 minecraft:light_gray_concrete
fill ~-18 ~8 ~-19 ~-18 ~14 ~-14 minecraft:light_gray_concrete
fill ~-13 ~8 ~-19 ~-13 ~14 ~-14 minecraft:light_gray_concrete
fill ~-15 ~8 ~-13 ~-14 ~10 ~-13 minecraft:air
fill ~-17 ~8 ~-18 ~-17 ~10 ~-18 minecraft:warped_planks
setblock ~-16 ~8 ~-18 minecraft:barrel["facing_direction":5,"open_bit":false]
fill ~-17 ~8 ~-17 ~-17 ~10 ~-17 minecraft:warped_planks
setblock ~-16 ~8 ~-17 minecraft:barrel["facing_direction":5,"open_bit":false]
fill ~-17 ~8 ~-16 ~-17 ~10 ~-16 minecraft:warped_planks
setblock ~-16 ~8 ~-16 minecraft:barrel["facing_direction":5,"open_bit":false]
fill ~-17 ~8 ~-15 ~-17 ~10 ~-15 minecraft:warped_planks
setblock ~-16 ~8 ~-15 minecraft:barrel["facing_direction":5,"open_bit":false]
setblock ~-14 ~9 ~-18 minecraft:sea_lantern
# En-suite
fill ~-12 ~7 ~-19 ~-8 ~7 ~-14 minecraft:deepslate_tiles
fill ~-12 ~15 ~-19 ~-8 ~15 ~-14 minecraft:deepslate_tiles
fill ~-12 ~8 ~-19 ~-8 ~14 ~-19 minecraft:light_gray_concrete
fill ~-12 ~8 ~-14 ~-8 ~14 ~-14 minecraft:light_gray_concrete
fill ~-12 ~8 ~-19 ~-12 ~14 ~-14 minecraft:light_gray_concrete
fill ~-8 ~8 ~-19 ~-8 ~14 ~-14 minecraft:light_gray_concrete
fill ~-10 ~8 ~-13 ~-9 ~10 ~-13 minecraft:air
setblock ~-11 ~8 ~-18 minecraft:cauldron["cauldron_liquid":"water","fill_level":6]
fill ~-10 ~8 ~-18 ~-9 ~8 ~-17 minecraft:quartz_slab
fill ~-12 ~8 ~-16 ~-12 ~10 ~-15 minecraft:white_stained_glass
setblock ~-9 ~8 ~-15 minecraft:quartz_stairs["weirdo_direction":1,"upside_down_bit":false]
setblock ~-10 ~11 ~-17 minecraft:sea_lantern
setblock ~-16 ~14 ~-12 minecraft:sea_lantern
setblock ~-13 ~14 ~-12 minecraft:sea_lantern
setblock ~-10 ~14 ~-12 minecraft:sea_lantern
setblock ~-16 ~14 ~-3 minecraft:redstone_lamp
setblock ~-12 ~14 ~-3 minecraft:redstone_lamp
setblock ~-8 ~11 ~-2 myc:alarm_light
# --- 12 bedrooms 2 + 3, luxury bathroom, balcony ---
# Bedroom 2
fill ~6 ~7 ~-10 ~17 ~7 ~-1 minecraft:dark_oak_planks
fill ~6 ~15 ~-10 ~17 ~15 ~-1 minecraft:dark_oak_planks
fill ~6 ~8 ~-1 ~17 ~14 ~-1 minecraft:white_concrete
fill ~6 ~8 ~-10 ~17 ~14 ~-10 minecraft:white_concrete
fill ~6 ~8 ~-10 ~6 ~14 ~-1 minecraft:white_concrete
fill ~17 ~8 ~-10 ~17 ~14 ~-1 minecraft:white_concrete
fill ~6 ~8 ~-5 ~6 ~10 ~-3 minecraft:air
setblock ~6 ~8 ~-4 minecraft:dark_oak_door["direction":3,"door_hinge_bit":false,"open_bit":false,"upper_block_bit":false]
setblock ~6 ~9 ~-4 minecraft:dark_oak_door["direction":3,"door_hinge_bit":false,"open_bit":false,"upper_block_bit":true]
fill ~9 ~8 ~-7 ~10 ~8 ~-4 minecraft:white_wool
fill ~9 ~8 ~-4 ~10 ~8 ~-4 minecraft:cyan_wool
fill ~9 ~9 ~-3 ~10 ~9 ~-3 minecraft:dark_oak_planks
fill ~9 ~8 ~-3 ~10 ~8 ~-3 minecraft:dark_oak_planks
setblock ~13 ~8 ~-8 minecraft:dark_oak_fence
setblock ~13 ~8 ~-7 minecraft:dark_oak_fence
setblock ~14 ~8 ~-8 minecraft:dark_oak_fence
setblock ~14 ~8 ~-7 minecraft:dark_oak_fence
fill ~13 ~9 ~-8 ~14 ~9 ~-7 minecraft:quartz_slab
setblock ~13 ~8 ~-6 minecraft:dark_oak_stairs["weirdo_direction":3,"upside_down_bit":false]
fill ~11 ~9 ~-10 ~16 ~12 ~-10 minecraft:black_concrete
fill ~12 ~10 ~-10 ~15 ~11 ~-10 myc:screen
fill ~8 ~7 ~-8 ~15 ~7 ~-3 minecraft:blue_carpet
setblock ~16 ~8 ~-9 minecraft:barrel["facing_direction":4,"open_bit":false]
setblock ~16 ~8 ~-6 minecraft:barrel["facing_direction":4,"open_bit":false]
setblock ~16 ~8 ~-3 minecraft:barrel["facing_direction":4,"open_bit":false]
setblock ~8 ~11 ~-9 minecraft:sea_lantern
setblock ~14 ~13 ~-5 minecraft:redstone_lamp
# Bedroom 3
fill ~6 ~7 ~-19 ~17 ~7 ~-11 minecraft:dark_oak_planks
fill ~6 ~15 ~-19 ~17 ~15 ~-11 minecraft:dark_oak_planks
fill ~6 ~8 ~-11 ~17 ~14 ~-11 minecraft:white_concrete
fill ~6 ~8 ~-19 ~17 ~14 ~-19 minecraft:white_concrete
fill ~6 ~8 ~-19 ~6 ~14 ~-11 minecraft:white_concrete
fill ~17 ~8 ~-19 ~17 ~14 ~-11 minecraft:white_concrete
fill ~6 ~8 ~-15 ~6 ~10 ~-13 minecraft:air
setblock ~6 ~8 ~-14 minecraft:dark_oak_door["direction":3,"door_hinge_bit":false,"open_bit":false,"upper_block_bit":false]
setblock ~6 ~9 ~-14 minecraft:dark_oak_door["direction":3,"door_hinge_bit":false,"open_bit":false,"upper_block_bit":true]
fill ~9 ~8 ~-17 ~10 ~8 ~-14 minecraft:white_wool
fill ~9 ~8 ~-14 ~10 ~8 ~-14 minecraft:red_wool
fill ~9 ~9 ~-13 ~10 ~9 ~-13 minecraft:dark_oak_planks
fill ~9 ~8 ~-13 ~10 ~8 ~-13 minecraft:dark_oak_planks
setblock ~13 ~8 ~-18 minecraft:dark_oak_fence
setblock ~13 ~8 ~-17 minecraft:dark_oak_fence
setblock ~14 ~8 ~-18 minecraft:dark_oak_fence
setblock ~14 ~8 ~-17 minecraft:dark_oak_fence
fill ~13 ~9 ~-18 ~14 ~9 ~-17 minecraft:quartz_slab
setblock ~13 ~8 ~-16 minecraft:dark_oak_stairs["weirdo_direction":3,"upside_down_bit":false]
fill ~11 ~9 ~-19 ~16 ~12 ~-19 minecraft:black_concrete
fill ~12 ~10 ~-19 ~15 ~11 ~-19 myc:screen
fill ~8 ~7 ~-18 ~15 ~7 ~-13 minecraft:red_carpet
setblock ~16 ~8 ~-18 minecraft:chest["minecraft:cardinal_direction":"west"]
setblock ~8 ~11 ~-19 minecraft:sea_lantern
setblock ~14 ~13 ~-15 minecraft:redstone_lamp
# Luxury family bathroom
fill ~-4 ~7 ~-21 ~4 ~7 ~-14 minecraft:deepslate_tiles
fill ~-4 ~15 ~-21 ~4 ~15 ~-14 minecraft:deepslate_tiles
fill ~-4 ~8 ~-14 ~4 ~14 ~-14 minecraft:light_gray_concrete
fill ~-4 ~8 ~-21 ~4 ~14 ~-21 minecraft:light_gray_concrete
fill ~-4 ~8 ~-21 ~-4 ~14 ~-14 minecraft:light_gray_concrete
fill ~4 ~8 ~-21 ~4 ~14 ~-14 minecraft:light_gray_concrete
fill ~-1 ~8 ~-14 ~1 ~10 ~-14 minecraft:air
# Sunken tub
fill ~-2 ~7 ~-19 ~2 ~7 ~-17 minecraft:polished_deepslate
fill ~-2 ~8 ~-19 ~2 ~8 ~-17 minecraft:water
fill ~-3 ~8 ~-20 ~3 ~8 ~-20 minecraft:quartz_slab
setblock ~-3 ~8 ~-16 minecraft:cauldron["cauldron_liquid":"water","fill_level":6]
setblock ~3 ~8 ~-16 minecraft:cauldron["cauldron_liquid":"water","fill_level":6]
fill ~-3 ~8 ~-15 ~-2 ~10 ~-15 minecraft:white_stained_glass
setblock ~-2 ~11 ~-18 minecraft:sea_lantern
setblock ~2 ~11 ~-18 minecraft:sea_lantern
setblock ~ ~12 ~-16 minecraft:redstone_lamp
# Front balcony with glass railing
fill ~-10 ~7 ~1 ~10 ~7 ~4 minecraft:smooth_stone
fill ~-10 ~7 ~1 ~10 ~7 ~1 minecraft:deepslate_tiles
fill ~-10 ~8 ~4 ~10 ~8 ~4 minecraft:glass_pane
setblock ~-10 ~8 ~4 minecraft:polished_blackstone_wall
setblock ~10 ~8 ~4 minecraft:polished_blackstone_wall
setblock ~ ~8 ~4 minecraft:polished_blackstone_wall
fill ~-10 ~8 ~1 ~-10 ~8 ~4 minecraft:glass_pane
setblock ~-10 ~8 ~1 minecraft:polished_blackstone_wall
setblock ~-10 ~8 ~4 minecraft:polished_blackstone_wall
setblock ~-10 ~8 ~2 minecraft:polished_blackstone_wall
fill ~10 ~8 ~1 ~10 ~8 ~4 minecraft:glass_pane
setblock ~10 ~8 ~1 minecraft:polished_blackstone_wall
setblock ~10 ~8 ~4 minecraft:polished_blackstone_wall
setblock ~10 ~8 ~2 minecraft:polished_blackstone_wall
setblock ~-8 ~8 ~3 minecraft:flower_pot
setblock ~-4 ~8 ~3 minecraft:flower_pot
setblock ~ ~8 ~3 minecraft:flower_pot
setblock ~4 ~8 ~3 minecraft:flower_pot
setblock ~8 ~8 ~3 minecraft:flower_pot
setblock ~-3 ~8 ~3 minecraft:dark_oak_stairs["weirdo_direction":2,"upside_down_bit":false]
setblock ~-2 ~8 ~3 minecraft:dark_oak_stairs["weirdo_direction":2,"upside_down_bit":false]
setblock ~-1 ~8 ~3 minecraft:dark_oak_stairs["weirdo_direction":2,"upside_down_bit":false]
setblock ~ ~8 ~3 minecraft:dark_oak_stairs["weirdo_direction":2,"upside_down_bit":false]
setblock ~1 ~8 ~3 minecraft:dark_oak_stairs["weirdo_direction":2,"upside_down_bit":false]
setblock ~2 ~8 ~3 minecraft:dark_oak_stairs["weirdo_direction":2,"upside_down_bit":false]
setblock ~3 ~8 ~3 minecraft:dark_oak_stairs["weirdo_direction":2,"upside_down_bit":false]
setblock ~-4 ~8 ~3 minecraft:gray_wool
setblock ~4 ~8 ~3 minecraft:gray_wool
setblock ~-1 ~8 ~2 minecraft:dark_oak_fence
setblock ~-1 ~8 ~2 minecraft:dark_oak_fence
setblock ~1 ~8 ~2 minecraft:dark_oak_fence
setblock ~1 ~8 ~2 minecraft:dark_oak_fence
fill ~-1 ~9 ~2 ~1 ~9 ~2 minecraft:quartz_slab
setblock ~-10 ~11 ~ myc:alarm_light
setblock ~10 ~11 ~ myc:alarm_light
setblock ~-9 ~8 ~1 minecraft:redstone_lamp
setblock ~-5 ~8 ~1 minecraft:redstone_lamp
setblock ~-1 ~8 ~1 minecraft:redstone_lamp
setblock ~3 ~8 ~1 minecraft:redstone_lamp
setblock ~7 ~8 ~1 minecraft:redstone_lamp
# --- 13 home cinema ---
fill ~-19 ~15 ~-17 ~-6 ~15 ~-1 minecraft:black_carpet
fill ~-19 ~23 ~-17 ~-6 ~23 ~-1 minecraft:polished_deepslate
fill ~-19 ~16 ~-1 ~-6 ~22 ~-1 minecraft:black_concrete
fill ~-19 ~16 ~-17 ~-6 ~22 ~-17 minecraft:black_concrete
fill ~-19 ~16 ~-17 ~-19 ~22 ~-1 minecraft:black_concrete
