# part_10.mcfunction - generated by tools/gen_mansion.py, do not edit
# Relative coordinates only; run via execute positioned <x> <y> <z>
# (continued: 25 landscaped garden)
setblock ~-16 ~1 ~27 minecraft:flowering_azalea
setblock ~-13 ~-1 ~27 minecraft:calcite
setblock ~-13 ~ ~27 minecraft:podzol
setblock ~-13 ~1 ~27 minecraft:flowering_azalea
# --- 26 swimming pool + deck ---
# Pool deck
fill ~20 ~-1 ~4 ~38 ~-1 ~26 minecraft:smooth_stone
fill ~21 ~-1 ~5 ~37 ~-1 ~25 minecraft:calcite
# Pool basin, 3 deep
fill ~23 ~-4 ~8 ~35 ~-1 ~22 minecraft:deepslate_tiles
fill ~24 ~-4 ~9 ~34 ~-2 ~21 minecraft:water
fill ~24 ~-5 ~9 ~34 ~-5 ~21 minecraft:light_blue_stained_glass
# Coping and invisible safety kerb
setblock ~23 ~-1 ~8 minecraft:quartz_slab
setblock ~23 ~-1 ~22 minecraft:quartz_slab
setblock ~23 ~ ~8 minecraft:barrier
setblock ~23 ~ ~22 minecraft:barrier
setblock ~24 ~-1 ~8 minecraft:quartz_slab
setblock ~24 ~-1 ~22 minecraft:quartz_slab
setblock ~24 ~ ~8 minecraft:barrier
setblock ~24 ~ ~22 minecraft:barrier
setblock ~25 ~-1 ~8 minecraft:quartz_slab
setblock ~25 ~-1 ~22 minecraft:quartz_slab
setblock ~25 ~ ~8 minecraft:barrier
setblock ~25 ~ ~22 minecraft:barrier
setblock ~26 ~-1 ~8 minecraft:quartz_slab
setblock ~26 ~-1 ~22 minecraft:quartz_slab
setblock ~26 ~ ~8 minecraft:barrier
setblock ~26 ~ ~22 minecraft:barrier
setblock ~27 ~-1 ~8 minecraft:quartz_slab
setblock ~27 ~-1 ~22 minecraft:quartz_slab
setblock ~27 ~ ~8 minecraft:barrier
setblock ~27 ~ ~22 minecraft:barrier
setblock ~28 ~-1 ~8 minecraft:quartz_slab
setblock ~28 ~-1 ~22 minecraft:quartz_slab
setblock ~28 ~ ~8 minecraft:barrier
setblock ~28 ~ ~22 minecraft:barrier
setblock ~29 ~-1 ~8 minecraft:quartz_slab
setblock ~29 ~-1 ~22 minecraft:quartz_slab
setblock ~29 ~ ~8 minecraft:barrier
setblock ~29 ~ ~22 minecraft:barrier
setblock ~30 ~-1 ~8 minecraft:quartz_slab
setblock ~30 ~-1 ~22 minecraft:quartz_slab
setblock ~30 ~ ~8 minecraft:barrier
setblock ~30 ~ ~22 minecraft:barrier
setblock ~31 ~-1 ~8 minecraft:quartz_slab
setblock ~31 ~-1 ~22 minecraft:quartz_slab
setblock ~31 ~ ~8 minecraft:barrier
setblock ~31 ~ ~22 minecraft:barrier
setblock ~32 ~-1 ~8 minecraft:quartz_slab
setblock ~32 ~-1 ~22 minecraft:quartz_slab
setblock ~32 ~ ~8 minecraft:barrier
setblock ~32 ~ ~22 minecraft:barrier
setblock ~33 ~-1 ~8 minecraft:quartz_slab
setblock ~33 ~-1 ~22 minecraft:quartz_slab
setblock ~33 ~ ~8 minecraft:barrier
setblock ~33 ~ ~22 minecraft:barrier
setblock ~34 ~-1 ~8 minecraft:quartz_slab
setblock ~34 ~-1 ~22 minecraft:quartz_slab
setblock ~34 ~ ~8 minecraft:barrier
setblock ~34 ~ ~22 minecraft:barrier
setblock ~35 ~-1 ~8 minecraft:quartz_slab
setblock ~35 ~-1 ~22 minecraft:quartz_slab
setblock ~35 ~ ~8 minecraft:barrier
setblock ~35 ~ ~22 minecraft:barrier
setblock ~23 ~-1 ~9 minecraft:quartz_slab
setblock ~35 ~-1 ~9 minecraft:quartz_slab
setblock ~23 ~-1 ~10 minecraft:quartz_slab
setblock ~35 ~-1 ~10 minecraft:quartz_slab
setblock ~23 ~-1 ~11 minecraft:quartz_slab
setblock ~35 ~-1 ~11 minecraft:quartz_slab
setblock ~23 ~-1 ~12 minecraft:quartz_slab
setblock ~35 ~-1 ~12 minecraft:quartz_slab
setblock ~23 ~-1 ~13 minecraft:quartz_slab
setblock ~35 ~-1 ~13 minecraft:quartz_slab
setblock ~23 ~-1 ~14 minecraft:quartz_slab
setblock ~35 ~-1 ~14 minecraft:quartz_slab
setblock ~23 ~-1 ~15 minecraft:quartz_slab
setblock ~35 ~-1 ~15 minecraft:quartz_slab
setblock ~23 ~-1 ~16 minecraft:quartz_slab
setblock ~35 ~-1 ~16 minecraft:quartz_slab
setblock ~23 ~-1 ~17 minecraft:quartz_slab
setblock ~35 ~-1 ~17 minecraft:quartz_slab
setblock ~23 ~-1 ~18 minecraft:quartz_slab
setblock ~35 ~-1 ~18 minecraft:quartz_slab
setblock ~23 ~-1 ~19 minecraft:quartz_slab
setblock ~35 ~-1 ~19 minecraft:quartz_slab
setblock ~23 ~-1 ~20 minecraft:quartz_slab
setblock ~35 ~-1 ~20 minecraft:quartz_slab
setblock ~23 ~-1 ~21 minecraft:quartz_slab
setblock ~35 ~-1 ~21 minecraft:quartz_slab
# Steps into the shallow end
fill ~25 ~-4 ~10 ~25 ~-4 ~12 minecraft:quartz_slab
fill ~26 ~-3 ~10 ~26 ~-3 ~12 minecraft:quartz_slab
fill ~27 ~-2 ~10 ~27 ~-2 ~12 minecraft:quartz_slab
# Diving board
fill ~29 ~ ~6 ~29 ~ ~7 minecraft:polished_blackstone
fill ~28 ~1 ~5 ~30 ~1 ~7 minecraft:smooth_stone_slab
fill ~28 ~1 ~8 ~30 ~1 ~9 minecraft:dark_oak_slab
setblock ~28 ~1 ~6 minecraft:dark_oak_fence
setblock ~28 ~2 ~6 minecraft:dark_oak_fence
setblock ~30 ~1 ~6 minecraft:dark_oak_fence
setblock ~30 ~2 ~6 minecraft:dark_oak_fence
# Sun loungers
setblock ~37 ~ ~11 minecraft:quartz_stairs["weirdo_direction":1,"upside_down_bit":false]
setblock ~36 ~ ~11 minecraft:quartz_slab
setblock ~37 ~1 ~11 minecraft:white_wool
setblock ~37 ~ ~14 minecraft:quartz_stairs["weirdo_direction":1,"upside_down_bit":false]
setblock ~36 ~ ~14 minecraft:quartz_slab
setblock ~37 ~1 ~14 minecraft:white_wool
setblock ~37 ~ ~17 minecraft:quartz_stairs["weirdo_direction":1,"upside_down_bit":false]
setblock ~36 ~ ~17 minecraft:quartz_slab
setblock ~37 ~1 ~17 minecraft:white_wool
setblock ~37 ~ ~20 minecraft:quartz_stairs["weirdo_direction":1,"upside_down_bit":false]
setblock ~36 ~ ~20 minecraft:quartz_slab
setblock ~37 ~1 ~20 minecraft:white_wool
# Poolside bar and pergola
fill ~21 ~ ~24 ~27 ~ ~24 minecraft:warped_planks
fill ~21 ~1 ~24 ~27 ~1 ~24 minecraft:quartz_slab
setblock ~22 ~ ~23 minecraft:dark_oak_stairs["weirdo_direction":3,"upside_down_bit":false]
setblock ~24 ~ ~23 minecraft:dark_oak_stairs["weirdo_direction":3,"upside_down_bit":false]
setblock ~26 ~ ~23 minecraft:dark_oak_stairs["weirdo_direction":3,"upside_down_bit":false]
fill ~21 ~ ~25 ~21 ~3 ~25 minecraft:dark_oak_fence
setblock ~21 ~4 ~25 minecraft:dark_oak_slab
fill ~27 ~ ~25 ~27 ~3 ~25 minecraft:dark_oak_fence
setblock ~27 ~4 ~25 minecraft:dark_oak_slab
fill ~21 ~4 ~24 ~27 ~4 ~26 minecraft:dark_oak_slab
setblock ~22 ~3 ~25 minecraft:lantern["hanging":true]
setblock ~24 ~3 ~25 minecraft:lantern["hanging":true]
setblock ~26 ~3 ~25 minecraft:lantern["hanging":true]
# Pool lighting - deck lights are always-on
setblock ~23 ~-2 ~10 minecraft:sea_lantern
setblock ~35 ~-2 ~10 minecraft:sea_lantern
setblock ~23 ~-2 ~14 minecraft:sea_lantern
setblock ~35 ~-2 ~14 minecraft:sea_lantern
setblock ~23 ~-2 ~18 minecraft:sea_lantern
setblock ~35 ~-2 ~18 minecraft:sea_lantern
setblock ~24 ~ ~23 minecraft:end_rod["facing_direction":1]
setblock ~29 ~ ~23 minecraft:end_rod["facing_direction":1]
setblock ~34 ~ ~23 minecraft:end_rod["facing_direction":1]
# Changing cabana
fill ~31 ~ ~24 ~35 ~ ~27 minecraft:light_gray_concrete
fill ~31 ~3 ~24 ~35 ~3 ~27 minecraft:light_gray_concrete
fill ~31 ~ ~24 ~35 ~3 ~24 minecraft:light_gray_concrete
fill ~31 ~ ~27 ~35 ~3 ~27 minecraft:light_gray_concrete
fill ~31 ~ ~24 ~31 ~3 ~27 minecraft:light_gray_concrete
fill ~35 ~ ~24 ~35 ~3 ~27 minecraft:light_gray_concrete
fill ~33 ~ ~24 ~33 ~2 ~24 minecraft:air
setblock ~32 ~ ~26 minecraft:barrel["facing_direction":1,"open_bit":false]
setblock ~34 ~ ~26 minecraft:redstone_lamp
setblock ~20 ~3 ~4 myc:alarm_light
setblock ~38 ~3 ~26 myc:alarm_light
# --- 27 garage with three bays ---
# Garage shell
fill ~-38 ~-1 ~6 ~-20 ~-1 ~22 minecraft:deepslate_tiles
fill ~-38 ~ ~6 ~-20 ~4 ~6 minecraft:light_gray_concrete
fill ~-38 ~ ~22 ~-20 ~4 ~22 minecraft:light_gray_concrete
fill ~-38 ~ ~6 ~-38 ~4 ~22 minecraft:light_gray_concrete
fill ~-20 ~ ~6 ~-20 ~4 ~22 minecraft:light_gray_concrete
fill ~-38 ~5 ~6 ~-20 ~5 ~22 minecraft:polished_deepslate
fill ~-37 ~ ~7 ~-21 ~4 ~21 minecraft:air
# Three bay mouths on the south elevation - PURE AIR, each a seal
fill ~-36 ~ ~22 ~-33 ~4 ~22 minecraft:air
fill ~-37 ~ ~22 ~-37 ~4 ~22 minecraft:polished_blackstone
fill ~-32 ~ ~22 ~-32 ~4 ~22 minecraft:polished_blackstone
fill ~-36 ~5 ~22 ~-33 ~5 ~22 myc:clean_panel
setblock ~-35 ~5 ~21 minecraft:sea_lantern
setblock ~-34 ~5 ~21 minecraft:sea_lantern
setblock ~-36 ~5 ~21 myc:alarm_light
fill ~-30 ~ ~22 ~-27 ~4 ~22 minecraft:air
fill ~-31 ~ ~22 ~-31 ~4 ~22 minecraft:polished_blackstone
fill ~-26 ~ ~22 ~-26 ~4 ~22 minecraft:polished_blackstone
fill ~-30 ~5 ~22 ~-27 ~5 ~22 myc:clean_panel
setblock ~-29 ~5 ~21 minecraft:sea_lantern
setblock ~-28 ~5 ~21 minecraft:sea_lantern
setblock ~-30 ~5 ~21 myc:alarm_light
fill ~-24 ~ ~22 ~-21 ~4 ~22 minecraft:air
fill ~-25 ~ ~22 ~-25 ~4 ~22 minecraft:polished_blackstone
fill ~-20 ~ ~22 ~-20 ~4 ~22 minecraft:polished_blackstone
fill ~-24 ~5 ~22 ~-21 ~5 ~22 myc:clean_panel
setblock ~-23 ~5 ~21 minecraft:sea_lantern
setblock ~-22 ~5 ~21 minecraft:sea_lantern
setblock ~-24 ~5 ~21 myc:alarm_light
# Bay floor markings
setblock ~-37 ~-1 ~8 minecraft:yellow_concrete
setblock ~-32 ~-1 ~8 minecraft:yellow_concrete
setblock ~-37 ~-1 ~9 minecraft:yellow_concrete
setblock ~-32 ~-1 ~9 minecraft:yellow_concrete
setblock ~-37 ~-1 ~10 minecraft:yellow_concrete
setblock ~-32 ~-1 ~10 minecraft:yellow_concrete
setblock ~-37 ~-1 ~11 minecraft:yellow_concrete
setblock ~-32 ~-1 ~11 minecraft:yellow_concrete
setblock ~-37 ~-1 ~12 minecraft:yellow_concrete
setblock ~-32 ~-1 ~12 minecraft:yellow_concrete
