# part_04.mcfunction - generated by tools/gen_mansion.py, do not edit
# Relative coordinates only; run via execute positioned <x> <y> <z>
# (continued: 13 home cinema)
fill ~-16 ~17 ~-17 ~-8 ~20 ~-17 myc:screen
fill ~-17 ~16 ~-16 ~-17 ~20 ~-16 myc:clean_panel
fill ~-7 ~16 ~-16 ~-7 ~20 ~-16 myc:clean_panel
# Three tiers of seating, each one block higher
fill ~-17 ~15 ~-13 ~-7 ~15 ~-12 minecraft:polished_blackstone
setblock ~-16 ~16 ~-13 minecraft:dark_oak_stairs["weirdo_direction":3,"upside_down_bit":false]
setblock ~-15 ~16 ~-13 minecraft:dark_oak_stairs["weirdo_direction":3,"upside_down_bit":false]
setblock ~-14 ~16 ~-13 minecraft:dark_oak_stairs["weirdo_direction":3,"upside_down_bit":false]
setblock ~-13 ~16 ~-13 minecraft:dark_oak_stairs["weirdo_direction":3,"upside_down_bit":false]
setblock ~-12 ~16 ~-13 minecraft:dark_oak_stairs["weirdo_direction":3,"upside_down_bit":false]
setblock ~-11 ~16 ~-13 minecraft:dark_oak_stairs["weirdo_direction":3,"upside_down_bit":false]
setblock ~-10 ~16 ~-13 minecraft:dark_oak_stairs["weirdo_direction":3,"upside_down_bit":false]
setblock ~-9 ~16 ~-13 minecraft:dark_oak_stairs["weirdo_direction":3,"upside_down_bit":false]
setblock ~-8 ~16 ~-13 minecraft:dark_oak_stairs["weirdo_direction":3,"upside_down_bit":false]
setblock ~-17 ~16 ~-13 minecraft:red_wool
setblock ~-7 ~16 ~-13 minecraft:red_wool
setblock ~-16 ~16 ~-12 minecraft:dark_oak_slab
setblock ~-12 ~16 ~-12 minecraft:dark_oak_slab
setblock ~-8 ~16 ~-12 minecraft:dark_oak_slab
fill ~-17 ~16 ~-10 ~-7 ~16 ~-9 minecraft:polished_blackstone
setblock ~-16 ~17 ~-10 minecraft:dark_oak_stairs["weirdo_direction":3,"upside_down_bit":false]
setblock ~-15 ~17 ~-10 minecraft:dark_oak_stairs["weirdo_direction":3,"upside_down_bit":false]
setblock ~-14 ~17 ~-10 minecraft:dark_oak_stairs["weirdo_direction":3,"upside_down_bit":false]
setblock ~-13 ~17 ~-10 minecraft:dark_oak_stairs["weirdo_direction":3,"upside_down_bit":false]
setblock ~-12 ~17 ~-10 minecraft:dark_oak_stairs["weirdo_direction":3,"upside_down_bit":false]
setblock ~-11 ~17 ~-10 minecraft:dark_oak_stairs["weirdo_direction":3,"upside_down_bit":false]
setblock ~-10 ~17 ~-10 minecraft:dark_oak_stairs["weirdo_direction":3,"upside_down_bit":false]
setblock ~-9 ~17 ~-10 minecraft:dark_oak_stairs["weirdo_direction":3,"upside_down_bit":false]
setblock ~-8 ~17 ~-10 minecraft:dark_oak_stairs["weirdo_direction":3,"upside_down_bit":false]
setblock ~-17 ~17 ~-10 minecraft:red_wool
setblock ~-7 ~17 ~-10 minecraft:red_wool
setblock ~-16 ~17 ~-9 minecraft:dark_oak_slab
setblock ~-12 ~17 ~-9 minecraft:dark_oak_slab
setblock ~-8 ~17 ~-9 minecraft:dark_oak_slab
fill ~-17 ~17 ~-7 ~-7 ~17 ~-6 minecraft:polished_blackstone
setblock ~-16 ~18 ~-7 minecraft:dark_oak_stairs["weirdo_direction":3,"upside_down_bit":false]
setblock ~-15 ~18 ~-7 minecraft:dark_oak_stairs["weirdo_direction":3,"upside_down_bit":false]
setblock ~-14 ~18 ~-7 minecraft:dark_oak_stairs["weirdo_direction":3,"upside_down_bit":false]
setblock ~-13 ~18 ~-7 minecraft:dark_oak_stairs["weirdo_direction":3,"upside_down_bit":false]
setblock ~-12 ~18 ~-7 minecraft:dark_oak_stairs["weirdo_direction":3,"upside_down_bit":false]
setblock ~-11 ~18 ~-7 minecraft:dark_oak_stairs["weirdo_direction":3,"upside_down_bit":false]
setblock ~-10 ~18 ~-7 minecraft:dark_oak_stairs["weirdo_direction":3,"upside_down_bit":false]
setblock ~-9 ~18 ~-7 minecraft:dark_oak_stairs["weirdo_direction":3,"upside_down_bit":false]
setblock ~-8 ~18 ~-7 minecraft:dark_oak_stairs["weirdo_direction":3,"upside_down_bit":false]
setblock ~-17 ~18 ~-7 minecraft:red_wool
setblock ~-7 ~18 ~-7 minecraft:red_wool
setblock ~-16 ~18 ~-6 minecraft:dark_oak_slab
setblock ~-12 ~18 ~-6 minecraft:dark_oak_slab
setblock ~-8 ~18 ~-6 minecraft:dark_oak_slab
# Aisle lighting and acoustic panelling
setblock ~-17 ~16 ~-16 minecraft:redstone_lamp
setblock ~-17 ~16 ~-14 minecraft:redstone_lamp
setblock ~-17 ~16 ~-12 minecraft:redstone_lamp
setblock ~-17 ~16 ~-10 minecraft:redstone_lamp
setblock ~-17 ~16 ~-8 minecraft:redstone_lamp
setblock ~-17 ~16 ~-6 minecraft:redstone_lamp
setblock ~-17 ~16 ~-4 minecraft:redstone_lamp
fill ~-17 ~21 ~-16 ~-7 ~21 ~-2 myc:clean_panel
setblock ~-15 ~21 ~-5 minecraft:sea_lantern
setblock ~-12 ~21 ~-5 minecraft:sea_lantern
setblock ~-9 ~21 ~-5 minecraft:sea_lantern
setblock ~-8 ~16 ~-2 myc:control_panel
setblock ~-7 ~19 ~-2 myc:alarm_light
# --- 14 gym ---
fill ~5 ~15 ~-11 ~17 ~15 ~-1 minecraft:dark_oak_planks
fill ~5 ~23 ~-11 ~17 ~23 ~-1 minecraft:dark_oak_planks
fill ~5 ~16 ~-1 ~17 ~22 ~-1 minecraft:light_gray_concrete
fill ~5 ~16 ~-11 ~17 ~22 ~-11 minecraft:light_gray_concrete
fill ~5 ~16 ~-11 ~5 ~22 ~-1 minecraft:light_gray_concrete
fill ~17 ~16 ~-11 ~17 ~22 ~-1 minecraft:light_gray_concrete
fill ~5 ~16 ~-6 ~5 ~18 ~-4 minecraft:air
# Mirrored wall and rubber flooring
fill ~6 ~15 ~-10 ~16 ~15 ~-2 minecraft:black_carpet
fill ~17 ~16 ~-10 ~17 ~19 ~-2 minecraft:white_stained_glass
# Weight racks built from blocks
fill ~7 ~16 ~-3 ~7 ~17 ~-3 minecraft:iron_block
setblock ~7 ~18 ~-3 minecraft:polished_blackstone_slab
setblock ~8 ~16 ~-3 minecraft:anvil["damage":"undamaged","minecraft:cardinal_direction":"north"]
fill ~10 ~16 ~-3 ~10 ~17 ~-3 minecraft:iron_block
setblock ~10 ~18 ~-3 minecraft:polished_blackstone_slab
setblock ~11 ~16 ~-3 minecraft:anvil["damage":"undamaged","minecraft:cardinal_direction":"north"]
fill ~13 ~16 ~-3 ~13 ~17 ~-3 minecraft:iron_block
setblock ~13 ~18 ~-3 minecraft:polished_blackstone_slab
setblock ~14 ~16 ~-3 minecraft:anvil["damage":"undamaged","minecraft:cardinal_direction":"north"]
# Benches
setblock ~7 ~16 ~-6 minecraft:dark_oak_slab
setblock ~8 ~16 ~-6 minecraft:dark_oak_slab
setblock ~9 ~16 ~-6 minecraft:dark_oak_slab
setblock ~10 ~16 ~-6 minecraft:dark_oak_slab
setblock ~6 ~16 ~-6 minecraft:black_wool
setblock ~7 ~16 ~-8 minecraft:dark_oak_slab
setblock ~8 ~16 ~-8 minecraft:dark_oak_slab
setblock ~9 ~16 ~-8 minecraft:dark_oak_slab
setblock ~10 ~16 ~-8 minecraft:dark_oak_slab
setblock ~6 ~16 ~-8 minecraft:black_wool
# Treadmills and cardio row
setblock ~12 ~16 ~-9 minecraft:polished_blackstone
setblock ~12 ~17 ~-9 myc:screen
setblock ~12 ~16 ~-8 minecraft:smooth_stone_slab
setblock ~14 ~16 ~-9 minecraft:polished_blackstone
setblock ~14 ~17 ~-9 myc:screen
setblock ~14 ~16 ~-8 minecraft:smooth_stone_slab
setblock ~16 ~16 ~-9 minecraft:polished_blackstone
setblock ~16 ~17 ~-9 myc:screen
setblock ~16 ~16 ~-8 minecraft:smooth_stone_slab
# Storage and hydration
setblock ~6 ~16 ~-10 minecraft:barrel["facing_direction":1,"open_bit":false]
setblock ~7 ~16 ~-10 minecraft:barrel["facing_direction":1,"open_bit":false]
setblock ~8 ~16 ~-10 minecraft:barrel["facing_direction":1,"open_bit":false]
setblock ~16 ~16 ~-3 minecraft:cauldron["cauldron_liquid":"water","fill_level":6]
setblock ~6 ~21 ~-9 minecraft:sea_lantern
setblock ~9 ~21 ~-9 minecraft:sea_lantern
setblock ~12 ~21 ~-9 minecraft:sea_lantern
setblock ~15 ~21 ~-9 minecraft:sea_lantern
setblock ~6 ~21 ~-3 minecraft:redstone_lamp
setblock ~10 ~21 ~-3 minecraft:redstone_lamp
setblock ~14 ~21 ~-3 minecraft:redstone_lamp
setblock ~5 ~19 ~-2 myc:alarm_light
# --- 15 gaming room + lounge ---
fill ~5 ~15 ~-22 ~17 ~15 ~-12 minecraft:black_carpet
fill ~5 ~23 ~-22 ~17 ~23 ~-12 minecraft:polished_deepslate
fill ~5 ~16 ~-12 ~17 ~22 ~-12 minecraft:black_concrete
fill ~5 ~16 ~-22 ~17 ~22 ~-22 minecraft:black_concrete
fill ~5 ~16 ~-22 ~5 ~22 ~-12 minecraft:black_concrete
fill ~17 ~16 ~-22 ~17 ~22 ~-12 minecraft:black_concrete
fill ~5 ~16 ~-17 ~5 ~18 ~-15 minecraft:air
setblock ~5 ~16 ~-16 minecraft:warped_door["direction":3,"door_hinge_bit":false,"open_bit":false,"upper_block_bit":false]
setblock ~5 ~17 ~-16 minecraft:warped_door["direction":3,"door_hinge_bit":false,"open_bit":false,"upper_block_bit":true]
# Six-monitor primary battlestation
fill ~7 ~16 ~-21 ~15 ~16 ~-21 minecraft:polished_blackstone
fill ~7 ~17 ~-21 ~15 ~17 ~-21 minecraft:quartz_slab
fill ~6 ~17 ~-22 ~9 ~20 ~-22 minecraft:black_concrete
fill ~7 ~18 ~-22 ~8 ~19 ~-22 myc:screen
fill ~9 ~17 ~-22 ~12 ~20 ~-22 minecraft:black_concrete
fill ~10 ~18 ~-22 ~11 ~19 ~-22 myc:screen
fill ~12 ~17 ~-22 ~15 ~20 ~-22 minecraft:black_concrete
fill ~13 ~18 ~-22 ~14 ~19 ~-22 myc:screen
setblock ~11 ~17 ~-21 myc:control_panel
fill ~8 ~16 ~-20 ~8 ~17 ~-20 myc:server_rack
fill ~14 ~16 ~-20 ~14 ~17 ~-20 myc:server_rack
# Chairs
setblock ~8 ~16 ~-20 minecraft:dark_oak_stairs["weirdo_direction":3,"upside_down_bit":false]
setblock ~8 ~17 ~-20 minecraft:black_wool
setblock ~11 ~16 ~-20 minecraft:dark_oak_stairs["weirdo_direction":3,"upside_down_bit":false]
setblock ~11 ~17 ~-20 minecraft:black_wool
setblock ~14 ~16 ~-20 minecraft:dark_oak_stairs["weirdo_direction":3,"upside_down_bit":false]
setblock ~14 ~17 ~-20 minecraft:black_wool
# Secondary consoles and streaming corner
fill ~7 ~16 ~-14 ~10 ~16 ~-14 minecraft:polished_blackstone
fill ~7 ~17 ~-14 ~10 ~17 ~-14 minecraft:dark_oak_slab
fill ~7 ~17 ~-13 ~10 ~20 ~-13 minecraft:black_concrete
fill ~8 ~18 ~-13 ~9 ~19 ~-13 myc:screen
setblock ~7 ~17 ~-14 minecraft:jukebox
setblock ~10 ~17 ~-14 minecraft:noteblock
# Lounge seating
setblock ~13 ~16 ~-14 minecraft:dark_oak_stairs["weirdo_direction":3,"upside_down_bit":false]
setblock ~14 ~16 ~-14 minecraft:dark_oak_stairs["weirdo_direction":3,"upside_down_bit":false]
setblock ~15 ~16 ~-14 minecraft:dark_oak_stairs["weirdo_direction":3,"upside_down_bit":false]
setblock ~16 ~16 ~-14 minecraft:dark_oak_stairs["weirdo_direction":3,"upside_down_bit":false]
setblock ~12 ~16 ~-14 minecraft:cyan_wool
setblock ~17 ~16 ~-14 minecraft:cyan_wool
setblock ~14 ~16 ~-16 minecraft:dark_oak_fence
setblock ~14 ~16 ~-15 minecraft:dark_oak_fence
setblock ~15 ~16 ~-16 minecraft:dark_oak_fence
setblock ~15 ~16 ~-15 minecraft:dark_oak_fence
fill ~14 ~17 ~-16 ~15 ~17 ~-15 minecraft:quartz_slab
fill ~13 ~15 ~-17 ~16 ~15 ~-13 minecraft:blue_carpet
# RGB cove lighting
setblock ~6 ~21 ~-22 minecraft:lime_stained_glass
setblock ~8 ~21 ~-22 minecraft:red_stained_glass
setblock ~10 ~21 ~-22 minecraft:red_stained_glass
setblock ~12 ~21 ~-22 minecraft:cyan_stained_glass
setblock ~14 ~21 ~-22 minecraft:cyan_stained_glass
setblock ~16 ~21 ~-22 minecraft:red_stained_glass
setblock ~6 ~21 ~-18 minecraft:redstone_lamp
setblock ~9 ~21 ~-18 minecraft:redstone_lamp
setblock ~12 ~21 ~-18 minecraft:redstone_lamp
setblock ~15 ~21 ~-18 minecraft:redstone_lamp
setblock ~6 ~20 ~-21 minecraft:sea_lantern
setblock ~6 ~20 ~-14 minecraft:sea_lantern
setblock ~5 ~19 ~-22 myc:alarm_light
# Central lounge between cinema and gym
fill ~-5 ~15 ~-13 ~4 ~15 ~-2 minecraft:dark_oak_planks
setblock ~-3 ~16 ~-4 minecraft:dark_oak_stairs["weirdo_direction":3,"upside_down_bit":false]
setblock ~-2 ~16 ~-4 minecraft:dark_oak_stairs["weirdo_direction":3,"upside_down_bit":false]
setblock ~-1 ~16 ~-4 minecraft:dark_oak_stairs["weirdo_direction":3,"upside_down_bit":false]
setblock ~ ~16 ~-4 minecraft:dark_oak_stairs["weirdo_direction":3,"upside_down_bit":false]
setblock ~1 ~16 ~-4 minecraft:dark_oak_stairs["weirdo_direction":3,"upside_down_bit":false]
setblock ~2 ~16 ~-4 minecraft:dark_oak_stairs["weirdo_direction":3,"upside_down_bit":false]
setblock ~-4 ~16 ~-4 minecraft:gray_wool
setblock ~3 ~16 ~-4 minecraft:gray_wool
setblock ~-3 ~16 ~-11 minecraft:dark_oak_stairs["weirdo_direction":2,"upside_down_bit":false]
setblock ~-2 ~16 ~-11 minecraft:dark_oak_stairs["weirdo_direction":2,"upside_down_bit":false]
setblock ~-1 ~16 ~-11 minecraft:dark_oak_stairs["weirdo_direction":2,"upside_down_bit":false]
setblock ~ ~16 ~-11 minecraft:dark_oak_stairs["weirdo_direction":2,"upside_down_bit":false]
