# part_83.mcfunction - generated by tools/gen_mansion.py, do not edit
# Relative coordinates only; run via execute positioned <x> <y> <z>
# (continued: 27 garage with three bays)
setblock ~-32 ~-1 ~10 minecraft:yellow_concrete
setblock ~-37 ~-1 ~11 minecraft:yellow_concrete
setblock ~-32 ~-1 ~11 minecraft:yellow_concrete
setblock ~-37 ~-1 ~12 minecraft:yellow_concrete
setblock ~-32 ~-1 ~12 minecraft:yellow_concrete
setblock ~-37 ~-1 ~13 minecraft:yellow_concrete
setblock ~-32 ~-1 ~13 minecraft:yellow_concrete
setblock ~-37 ~-1 ~14 minecraft:yellow_concrete
setblock ~-32 ~-1 ~14 minecraft:yellow_concrete
setblock ~-37 ~-1 ~15 minecraft:yellow_concrete
setblock ~-32 ~-1 ~15 minecraft:yellow_concrete
setblock ~-37 ~-1 ~16 minecraft:yellow_concrete
setblock ~-32 ~-1 ~16 minecraft:yellow_concrete
setblock ~-37 ~-1 ~17 minecraft:yellow_concrete
setblock ~-32 ~-1 ~17 minecraft:yellow_concrete
setblock ~-37 ~-1 ~18 minecraft:yellow_concrete
setblock ~-32 ~-1 ~18 minecraft:yellow_concrete
setblock ~-37 ~-1 ~19 minecraft:yellow_concrete
setblock ~-32 ~-1 ~19 minecraft:yellow_concrete
setblock ~-37 ~-1 ~20 minecraft:yellow_concrete
setblock ~-32 ~-1 ~20 minecraft:yellow_concrete
setblock ~-37 ~-1 ~21 minecraft:yellow_concrete
setblock ~-32 ~-1 ~21 minecraft:yellow_concrete
setblock ~-31 ~-1 ~8 minecraft:yellow_concrete
setblock ~-26 ~-1 ~8 minecraft:yellow_concrete
setblock ~-31 ~-1 ~9 minecraft:yellow_concrete
setblock ~-26 ~-1 ~9 minecraft:yellow_concrete
setblock ~-31 ~-1 ~10 minecraft:yellow_concrete
setblock ~-26 ~-1 ~10 minecraft:yellow_concrete
setblock ~-31 ~-1 ~11 minecraft:yellow_concrete
setblock ~-26 ~-1 ~11 minecraft:yellow_concrete
setblock ~-31 ~-1 ~12 minecraft:yellow_concrete
setblock ~-26 ~-1 ~12 minecraft:yellow_concrete
setblock ~-31 ~-1 ~13 minecraft:yellow_concrete
setblock ~-26 ~-1 ~13 minecraft:yellow_concrete
setblock ~-31 ~-1 ~14 minecraft:yellow_concrete
setblock ~-26 ~-1 ~14 minecraft:yellow_concrete
setblock ~-31 ~-1 ~15 minecraft:yellow_concrete
setblock ~-26 ~-1 ~15 minecraft:yellow_concrete
setblock ~-31 ~-1 ~16 minecraft:yellow_concrete
setblock ~-26 ~-1 ~16 minecraft:yellow_concrete
setblock ~-31 ~-1 ~17 minecraft:yellow_concrete
setblock ~-26 ~-1 ~17 minecraft:yellow_concrete
setblock ~-31 ~-1 ~18 minecraft:yellow_concrete
setblock ~-26 ~-1 ~18 minecraft:yellow_concrete
setblock ~-31 ~-1 ~19 minecraft:yellow_concrete
setblock ~-26 ~-1 ~19 minecraft:yellow_concrete
setblock ~-31 ~-1 ~20 minecraft:yellow_concrete
setblock ~-26 ~-1 ~20 minecraft:yellow_concrete
setblock ~-31 ~-1 ~21 minecraft:yellow_concrete
setblock ~-26 ~-1 ~21 minecraft:yellow_concrete
setblock ~-25 ~-1 ~8 minecraft:yellow_concrete
setblock ~-20 ~-1 ~8 minecraft:yellow_concrete
setblock ~-25 ~-1 ~9 minecraft:yellow_concrete
setblock ~-20 ~-1 ~9 minecraft:yellow_concrete
setblock ~-25 ~-1 ~10 minecraft:yellow_concrete
setblock ~-20 ~-1 ~10 minecraft:yellow_concrete
setblock ~-25 ~-1 ~11 minecraft:yellow_concrete
setblock ~-20 ~-1 ~11 minecraft:yellow_concrete
setblock ~-25 ~-1 ~12 minecraft:yellow_concrete
setblock ~-20 ~-1 ~12 minecraft:yellow_concrete
setblock ~-25 ~-1 ~13 minecraft:yellow_concrete
setblock ~-20 ~-1 ~13 minecraft:yellow_concrete
setblock ~-25 ~-1 ~14 minecraft:yellow_concrete
setblock ~-20 ~-1 ~14 minecraft:yellow_concrete
setblock ~-25 ~-1 ~15 minecraft:yellow_concrete
setblock ~-20 ~-1 ~15 minecraft:yellow_concrete
setblock ~-25 ~-1 ~16 minecraft:yellow_concrete
setblock ~-20 ~-1 ~16 minecraft:yellow_concrete
setblock ~-25 ~-1 ~17 minecraft:yellow_concrete
setblock ~-20 ~-1 ~17 minecraft:yellow_concrete
setblock ~-25 ~-1 ~18 minecraft:yellow_concrete
setblock ~-20 ~-1 ~18 minecraft:yellow_concrete
setblock ~-25 ~-1 ~19 minecraft:yellow_concrete
setblock ~-20 ~-1 ~19 minecraft:yellow_concrete
setblock ~-25 ~-1 ~20 minecraft:yellow_concrete
setblock ~-20 ~-1 ~20 minecraft:yellow_concrete
setblock ~-25 ~-1 ~21 minecraft:yellow_concrete
setblock ~-20 ~-1 ~21 minecraft:yellow_concrete
# Workshop wall
setblock ~-36 ~ ~7 minecraft:barrel["facing_direction":1,"open_bit":false]
setblock ~-36 ~1 ~7 myc:clean_panel
setblock ~-34 ~ ~7 minecraft:barrel["facing_direction":1,"open_bit":false]
setblock ~-34 ~1 ~7 myc:clean_panel
setblock ~-32 ~ ~7 minecraft:barrel["facing_direction":1,"open_bit":false]
setblock ~-32 ~1 ~7 myc:clean_panel
setblock ~-30 ~ ~7 minecraft:barrel["facing_direction":1,"open_bit":false]
setblock ~-30 ~1 ~7 myc:clean_panel
setblock ~-37 ~ ~7 minecraft:crafting_table
setblock ~-36 ~1 ~8 minecraft:anvil["damage":"undamaged","minecraft:cardinal_direction":"south"]
fill ~-34 ~ ~8 ~-30 ~ ~8 minecraft:polished_blackstone
fill ~-34 ~1 ~8 ~-30 ~1 ~8 minecraft:quartz_slab
fill ~-34 ~1 ~7 ~-30 ~4 ~7 minecraft:black_concrete
fill ~-33 ~2 ~7 ~-31 ~3 ~7 myc:screen
setblock ~-34 ~1 ~8 myc:control_panel
# Charging points
setblock ~-35 ~ ~7 minecraft:redstone_lamp
setblock ~-34 ~1 ~7 myc:screen
setblock ~-29 ~ ~7 minecraft:redstone_lamp
setblock ~-28 ~1 ~7 myc:screen
setblock ~-23 ~ ~7 minecraft:redstone_lamp
setblock ~-22 ~1 ~7 myc:screen
# Apron connecting the bays to the driveway
fill ~-38 ~-1 ~23 ~-20 ~-1 ~28 minecraft:polished_blackstone
fill ~-19 ~-1 ~24 ~-7 ~-1 ~27 minecraft:polished_blackstone
setblock ~-36 ~5 ~9 minecraft:redstone_lamp
setblock ~-32 ~5 ~9 minecraft:redstone_lamp
setblock ~-28 ~5 ~9 minecraft:redstone_lamp
setblock ~-24 ~5 ~9 minecraft:redstone_lamp
# --- 23 escape tunnel + concealed exit ---
# Tunnel bore, 38 blocks south under the grounds
fill ~-12 ~-21 ~-4 ~-8 ~-17 ~34 minecraft:deepslate_bricks
fill ~-11 ~-20 ~-4 ~-9 ~-18 ~34 minecraft:air
fill ~-11 ~-21 ~-4 ~-9 ~-21 ~34 minecraft:deepslate_tiles
# Tunnel mouth in the bunker's south wall - PURE AIR, seal
fill ~-11 ~-20 ~-4 ~-9 ~-18 ~-4 minecraft:air
# Tunnel services: lighting, alarms, ribs
setblock ~-11 ~-18 ~-2 minecraft:redstone_lamp
setblock ~-9 ~-18 ~-2 minecraft:redstone_lamp
setblock ~-11 ~-18 ~4 minecraft:redstone_lamp
setblock ~-9 ~-18 ~4 minecraft:redstone_lamp
setblock ~-11 ~-18 ~10 minecraft:redstone_lamp
setblock ~-9 ~-18 ~10 minecraft:redstone_lamp
setblock ~-11 ~-18 ~16 minecraft:redstone_lamp
setblock ~-9 ~-18 ~16 minecraft:redstone_lamp
setblock ~-11 ~-18 ~22 minecraft:redstone_lamp
setblock ~-9 ~-18 ~22 minecraft:redstone_lamp
setblock ~-11 ~-18 ~28 minecraft:redstone_lamp
setblock ~-9 ~-18 ~28 minecraft:redstone_lamp
setblock ~-12 ~-19 ~ myc:alarm_light
fill ~-12 ~-20 ~1 ~-12 ~-18 ~1 myc:clean_panel
fill ~-8 ~-20 ~1 ~-8 ~-18 ~1 myc:clean_panel
setblock ~-12 ~-19 ~8 myc:alarm_light
fill ~-12 ~-20 ~9 ~-12 ~-18 ~9 myc:clean_panel
fill ~-8 ~-20 ~9 ~-8 ~-18 ~9 myc:clean_panel
setblock ~-12 ~-19 ~16 myc:alarm_light
fill ~-12 ~-20 ~17 ~-12 ~-18 ~17 myc:clean_panel
fill ~-8 ~-20 ~17 ~-8 ~-18 ~17 myc:clean_panel
setblock ~-12 ~-19 ~24 myc:alarm_light
fill ~-12 ~-20 ~25 ~-12 ~-18 ~25 myc:clean_panel
fill ~-8 ~-20 ~25 ~-8 ~-18 ~25 myc:clean_panel
setblock ~-12 ~-19 ~32 myc:alarm_light
fill ~-12 ~-20 ~33 ~-12 ~-18 ~33 myc:clean_panel
fill ~-8 ~-20 ~33 ~-8 ~-18 ~33 myc:clean_panel
# Supply cache half way along
setblock ~-11 ~-20 ~14 minecraft:barrel["facing_direction":5,"open_bit":false]
setblock ~-11 ~-20 ~16 minecraft:barrel["facing_direction":5,"open_bit":false]
setblock ~-9 ~-20 ~15 minecraft:chest["minecraft:cardinal_direction":"west"]
# Vertical exit shaft up to the garden, with a ladder
fill ~-12 ~-21 ~33 ~-10 ~-1 ~35 minecraft:deepslate_bricks
fill ~-11 ~-20 ~33 ~-11 ~-2 ~34 minecraft:air
setblock ~-11 ~-20 ~34 minecraft:ladder["facing_direction":3]
setblock ~-11 ~-19 ~34 minecraft:ladder["facing_direction":3]
setblock ~-11 ~-18 ~34 minecraft:ladder["facing_direction":3]
setblock ~-11 ~-17 ~34 minecraft:ladder["facing_direction":3]
setblock ~-11 ~-16 ~34 minecraft:ladder["facing_direction":3]
setblock ~-11 ~-15 ~34 minecraft:ladder["facing_direction":3]
setblock ~-11 ~-14 ~34 minecraft:ladder["facing_direction":3]
setblock ~-11 ~-13 ~34 minecraft:ladder["facing_direction":3]
setblock ~-11 ~-12 ~34 minecraft:ladder["facing_direction":3]
setblock ~-11 ~-11 ~34 minecraft:ladder["facing_direction":3]
setblock ~-11 ~-10 ~34 minecraft:ladder["facing_direction":3]
setblock ~-11 ~-9 ~34 minecraft:ladder["facing_direction":3]
setblock ~-11 ~-8 ~34 minecraft:ladder["facing_direction":3]
setblock ~-11 ~-7 ~34 minecraft:ladder["facing_direction":3]
setblock ~-11 ~-6 ~34 minecraft:ladder["facing_direction":3]
setblock ~-11 ~-5 ~34 minecraft:ladder["facing_direction":3]
setblock ~-11 ~-4 ~34 minecraft:ladder["facing_direction":3]
setblock ~-11 ~-3 ~34 minecraft:ladder["facing_direction":3]
setblock ~-11 ~-2 ~34 minecraft:ladder["facing_direction":3]
# Concealed hatch at the surface, hidden inside a hedge block
fill ~-11 ~-1 ~33 ~-11 ~-1 ~34 minecraft:air
setblock ~-11 ~ ~34 minecraft:trapdoor["direction":0,"open_bit":false,"upside_down_bit":false]
fill ~-13 ~ ~32 ~-9 ~1 ~32 minecraft:azalea_leaves["persistent_bit":true,"update_bit":false]
fill ~-13 ~ ~35 ~-9 ~1 ~35 minecraft:azalea_leaves["persistent_bit":true,"update_bit":false]
setblock ~-12 ~ ~34 minecraft:azalea_leaves["persistent_bit":true,"update_bit":false]
setblock ~-10 ~ ~34 minecraft:azalea_leaves["persistent_bit":true,"update_bit":false]
setblock ~-10 ~-19 ~33 myc:alarm_light
# --- 28 detail pass - cladding, alarms, smart lighting ---
# myc:clean_panel cladding bands through the circulation cores
fill ~-6 ~6 ~-12 ~6 ~6 ~-1 myc:clean_panel
fill ~-6 ~14 ~-12 ~6 ~14 ~-1 myc:clean_panel
fill ~-5 ~22 ~-12 ~4 ~22 ~-2 myc:clean_panel
fill ~-18 ~6 ~-26 ~-18 ~6 ~-1 myc:clean_panel
fill ~18 ~6 ~-26 ~18 ~6 ~-1 myc:clean_panel
# Skirting and reveal detail on the main floors
fill ~-18 ~ ~-26 ~18 ~ ~-26 minecraft:polished_deepslate_slab
fill ~-18 ~ ~-1 ~18 ~ ~-1 minecraft:polished_deepslate_slab
fill ~-18 ~7 ~-26 ~18 ~7 ~-26 minecraft:polished_deepslate_slab
fill ~-18 ~7 ~-1 ~18 ~7 ~-1 minecraft:polished_deepslate_slab
fill ~-18 ~15 ~-26 ~18 ~15 ~-26 minecraft:polished_deepslate_slab
fill ~-18 ~15 ~-1 ~18 ~15 ~-1 minecraft:polished_deepslate_slab
# Perimeter alarm lights near every exit and stair core
setblock ~-5 ~4 ~-1 myc:alarm_light
