# part_00.mcfunction - generated by tools/gen_mansion.py, do not edit
# Relative coordinates only; run via execute positioned <x> <y> <z>
# --- 00 site clear + terrain pad ---
# Clear the working envelope, then lay ground.
fill ~-40 ~-30 ~-40 ~-20 ~2 ~ minecraft:air
fill ~-19 ~-30 ~-40 ~ ~2 ~ minecraft:air
fill ~-40 ~3 ~-40 ~-20 ~34 ~ minecraft:air
fill ~-19 ~3 ~-40 ~ ~34 ~ minecraft:air
fill ~-40 ~-30 ~1 ~-20 ~2 ~40 minecraft:air
fill ~-19 ~-30 ~1 ~ ~2 ~40 minecraft:air
fill ~-40 ~3 ~1 ~-20 ~34 ~40 minecraft:air
fill ~-19 ~3 ~1 ~ ~34 ~40 minecraft:air
fill ~1 ~-30 ~-40 ~40 ~2 ~-20 minecraft:air
fill ~1 ~-30 ~-19 ~40 ~2 ~ minecraft:air
fill ~1 ~3 ~-40 ~40 ~34 ~-20 minecraft:air
fill ~1 ~3 ~-19 ~40 ~34 ~ minecraft:air
fill ~1 ~-30 ~1 ~20 ~2 ~40 minecraft:air
fill ~21 ~-30 ~1 ~40 ~2 ~40 minecraft:air
fill ~1 ~3 ~1 ~20 ~34 ~40 minecraft:air
fill ~21 ~3 ~1 ~40 ~34 ~40 minecraft:air
fill ~-40 ~-6 ~-40 ~40 ~-3 ~40 minecraft:stone
fill ~-40 ~-2 ~-40 ~40 ~-2 ~40 minecraft:dirt
fill ~-40 ~-1 ~-40 ~40 ~-1 ~40 minecraft:grass_block
# Landscaped mounding and texture in the outer garden band.
setblock ~33 ~-1 ~9 minecraft:grass_block
setblock ~-2 ~-1 ~38 minecraft:moss_block
setblock ~33 ~-1 ~30 minecraft:podzol
setblock ~-35 ~-1 ~10 minecraft:moss_block
setblock ~-14 ~-1 ~22 minecraft:grass_block
setblock ~-38 ~-1 ~9 minecraft:moss_block
setblock ~28 ~-1 ~8 minecraft:grass_block
setblock ~20 ~-1 ~12 minecraft:grass_block
setblock ~-32 ~-1 ~29 minecraft:grass_block
setblock ~20 ~-1 ~32 minecraft:dirt["dirt_type":"coarse"]
setblock ~29 ~-1 ~5 minecraft:dirt["dirt_type":"coarse"]
setblock ~27 ~-1 ~8 minecraft:grass_block
setblock ~-32 ~-1 ~29 minecraft:grass_block
setblock ~-12 ~-1 ~17 minecraft:moss_block
setblock ~-16 ~-1 ~36 minecraft:grass_block
setblock ~-26 ~-1 ~32 minecraft:podzol
setblock ~21 ~-1 ~21 minecraft:moss_block
setblock ~-33 ~-1 ~34 minecraft:podzol
setblock ~37 ~-1 ~14 minecraft:dirt["dirt_type":"coarse"]
setblock ~-14 ~-1 ~23 minecraft:podzol
setblock ~30 ~-1 ~18 minecraft:grass_block
setblock ~29 ~-1 ~26 minecraft:podzol
setblock ~-14 ~-1 ~34 minecraft:podzol
setblock ~-25 ~-1 ~23 minecraft:grass_block
setblock ~-25 ~-1 ~15 minecraft:moss_block
setblock ~18 ~-1 ~18 minecraft:podzol
setblock ~2 ~-1 ~31 minecraft:moss_block
setblock ~-19 ~-1 ~22 minecraft:dirt["dirt_type":"coarse"]
setblock ~-6 ~-1 ~15 minecraft:moss_block
setblock ~-24 ~-1 ~5 minecraft:grass_block
setblock ~-17 ~-1 ~21 minecraft:moss_block
setblock ~33 ~-1 ~7 minecraft:podzol
setblock ~-30 ~-1 ~38 minecraft:moss_block
setblock ~-36 ~-1 ~7 minecraft:moss_block
setblock ~-28 ~-1 ~15 minecraft:podzol
setblock ~-8 ~-1 ~16 minecraft:podzol
setblock ~4 ~-1 ~20 minecraft:dirt["dirt_type":"coarse"]
setblock ~18 ~-1 ~16 minecraft:podzol
setblock ~-36 ~-1 ~26 minecraft:moss_block
setblock ~34 ~-1 ~19 minecraft:dirt["dirt_type":"coarse"]
setblock ~34 ~-1 ~33 minecraft:moss_block
setblock ~17 ~-1 ~27 minecraft:grass_block
setblock ~-28 ~-1 ~37 minecraft:moss_block
setblock ~-20 ~-1 ~26 minecraft:moss_block
setblock ~11 ~-1 ~26 minecraft:grass_block
setblock ~12 ~-1 ~10 minecraft:dirt["dirt_type":"coarse"]
setblock ~15 ~-1 ~30 minecraft:podzol
setblock ~-22 ~-1 ~33 minecraft:podzol
setblock ~-20 ~-1 ~27 minecraft:grass_block
setblock ~-18 ~-1 ~16 minecraft:podzol
setblock ~-27 ~-1 ~32 minecraft:podzol
setblock ~18 ~-1 ~23 minecraft:dirt["dirt_type":"coarse"]
# --- 01 foundation + substructure excavation ---
fill ~-20 ~-3 ~-28 ~20 ~-1 ~1 minecraft:polished_deepslate
# Basement void
fill ~-17 ~-10 ~-25 ~17 ~-3 ~-2 minecraft:polished_deepslate
fill ~-16 ~-9 ~-24 ~16 ~-4 ~-3 minecraft:air
# Bunker void, deeper and armoured
fill ~-15 ~-23 ~-21 ~15 ~-14 ~-3 minecraft:reinforced_deepslate
fill ~-14 ~-22 ~-20 ~14 ~-15 ~-4 minecraft:polished_deepslate
fill ~-13 ~-21 ~-19 ~13 ~-16 ~-5 minecraft:air
# Basement and bunker floor finishes
fill ~-16 ~-10 ~-24 ~16 ~-10 ~-3 minecraft:deepslate_tiles
fill ~-13 ~-22 ~-19 ~13 ~-22 ~-5 minecraft:deepslate_tiles
# --- 02 ground floor shell ---
fill ~-19 ~-1 ~-27 ~19 ~-1 ~ minecraft:quartz_block
fill ~-19 ~ ~-27 ~19 ~6 ~-27 minecraft:white_concrete
fill ~-19 ~ ~ ~19 ~6 ~ minecraft:white_concrete
fill ~-19 ~ ~-27 ~-19 ~6 ~ minecraft:white_concrete
fill ~19 ~ ~-27 ~19 ~6 ~ minecraft:white_concrete
fill ~-19 ~7 ~-27 ~19 ~7 ~ minecraft:polished_deepslate
# Corner piers
fill ~-19 ~ ~-27 ~-19 ~6 ~-27 minecraft:quartz_block["chisel_type":"lines"]
setblock ~-19 ~7 ~-27 minecraft:polished_blackstone_slab
fill ~-19 ~ ~ ~-19 ~6 ~ minecraft:quartz_block["chisel_type":"lines"]
setblock ~-19 ~7 ~ minecraft:polished_blackstone_slab
fill ~19 ~ ~-27 ~19 ~6 ~-27 minecraft:quartz_block["chisel_type":"lines"]
setblock ~19 ~7 ~-27 minecraft:polished_blackstone_slab
fill ~19 ~ ~ ~19 ~6 ~ minecraft:quartz_block["chisel_type":"lines"]
setblock ~19 ~7 ~ minecraft:polished_blackstone_slab
# Main entrance portal - PURE AIR, registered as a lockdown seal
fill ~-4 ~ ~ ~4 ~5 ~ minecraft:air
# Entrance reveal and threshold
fill ~-5 ~ ~ ~-5 ~5 ~ minecraft:polished_blackstone
fill ~5 ~ ~ ~5 ~5 ~ minecraft:polished_blackstone
fill ~-4 ~-1 ~ ~4 ~-1 ~ minecraft:deepslate_tiles
fill ~-4 ~6 ~ ~4 ~6 ~ myc:clean_panel
# --- 03 ground floor curtain walls ---
# West and east elevations - full-height glazing between piers
fill ~-19 ~1 ~-24 ~-19 ~5 ~-3 minecraft:light_blue_stained_glass
fill ~-19 ~1 ~-24 ~-19 ~5 ~-24 minecraft:polished_blackstone
fill ~-19 ~1 ~-20 ~-19 ~5 ~-20 minecraft:polished_blackstone
fill ~-19 ~1 ~-16 ~-19 ~5 ~-16 minecraft:polished_blackstone
fill ~-19 ~1 ~-12 ~-19 ~5 ~-12 minecraft:polished_blackstone
fill ~-19 ~1 ~-8 ~-19 ~5 ~-8 minecraft:polished_blackstone
fill ~-19 ~1 ~-4 ~-19 ~5 ~-4 minecraft:polished_blackstone
fill ~19 ~1 ~-24 ~19 ~5 ~-3 minecraft:light_blue_stained_glass
fill ~19 ~1 ~-24 ~19 ~5 ~-24 minecraft:polished_blackstone
fill ~19 ~1 ~-20 ~19 ~5 ~-20 minecraft:polished_blackstone
fill ~19 ~1 ~-16 ~19 ~5 ~-16 minecraft:polished_blackstone
fill ~19 ~1 ~-12 ~19 ~5 ~-12 minecraft:polished_blackstone
fill ~19 ~1 ~-8 ~19 ~5 ~-8 minecraft:polished_blackstone
fill ~19 ~1 ~-4 ~19 ~5 ~-4 minecraft:polished_blackstone
# North (rear) elevation glazing, split by the garden door
fill ~-17 ~1 ~-27 ~-4 ~5 ~-27 minecraft:light_blue_stained_glass
fill ~-17 ~1 ~-27 ~-17 ~5 ~-27 minecraft:polished_blackstone
fill ~-13 ~1 ~-27 ~-13 ~5 ~-27 minecraft:polished_blackstone
fill ~-9 ~1 ~-27 ~-9 ~5 ~-27 minecraft:polished_blackstone
fill ~-5 ~1 ~-27 ~-5 ~5 ~-27 minecraft:polished_blackstone
fill ~4 ~1 ~-27 ~17 ~5 ~-27 minecraft:light_blue_stained_glass
fill ~4 ~1 ~-27 ~4 ~5 ~-27 minecraft:polished_blackstone
fill ~8 ~1 ~-27 ~8 ~5 ~-27 minecraft:polished_blackstone
fill ~12 ~1 ~-27 ~12 ~5 ~-27 minecraft:polished_blackstone
fill ~16 ~1 ~-27 ~16 ~5 ~-27 minecraft:polished_blackstone
# Garden door opening - PURE AIR, seal
fill ~-3 ~ ~-27 ~3 ~4 ~-27 minecraft:air
fill ~-4 ~ ~-27 ~-4 ~4 ~-27 minecraft:polished_blackstone
fill ~4 ~ ~-27 ~4 ~4 ~-27 minecraft:polished_blackstone
# Front elevation glazing either side of the entrance
fill ~-17 ~1 ~ ~-6 ~5 ~ minecraft:light_blue_stained_glass
fill ~-17 ~1 ~ ~-17 ~5 ~ minecraft:polished_blackstone
fill ~-13 ~1 ~ ~-13 ~5 ~ minecraft:polished_blackstone
fill ~-9 ~1 ~ ~-9 ~5 ~ minecraft:polished_blackstone
fill ~6 ~1 ~ ~17 ~5 ~ minecraft:light_blue_stained_glass
fill ~6 ~1 ~ ~6 ~5 ~ minecraft:polished_blackstone
fill ~10 ~1 ~ ~10 ~5 ~ minecraft:polished_blackstone
fill ~14 ~1 ~ ~14 ~5 ~ minecraft:polished_blackstone
# Pool-side door on the east elevation - PURE AIR, seal
fill ~19 ~ ~-8 ~19 ~4 ~-4 minecraft:air
fill ~19 ~ ~-9 ~19 ~4 ~-9 minecraft:polished_blackstone
fill ~19 ~ ~-3 ~19 ~4 ~-3 minecraft:polished_blackstone
# --- 04 first floor shell ---
fill ~-19 ~7 ~-27 ~19 ~7 ~ minecraft:dark_oak_planks
fill ~-19 ~8 ~-27 ~19 ~14 ~-27 minecraft:white_concrete
fill ~-19 ~8 ~ ~19 ~14 ~ minecraft:white_concrete
fill ~-19 ~8 ~-27 ~-19 ~14 ~ minecraft:white_concrete
fill ~19 ~8 ~-27 ~19 ~14 ~ minecraft:white_concrete
fill ~-19 ~15 ~-27 ~19 ~15 ~ minecraft:polished_deepslate
fill ~-19 ~9 ~-24 ~-19 ~12 ~-3 minecraft:light_blue_stained_glass
fill ~-19 ~9 ~-24 ~-19 ~12 ~-24 minecraft:polished_blackstone
fill ~-19 ~9 ~-20 ~-19 ~12 ~-20 minecraft:polished_blackstone
fill ~-19 ~9 ~-16 ~-19 ~12 ~-16 minecraft:polished_blackstone
fill ~-19 ~9 ~-12 ~-19 ~12 ~-12 minecraft:polished_blackstone
fill ~-19 ~9 ~-8 ~-19 ~12 ~-8 minecraft:polished_blackstone
fill ~-19 ~9 ~-4 ~-19 ~12 ~-4 minecraft:polished_blackstone
fill ~19 ~9 ~-24 ~19 ~12 ~-3 minecraft:light_blue_stained_glass
fill ~19 ~9 ~-24 ~19 ~12 ~-24 minecraft:polished_blackstone
fill ~19 ~9 ~-20 ~19 ~12 ~-20 minecraft:polished_blackstone
fill ~19 ~9 ~-16 ~19 ~12 ~-16 minecraft:polished_blackstone
fill ~19 ~9 ~-12 ~19 ~12 ~-12 minecraft:polished_blackstone
fill ~19 ~9 ~-8 ~19 ~12 ~-8 minecraft:polished_blackstone
fill ~19 ~9 ~-4 ~19 ~12 ~-4 minecraft:polished_blackstone
fill ~-17 ~9 ~-27 ~17 ~12 ~-27 minecraft:light_blue_stained_glass
fill ~-17 ~9 ~-27 ~-17 ~12 ~-27 minecraft:polished_blackstone
fill ~-13 ~9 ~-27 ~-13 ~12 ~-27 minecraft:polished_blackstone
fill ~-9 ~9 ~-27 ~-9 ~12 ~-27 minecraft:polished_blackstone
fill ~-5 ~9 ~-27 ~-5 ~12 ~-27 minecraft:polished_blackstone
fill ~-1 ~9 ~-27 ~-1 ~12 ~-27 minecraft:polished_blackstone
fill ~3 ~9 ~-27 ~3 ~12 ~-27 minecraft:polished_blackstone
fill ~7 ~9 ~-27 ~7 ~12 ~-27 minecraft:polished_blackstone
fill ~11 ~9 ~-27 ~11 ~12 ~-27 minecraft:polished_blackstone
fill ~15 ~9 ~-27 ~15 ~12 ~-27 minecraft:polished_blackstone
fill ~-17 ~9 ~ ~-6 ~12 ~ minecraft:light_blue_stained_glass
fill ~-17 ~9 ~ ~-17 ~12 ~ minecraft:polished_blackstone
fill ~-13 ~9 ~ ~-13 ~12 ~ minecraft:polished_blackstone
fill ~-9 ~9 ~ ~-9 ~12 ~ minecraft:polished_blackstone
fill ~6 ~9 ~ ~17 ~12 ~ minecraft:light_blue_stained_glass
fill ~6 ~9 ~ ~6 ~12 ~ minecraft:polished_blackstone
fill ~10 ~9 ~ ~10 ~12 ~ minecraft:polished_blackstone
fill ~14 ~9 ~ ~14 ~12 ~ minecraft:polished_blackstone
# Balcony doors onto the front terrace (interior, not sealed)
fill ~-4 ~8 ~ ~4 ~11 ~ minecraft:air
# --- 05 second floor shell ---
fill ~-19 ~15 ~-27 ~19 ~15 ~ minecraft:dark_oak_planks
fill ~-19 ~16 ~-27 ~19 ~22 ~-27 minecraft:white_concrete
fill ~-19 ~16 ~ ~19 ~22 ~ minecraft:white_concrete
fill ~-19 ~16 ~-27 ~-19 ~22 ~ minecraft:white_concrete
fill ~19 ~16 ~-27 ~19 ~22 ~ minecraft:white_concrete
