# part_80.mcfunction - generated by tools/gen_mansion.py, do not edit
# Relative coordinates only; run via execute positioned <x> <y> <z>
# (continued: 21 bunker access shaft + quarters)
setblock ~-12 ~-21 ~-18 minecraft:barrel["facing_direction":1,"open_bit":false]
setblock ~-12 ~-20 ~-18 minecraft:barrel["facing_direction":1,"open_bit":false]
setblock ~-10 ~-21 ~-16 minecraft:barrel["facing_direction":1,"open_bit":false]
setblock ~-10 ~-20 ~-16 minecraft:barrel["facing_direction":1,"open_bit":false]
setblock ~-10 ~-21 ~-18 minecraft:barrel["facing_direction":1,"open_bit":false]
setblock ~-10 ~-20 ~-18 minecraft:barrel["facing_direction":1,"open_bit":false]
setblock ~-8 ~-21 ~-16 minecraft:barrel["facing_direction":1,"open_bit":false]
setblock ~-8 ~-20 ~-16 minecraft:barrel["facing_direction":1,"open_bit":false]
setblock ~-8 ~-21 ~-18 minecraft:barrel["facing_direction":1,"open_bit":false]
setblock ~-8 ~-20 ~-18 minecraft:barrel["facing_direction":1,"open_bit":false]
setblock ~-6 ~-21 ~-16 minecraft:barrel["facing_direction":1,"open_bit":false]
setblock ~-6 ~-20 ~-16 minecraft:barrel["facing_direction":1,"open_bit":false]
setblock ~-6 ~-21 ~-18 minecraft:barrel["facing_direction":1,"open_bit":false]
setblock ~-6 ~-20 ~-18 minecraft:barrel["facing_direction":1,"open_bit":false]
setblock ~-13 ~-21 ~-15 minecraft:chest["minecraft:cardinal_direction":"south"]
setblock ~-10 ~-21 ~-15 minecraft:chest["minecraft:cardinal_direction":"south"]
setblock ~-7 ~-21 ~-15 minecraft:chest["minecraft:cardinal_direction":"south"]
setblock ~-13 ~-21 ~-19 minecraft:cauldron["cauldron_liquid":"water","fill_level":6]
setblock ~-4 ~-21 ~-19 minecraft:composter
setblock ~-12 ~-16 ~-17 minecraft:redstone_lamp
setblock ~-9 ~-16 ~-17 minecraft:redstone_lamp
setblock ~-6 ~-16 ~-17 minecraft:redstone_lamp
setblock ~-3 ~-19 ~-14 myc:alarm_light
# --- 22 quarantine cell + bunker control ---
# Sealed glass-walled quarantine cell with its own door
fill ~4 ~-22 ~-11 ~12 ~-22 ~-5 minecraft:calcite
fill ~4 ~-15 ~-11 ~12 ~-15 ~-5 minecraft:calcite
fill ~4 ~-21 ~-5 ~12 ~-16 ~-5 minecraft:polished_deepslate
fill ~4 ~-21 ~-11 ~12 ~-16 ~-11 minecraft:polished_deepslate
fill ~4 ~-21 ~-11 ~4 ~-16 ~-5 minecraft:polished_deepslate
fill ~12 ~-21 ~-11 ~12 ~-16 ~-5 minecraft:polished_deepslate
fill ~3 ~-21 ~-8 ~3 ~-19 ~-8 minecraft:air
# Inner glass cell, airlocked from the anteroom
fill ~6 ~-22 ~-10 ~11 ~-22 ~-6 minecraft:calcite
fill ~6 ~-21 ~-6 ~11 ~-18 ~-6 minecraft:white_stained_glass
fill ~6 ~-21 ~-10 ~11 ~-18 ~-10 minecraft:white_stained_glass
fill ~6 ~-21 ~-10 ~6 ~-18 ~-6 minecraft:white_stained_glass
fill ~11 ~-21 ~-10 ~11 ~-18 ~-6 minecraft:white_stained_glass
fill ~6 ~-17 ~-10 ~11 ~-17 ~-6 myc:lab_panel
# Cell door - its own iron door in the glass wall
fill ~8 ~-21 ~-6 ~8 ~-20 ~-6 minecraft:air
setblock ~8 ~-21 ~-6 minecraft:iron_door["direction":2,"door_hinge_bit":false,"open_bit":false,"upper_block_bit":false]
setblock ~8 ~-20 ~-6 minecraft:iron_door["direction":2,"door_hinge_bit":false,"open_bit":false,"upper_block_bit":true]
setblock ~7 ~-20 ~-6 minecraft:stone_button["facing_direction":3]
# Cell interior
fill ~9 ~-21 ~-10 ~10 ~-21 ~-8 minecraft:white_wool
fill ~9 ~-21 ~-8 ~10 ~-21 ~-8 minecraft:light_gray_wool
fill ~9 ~-20 ~-7 ~10 ~-20 ~-7 minecraft:dark_oak_planks
fill ~9 ~-21 ~-7 ~10 ~-21 ~-7 minecraft:dark_oak_planks
setblock ~7 ~-21 ~-9 minecraft:cauldron["cauldron_liquid":"water","fill_level":6]
setblock ~7 ~-21 ~-7 myc:lab_panel
setblock ~10 ~-21 ~-10 myc:lab_panel
setblock ~8 ~-18 ~-8 minecraft:sea_lantern
# Observation and medical bay outside the glass
fill ~4 ~-21 ~-5 ~5 ~-21 ~-5 minecraft:calcite
fill ~4 ~-20 ~-5 ~5 ~-20 ~-5 minecraft:quartz_slab
setblock ~4 ~-20 ~-5 myc:lab_panel
setblock ~5 ~-20 ~-5 myc:screen
setblock ~12 ~-21 ~-8 minecraft:brewing_stand
setblock ~12 ~-21 ~-7 myc:lab_panel
setblock ~4 ~-21 ~-11 minecraft:barrel["facing_direction":1,"open_bit":false]
setblock ~5 ~-16 ~-7 minecraft:redstone_lamp
setblock ~8 ~-16 ~-7 minecraft:redstone_lamp
setblock ~11 ~-16 ~-7 minecraft:redstone_lamp
setblock ~3 ~-19 ~-5 myc:alarm_light
setblock ~12 ~-19 ~-11 myc:alarm_light
# Bunker command room
fill ~4 ~-22 ~-19 ~13 ~-22 ~-12 minecraft:deepslate_tiles
fill ~4 ~-15 ~-19 ~13 ~-15 ~-12 minecraft:deepslate_tiles
fill ~4 ~-21 ~-12 ~13 ~-16 ~-12 minecraft:polished_deepslate
fill ~4 ~-21 ~-19 ~13 ~-16 ~-19 minecraft:polished_deepslate
fill ~4 ~-21 ~-19 ~4 ~-16 ~-12 minecraft:polished_deepslate
fill ~13 ~-21 ~-19 ~13 ~-16 ~-12 minecraft:polished_deepslate
fill ~3 ~-21 ~-16 ~3 ~-19 ~-14 minecraft:air
fill ~4 ~-20 ~-19 ~13 ~-16 ~-19 minecraft:black_concrete
fill ~5 ~-19 ~-19 ~12 ~-17 ~-19 myc:screen
fill ~5 ~-21 ~-17 ~12 ~-21 ~-17 minecraft:polished_blackstone
fill ~5 ~-20 ~-17 ~12 ~-20 ~-17 minecraft:quartz_slab
# Bunker control panel bank
setblock ~5 ~-20 ~-17 myc:control_panel
setblock ~8 ~-20 ~-17 myc:control_panel
setblock ~11 ~-20 ~-17 myc:control_panel
setblock ~6 ~-20 ~-17 myc:screen
setblock ~7 ~-20 ~-17 myc:screen
setblock ~9 ~-20 ~-17 myc:screen
setblock ~10 ~-20 ~-17 myc:screen
setblock ~12 ~-20 ~-17 myc:screen
setblock ~6 ~-21 ~-18 minecraft:dark_oak_stairs["weirdo_direction":2,"upside_down_bit":false]
setblock ~9 ~-21 ~-18 minecraft:dark_oak_stairs["weirdo_direction":2,"upside_down_bit":false]
setblock ~12 ~-21 ~-18 minecraft:dark_oak_stairs["weirdo_direction":2,"upside_down_bit":false]
fill ~13 ~-21 ~-15 ~13 ~-19 ~-15 myc:server_rack
fill ~13 ~-21 ~-14 ~13 ~-19 ~-14 myc:server_rack
fill ~13 ~-21 ~-13 ~13 ~-19 ~-13 myc:server_rack
setblock ~4 ~-21 ~-13 minecraft:trapped_chest["minecraft:cardinal_direction":"east"]
setblock ~5 ~-16 ~-14 minecraft:redstone_lamp
setblock ~8 ~-16 ~-14 minecraft:redstone_lamp
setblock ~11 ~-16 ~-14 minecraft:redstone_lamp
setblock ~13 ~-19 ~-19 myc:alarm_light
# --- 24 entrance canopy + driveway ---
# Canopy slab on pillars over the entrance
fill ~-8 ~6 ~1 ~8 ~6 ~8 minecraft:smooth_stone
fill ~-8 ~7 ~1 ~8 ~7 ~8 minecraft:polished_deepslate
fill ~-7 ~5 ~2 ~7 ~5 ~7 myc:clean_panel
fill ~-7 ~ ~2 ~-7 ~5 ~2 minecraft:quartz_block["chisel_type":"lines"]
setblock ~-7 ~6 ~2 minecraft:polished_blackstone_slab
fill ~-7 ~ ~7 ~-7 ~5 ~7 minecraft:quartz_block["chisel_type":"lines"]
setblock ~-7 ~6 ~7 minecraft:polished_blackstone_slab
fill ~-3 ~ ~2 ~-3 ~5 ~2 minecraft:quartz_block["chisel_type":"lines"]
setblock ~-3 ~6 ~2 minecraft:polished_blackstone_slab
fill ~-3 ~ ~7 ~-3 ~5 ~7 minecraft:quartz_block["chisel_type":"lines"]
setblock ~-3 ~6 ~7 minecraft:polished_blackstone_slab
fill ~3 ~ ~2 ~3 ~5 ~2 minecraft:quartz_block["chisel_type":"lines"]
setblock ~3 ~6 ~2 minecraft:polished_blackstone_slab
fill ~3 ~ ~7 ~3 ~5 ~7 minecraft:quartz_block["chisel_type":"lines"]
setblock ~3 ~6 ~7 minecraft:polished_blackstone_slab
fill ~7 ~ ~2 ~7 ~5 ~2 minecraft:quartz_block["chisel_type":"lines"]
setblock ~7 ~6 ~2 minecraft:polished_blackstone_slab
fill ~7 ~ ~7 ~7 ~5 ~7 minecraft:quartz_block["chisel_type":"lines"]
setblock ~7 ~6 ~7 minecraft:polished_blackstone_slab
# Canopy downlights - always on
setblock ~-6 ~5 ~3 minecraft:sea_lantern
setblock ~-6 ~5 ~6 minecraft:sea_lantern
setblock ~-3 ~5 ~3 minecraft:sea_lantern
setblock ~-3 ~5 ~6 minecraft:sea_lantern
setblock ~ ~5 ~3 minecraft:sea_lantern
setblock ~ ~5 ~6 minecraft:sea_lantern
setblock ~3 ~5 ~3 minecraft:sea_lantern
setblock ~3 ~5 ~6 minecraft:sea_lantern
setblock ~6 ~5 ~3 minecraft:sea_lantern
setblock ~6 ~5 ~6 minecraft:sea_lantern
# Entrance steps and threshold apron
fill ~-6 ~-1 ~1 ~6 ~-1 ~9 minecraft:deepslate_tiles
setblock ~-6 ~-1 ~9 minecraft:polished_deepslate_stairs["weirdo_direction":2,"upside_down_bit":false]
setblock ~-5 ~-1 ~9 minecraft:polished_deepslate_stairs["weirdo_direction":2,"upside_down_bit":false]
setblock ~-4 ~-1 ~9 minecraft:polished_deepslate_stairs["weirdo_direction":2,"upside_down_bit":false]
setblock ~-3 ~-1 ~9 minecraft:polished_deepslate_stairs["weirdo_direction":2,"upside_down_bit":false]
setblock ~-2 ~-1 ~9 minecraft:polished_deepslate_stairs["weirdo_direction":2,"upside_down_bit":false]
setblock ~-1 ~-1 ~9 minecraft:polished_deepslate_stairs["weirdo_direction":2,"upside_down_bit":false]
setblock ~ ~-1 ~9 minecraft:polished_deepslate_stairs["weirdo_direction":2,"upside_down_bit":false]
setblock ~1 ~-1 ~9 minecraft:polished_deepslate_stairs["weirdo_direction":2,"upside_down_bit":false]
setblock ~2 ~-1 ~9 minecraft:polished_deepslate_stairs["weirdo_direction":2,"upside_down_bit":false]
setblock ~3 ~-1 ~9 minecraft:polished_deepslate_stairs["weirdo_direction":2,"upside_down_bit":false]
setblock ~4 ~-1 ~9 minecraft:polished_deepslate_stairs["weirdo_direction":2,"upside_down_bit":false]
setblock ~5 ~-1 ~9 minecraft:polished_deepslate_stairs["weirdo_direction":2,"upside_down_bit":false]
setblock ~6 ~-1 ~9 minecraft:polished_deepslate_stairs["weirdo_direction":2,"upside_down_bit":false]
setblock ~-6 ~-2 ~10 minecraft:polished_deepslate_stairs["weirdo_direction":2,"upside_down_bit":false]
setblock ~-5 ~-2 ~10 minecraft:polished_deepslate_stairs["weirdo_direction":2,"upside_down_bit":false]
setblock ~-4 ~-2 ~10 minecraft:polished_deepslate_stairs["weirdo_direction":2,"upside_down_bit":false]
setblock ~-3 ~-2 ~10 minecraft:polished_deepslate_stairs["weirdo_direction":2,"upside_down_bit":false]
setblock ~-2 ~-2 ~10 minecraft:polished_deepslate_stairs["weirdo_direction":2,"upside_down_bit":false]
setblock ~-1 ~-2 ~10 minecraft:polished_deepslate_stairs["weirdo_direction":2,"upside_down_bit":false]
setblock ~ ~-2 ~10 minecraft:polished_deepslate_stairs["weirdo_direction":2,"upside_down_bit":false]
setblock ~1 ~-2 ~10 minecraft:polished_deepslate_stairs["weirdo_direction":2,"upside_down_bit":false]
setblock ~2 ~-2 ~10 minecraft:polished_deepslate_stairs["weirdo_direction":2,"upside_down_bit":false]
setblock ~3 ~-2 ~10 minecraft:polished_deepslate_stairs["weirdo_direction":2,"upside_down_bit":false]
setblock ~4 ~-2 ~10 minecraft:polished_deepslate_stairs["weirdo_direction":2,"upside_down_bit":false]
setblock ~5 ~-2 ~10 minecraft:polished_deepslate_stairs["weirdo_direction":2,"upside_down_bit":false]
setblock ~6 ~-2 ~10 minecraft:polished_deepslate_stairs["weirdo_direction":2,"upside_down_bit":false]
# Driveway
fill ~-6 ~-1 ~10 ~6 ~-1 ~38 minecraft:polished_blackstone
fill ~-5 ~-1 ~10 ~5 ~-1 ~38 minecraft:deepslate_tiles
setblock ~-6 ~ ~12 minecraft:end_rod["facing_direction":1]
setblock ~6 ~ ~12 minecraft:end_rod["facing_direction":1]
setblock ~-6 ~ ~16 minecraft:end_rod["facing_direction":1]
setblock ~6 ~ ~16 minecraft:end_rod["facing_direction":1]
setblock ~-6 ~ ~20 minecraft:end_rod["facing_direction":1]
setblock ~6 ~ ~20 minecraft:end_rod["facing_direction":1]
setblock ~-6 ~ ~24 minecraft:end_rod["facing_direction":1]
setblock ~6 ~ ~24 minecraft:end_rod["facing_direction":1]
setblock ~-6 ~ ~28 minecraft:end_rod["facing_direction":1]
setblock ~6 ~ ~28 minecraft:end_rod["facing_direction":1]
setblock ~-6 ~ ~32 minecraft:end_rod["facing_direction":1]
setblock ~6 ~ ~32 minecraft:end_rod["facing_direction":1]
setblock ~-6 ~ ~36 minecraft:end_rod["facing_direction":1]
setblock ~6 ~ ~36 minecraft:end_rod["facing_direction":1]
# Turning circle island
fill ~-3 ~-1 ~22 ~3 ~-1 ~28 minecraft:grass_block
fill ~ ~ ~25 ~ ~4 ~25 minecraft:oak_log
fill ~-2 ~3 ~23 ~2 ~4 ~27 minecraft:azalea_leaves["persistent_bit":true,"update_bit":false]
fill ~-1 ~5 ~24 ~1 ~5 ~26 minecraft:azalea_leaves["persistent_bit":true,"update_bit":false]
setblock ~ ~6 ~25 minecraft:azalea_leaves["persistent_bit":true,"update_bit":false]
setblock ~-2 ~ ~23 minecraft:rose_bush
setblock ~-2 ~ ~27 minecraft:peony
setblock ~2 ~ ~23 minecraft:rose_bush
setblock ~2 ~ ~27 minecraft:peony
# Gate piers
fill ~-7 ~ ~38 ~-7 ~4 ~38 minecraft:polished_deepslate
setblock ~-7 ~5 ~38 minecraft:polished_blackstone_slab
setblock ~-7 ~5 ~38 minecraft:sea_lantern
fill ~7 ~ ~38 ~7 ~4 ~38 minecraft:polished_deepslate
setblock ~7 ~5 ~38 minecraft:polished_blackstone_slab
setblock ~7 ~5 ~38 minecraft:sea_lantern
setblock ~-7 ~4 ~1 myc:alarm_light
setblock ~7 ~4 ~1 myc:alarm_light
setblock ~-7 ~3 ~38 myc:alarm_light
