# part_05.mcfunction - generated by tools/gen_mansion.py, do not edit
# Relative coordinates only; run via execute positioned <x> <y> <z>
# (continued: 15 gaming room + lounge)
setblock ~1 ~16 ~-11 minecraft:dark_oak_stairs["weirdo_direction":2,"upside_down_bit":false]
setblock ~2 ~16 ~-11 minecraft:dark_oak_stairs["weirdo_direction":2,"upside_down_bit":false]
setblock ~-4 ~16 ~-11 minecraft:gray_wool
setblock ~3 ~16 ~-11 minecraft:gray_wool
setblock ~-2 ~16 ~-8 minecraft:dark_oak_fence
setblock ~-2 ~16 ~-7 minecraft:dark_oak_fence
setblock ~1 ~16 ~-8 minecraft:dark_oak_fence
setblock ~1 ~16 ~-7 minecraft:dark_oak_fence
fill ~-2 ~17 ~-8 ~1 ~17 ~-7 minecraft:quartz_slab
fill ~-4 ~15 ~-12 ~3 ~15 ~-3 minecraft:light_gray_carpet
setblock ~-4 ~16 ~-12 minecraft:bookshelf
setblock ~-4 ~17 ~-12 minecraft:chiseled_bookshelf
setblock ~3 ~16 ~-12 minecraft:bookshelf
setblock ~3 ~17 ~-12 minecraft:chiseled_bookshelf
setblock ~-4 ~21 ~-7 minecraft:sea_lantern
setblock ~-1 ~21 ~-7 minecraft:sea_lantern
setblock ~2 ~21 ~-7 minecraft:sea_lantern
# Stair from first floor up to second, in the hall void
setblock ~-3 ~8 ~-4 minecraft:quartz_stairs["weirdo_direction":3,"upside_down_bit":false]
setblock ~-3 ~9 ~-5 minecraft:quartz_stairs["weirdo_direction":3,"upside_down_bit":false]
setblock ~-3 ~10 ~-6 minecraft:quartz_stairs["weirdo_direction":3,"upside_down_bit":false]
setblock ~-3 ~11 ~-7 minecraft:quartz_stairs["weirdo_direction":3,"upside_down_bit":false]
setblock ~-3 ~12 ~-8 minecraft:quartz_stairs["weirdo_direction":3,"upside_down_bit":false]
setblock ~-3 ~13 ~-9 minecraft:quartz_stairs["weirdo_direction":3,"upside_down_bit":false]
setblock ~-3 ~14 ~-10 minecraft:quartz_stairs["weirdo_direction":3,"upside_down_bit":false]
setblock ~-2 ~8 ~-4 minecraft:quartz_stairs["weirdo_direction":3,"upside_down_bit":false]
setblock ~-2 ~9 ~-5 minecraft:quartz_stairs["weirdo_direction":3,"upside_down_bit":false]
setblock ~-2 ~10 ~-6 minecraft:quartz_stairs["weirdo_direction":3,"upside_down_bit":false]
setblock ~-2 ~11 ~-7 minecraft:quartz_stairs["weirdo_direction":3,"upside_down_bit":false]
setblock ~-2 ~12 ~-8 minecraft:quartz_stairs["weirdo_direction":3,"upside_down_bit":false]
setblock ~-2 ~13 ~-9 minecraft:quartz_stairs["weirdo_direction":3,"upside_down_bit":false]
setblock ~-2 ~14 ~-10 minecraft:quartz_stairs["weirdo_direction":3,"upside_down_bit":false]
setblock ~-1 ~8 ~-4 minecraft:quartz_stairs["weirdo_direction":3,"upside_down_bit":false]
setblock ~-1 ~9 ~-5 minecraft:quartz_stairs["weirdo_direction":3,"upside_down_bit":false]
setblock ~-1 ~10 ~-6 minecraft:quartz_stairs["weirdo_direction":3,"upside_down_bit":false]
setblock ~-1 ~11 ~-7 minecraft:quartz_stairs["weirdo_direction":3,"upside_down_bit":false]
setblock ~-1 ~12 ~-8 minecraft:quartz_stairs["weirdo_direction":3,"upside_down_bit":false]
setblock ~-1 ~13 ~-9 minecraft:quartz_stairs["weirdo_direction":3,"upside_down_bit":false]
setblock ~-1 ~14 ~-10 minecraft:quartz_stairs["weirdo_direction":3,"upside_down_bit":false]
setblock ~ ~8 ~-4 minecraft:quartz_stairs["weirdo_direction":3,"upside_down_bit":false]
setblock ~ ~9 ~-5 minecraft:quartz_stairs["weirdo_direction":3,"upside_down_bit":false]
setblock ~ ~10 ~-6 minecraft:quartz_stairs["weirdo_direction":3,"upside_down_bit":false]
setblock ~ ~11 ~-7 minecraft:quartz_stairs["weirdo_direction":3,"upside_down_bit":false]
setblock ~ ~12 ~-8 minecraft:quartz_stairs["weirdo_direction":3,"upside_down_bit":false]
setblock ~ ~13 ~-9 minecraft:quartz_stairs["weirdo_direction":3,"upside_down_bit":false]
setblock ~ ~14 ~-10 minecraft:quartz_stairs["weirdo_direction":3,"upside_down_bit":false]
setblock ~1 ~8 ~-4 minecraft:quartz_stairs["weirdo_direction":3,"upside_down_bit":false]
setblock ~1 ~9 ~-5 minecraft:quartz_stairs["weirdo_direction":3,"upside_down_bit":false]
setblock ~1 ~10 ~-6 minecraft:quartz_stairs["weirdo_direction":3,"upside_down_bit":false]
setblock ~1 ~11 ~-7 minecraft:quartz_stairs["weirdo_direction":3,"upside_down_bit":false]
setblock ~1 ~12 ~-8 minecraft:quartz_stairs["weirdo_direction":3,"upside_down_bit":false]
setblock ~1 ~13 ~-9 minecraft:quartz_stairs["weirdo_direction":3,"upside_down_bit":false]
setblock ~1 ~14 ~-10 minecraft:quartz_stairs["weirdo_direction":3,"upside_down_bit":false]
setblock ~2 ~8 ~-4 minecraft:quartz_stairs["weirdo_direction":3,"upside_down_bit":false]
setblock ~2 ~9 ~-5 minecraft:quartz_stairs["weirdo_direction":3,"upside_down_bit":false]
setblock ~2 ~10 ~-6 minecraft:quartz_stairs["weirdo_direction":3,"upside_down_bit":false]
setblock ~2 ~11 ~-7 minecraft:quartz_stairs["weirdo_direction":3,"upside_down_bit":false]
setblock ~2 ~12 ~-8 minecraft:quartz_stairs["weirdo_direction":3,"upside_down_bit":false]
setblock ~2 ~13 ~-9 minecraft:quartz_stairs["weirdo_direction":3,"upside_down_bit":false]
setblock ~2 ~14 ~-10 minecraft:quartz_stairs["weirdo_direction":3,"upside_down_bit":false]
setblock ~3 ~8 ~-4 minecraft:quartz_stairs["weirdo_direction":3,"upside_down_bit":false]
setblock ~3 ~9 ~-5 minecraft:quartz_stairs["weirdo_direction":3,"upside_down_bit":false]
setblock ~3 ~10 ~-6 minecraft:quartz_stairs["weirdo_direction":3,"upside_down_bit":false]
setblock ~3 ~11 ~-7 minecraft:quartz_stairs["weirdo_direction":3,"upside_down_bit":false]
setblock ~3 ~12 ~-8 minecraft:quartz_stairs["weirdo_direction":3,"upside_down_bit":false]
setblock ~3 ~13 ~-9 minecraft:quartz_stairs["weirdo_direction":3,"upside_down_bit":false]
setblock ~3 ~14 ~-10 minecraft:quartz_stairs["weirdo_direction":3,"upside_down_bit":false]
fill ~-3 ~15 ~-12 ~3 ~15 ~-11 minecraft:dark_oak_planks
# --- 16 rooftop terrace ---
# Decking zones
fill ~-16 ~23 ~-18 ~-6 ~23 ~-4 minecraft:dark_oak_planks
fill ~6 ~23 ~-18 ~16 ~23 ~-4 minecraft:smooth_stone
# Hot tub
fill ~-14 ~23 ~-9 ~-9 ~23 ~-5 minecraft:polished_deepslate
fill ~-13 ~23 ~-8 ~-10 ~23 ~-6 minecraft:water
setblock ~-14 ~24 ~-10 minecraft:quartz_stairs["weirdo_direction":3,"upside_down_bit":false]
setblock ~-13 ~24 ~-10 minecraft:quartz_stairs["weirdo_direction":3,"upside_down_bit":false]
setblock ~-12 ~24 ~-10 minecraft:quartz_stairs["weirdo_direction":3,"upside_down_bit":false]
setblock ~-11 ~24 ~-10 minecraft:quartz_stairs["weirdo_direction":3,"upside_down_bit":false]
setblock ~-10 ~24 ~-10 minecraft:quartz_stairs["weirdo_direction":3,"upside_down_bit":false]
setblock ~-9 ~24 ~-10 minecraft:quartz_stairs["weirdo_direction":3,"upside_down_bit":false]
setblock ~-14 ~24 ~-5 minecraft:sea_lantern
setblock ~-9 ~24 ~-9 myc:control_panel
# Lounge seating and fire table
setblock ~-15 ~24 ~-16 minecraft:dark_oak_stairs["weirdo_direction":3,"upside_down_bit":false]
setblock ~-14 ~24 ~-16 minecraft:dark_oak_stairs["weirdo_direction":3,"upside_down_bit":false]
setblock ~-13 ~24 ~-16 minecraft:dark_oak_stairs["weirdo_direction":3,"upside_down_bit":false]
setblock ~-12 ~24 ~-16 minecraft:dark_oak_stairs["weirdo_direction":3,"upside_down_bit":false]
setblock ~-11 ~24 ~-16 minecraft:dark_oak_stairs["weirdo_direction":3,"upside_down_bit":false]
setblock ~-10 ~24 ~-16 minecraft:dark_oak_stairs["weirdo_direction":3,"upside_down_bit":false]
setblock ~-9 ~24 ~-16 minecraft:dark_oak_stairs["weirdo_direction":3,"upside_down_bit":false]
setblock ~-8 ~24 ~-16 minecraft:dark_oak_stairs["weirdo_direction":3,"upside_down_bit":false]
setblock ~-16 ~24 ~-16 minecraft:gray_wool
setblock ~-7 ~24 ~-16 minecraft:gray_wool
setblock ~-15 ~24 ~-12 minecraft:dark_oak_stairs["weirdo_direction":2,"upside_down_bit":false]
setblock ~-14 ~24 ~-12 minecraft:dark_oak_stairs["weirdo_direction":2,"upside_down_bit":false]
setblock ~-13 ~24 ~-12 minecraft:dark_oak_stairs["weirdo_direction":2,"upside_down_bit":false]
setblock ~-12 ~24 ~-12 minecraft:dark_oak_stairs["weirdo_direction":2,"upside_down_bit":false]
setblock ~-11 ~24 ~-12 minecraft:dark_oak_stairs["weirdo_direction":2,"upside_down_bit":false]
setblock ~-10 ~24 ~-12 minecraft:dark_oak_stairs["weirdo_direction":2,"upside_down_bit":false]
setblock ~-9 ~24 ~-12 minecraft:dark_oak_stairs["weirdo_direction":2,"upside_down_bit":false]
setblock ~-8 ~24 ~-12 minecraft:dark_oak_stairs["weirdo_direction":2,"upside_down_bit":false]
setblock ~-16 ~24 ~-12 minecraft:gray_wool
setblock ~-7 ~24 ~-12 minecraft:gray_wool
setblock ~-13 ~24 ~-14 minecraft:dark_oak_fence
setblock ~-13 ~24 ~-14 minecraft:dark_oak_fence
setblock ~-10 ~24 ~-14 minecraft:dark_oak_fence
setblock ~-10 ~24 ~-14 minecraft:dark_oak_fence
fill ~-13 ~25 ~-14 ~-10 ~25 ~-14 minecraft:quartz_slab
setblock ~-12 ~25 ~-14 minecraft:shroomlight
# Helipad markings on the east deck
fill ~6 ~23 ~-16 ~16 ~23 ~-6 minecraft:black_concrete
setblock ~7 ~23 ~-15 minecraft:white_concrete
setblock ~7 ~23 ~-7 minecraft:white_concrete
setblock ~8 ~23 ~-15 minecraft:white_concrete
setblock ~8 ~23 ~-7 minecraft:white_concrete
setblock ~9 ~23 ~-15 minecraft:white_concrete
setblock ~9 ~23 ~-7 minecraft:white_concrete
setblock ~10 ~23 ~-15 minecraft:white_concrete
setblock ~10 ~23 ~-7 minecraft:white_concrete
setblock ~11 ~23 ~-15 minecraft:white_concrete
setblock ~11 ~23 ~-7 minecraft:white_concrete
setblock ~12 ~23 ~-15 minecraft:white_concrete
setblock ~12 ~23 ~-7 minecraft:white_concrete
setblock ~13 ~23 ~-15 minecraft:white_concrete
setblock ~13 ~23 ~-7 minecraft:white_concrete
setblock ~14 ~23 ~-15 minecraft:white_concrete
setblock ~14 ~23 ~-7 minecraft:white_concrete
setblock ~15 ~23 ~-15 minecraft:white_concrete
setblock ~15 ~23 ~-7 minecraft:white_concrete
setblock ~7 ~23 ~-15 minecraft:white_concrete
setblock ~15 ~23 ~-15 minecraft:white_concrete
setblock ~7 ~23 ~-14 minecraft:white_concrete
setblock ~15 ~23 ~-14 minecraft:white_concrete
setblock ~7 ~23 ~-13 minecraft:white_concrete
setblock ~15 ~23 ~-13 minecraft:white_concrete
setblock ~7 ~23 ~-12 minecraft:white_concrete
setblock ~15 ~23 ~-12 minecraft:white_concrete
setblock ~7 ~23 ~-11 minecraft:white_concrete
setblock ~15 ~23 ~-11 minecraft:white_concrete
setblock ~7 ~23 ~-10 minecraft:white_concrete
setblock ~15 ~23 ~-10 minecraft:white_concrete
setblock ~7 ~23 ~-9 minecraft:white_concrete
setblock ~15 ~23 ~-9 minecraft:white_concrete
setblock ~7 ~23 ~-8 minecraft:white_concrete
setblock ~15 ~23 ~-8 minecraft:white_concrete
setblock ~7 ~23 ~-7 minecraft:white_concrete
setblock ~15 ~23 ~-7 minecraft:white_concrete
# H marking
setblock ~10 ~23 ~-14 minecraft:white_concrete
setblock ~13 ~23 ~-14 minecraft:white_concrete
setblock ~10 ~23 ~-13 minecraft:white_concrete
setblock ~13 ~23 ~-13 minecraft:white_concrete
setblock ~10 ~23 ~-12 minecraft:white_concrete
setblock ~13 ~23 ~-12 minecraft:white_concrete
setblock ~10 ~23 ~-11 minecraft:white_concrete
setblock ~13 ~23 ~-11 minecraft:white_concrete
setblock ~10 ~23 ~-10 minecraft:white_concrete
setblock ~13 ~23 ~-10 minecraft:white_concrete
setblock ~10 ~23 ~-9 minecraft:white_concrete
setblock ~13 ~23 ~-9 minecraft:white_concrete
setblock ~10 ~23 ~-8 minecraft:white_concrete
setblock ~13 ~23 ~-8 minecraft:white_concrete
setblock ~10 ~23 ~-11 minecraft:white_concrete
setblock ~11 ~23 ~-11 minecraft:white_concrete
setblock ~12 ~23 ~-11 minecraft:white_concrete
setblock ~13 ~23 ~-11 minecraft:white_concrete
# Approach lights - always-on, not emergency circuit
setblock ~6 ~24 ~-16 minecraft:end_rod["facing_direction":1]
setblock ~6 ~24 ~-11 minecraft:end_rod["facing_direction":1]
setblock ~6 ~24 ~-6 minecraft:end_rod["facing_direction":1]
setblock ~16 ~24 ~-16 minecraft:end_rod["facing_direction":1]
setblock ~16 ~24 ~-11 minecraft:end_rod["facing_direction":1]
setblock ~16 ~24 ~-6 minecraft:end_rod["facing_direction":1]
# Bar and planting
fill ~-4 ~24 ~-20 ~4 ~24 ~-20 minecraft:warped_planks
fill ~-4 ~25 ~-20 ~4 ~25 ~-20 minecraft:quartz_slab
setblock ~-3 ~24 ~-19 minecraft:dark_oak_stairs["weirdo_direction":3,"upside_down_bit":false]
setblock ~-1 ~24 ~-19 minecraft:dark_oak_stairs["weirdo_direction":3,"upside_down_bit":false]
setblock ~1 ~24 ~-19 minecraft:dark_oak_stairs["weirdo_direction":3,"upside_down_bit":false]
setblock ~3 ~24 ~-19 minecraft:dark_oak_stairs["weirdo_direction":3,"upside_down_bit":false]
setblock ~-16 ~23 ~-3 minecraft:calcite
setblock ~-16 ~24 ~-3 minecraft:podzol
setblock ~-16 ~25 ~-3 minecraft:flowering_azalea
setblock ~-10 ~23 ~-3 minecraft:calcite
setblock ~-10 ~24 ~-3 minecraft:podzol
setblock ~-10 ~25 ~-3 minecraft:flowering_azalea
setblock ~-4 ~23 ~-3 minecraft:calcite
setblock ~-4 ~24 ~-3 minecraft:podzol
