# part_74.mcfunction - generated by tools/gen_mansion.py, do not edit
# Relative coordinates only; run via execute positioned <x> <y> <z>
# (continued: 07 entrance hall + feature staircase)
fill ~-3 ~ ~-11 ~3 ~ ~-5 minecraft:polished_deepslate
fill ~-3 ~8 ~-12 ~3 ~8 ~-11 minecraft:dark_oak_planks
fill ~-4 ~9 ~-12 ~-4 ~9 ~-5 minecraft:glass_pane
setblock ~-4 ~9 ~-12 minecraft:polished_blackstone_wall
setblock ~-4 ~9 ~-5 minecraft:polished_blackstone_wall
setblock ~-4 ~9 ~-9 minecraft:polished_blackstone_wall
fill ~4 ~9 ~-12 ~4 ~9 ~-5 minecraft:glass_pane
setblock ~4 ~9 ~-12 minecraft:polished_blackstone_wall
setblock ~4 ~9 ~-5 minecraft:polished_blackstone_wall
setblock ~4 ~9 ~-9 minecraft:polished_blackstone_wall
# Hall dressing
fill ~-3 ~ ~-3 ~3 ~ ~-2 minecraft:red_carpet
setblock ~-2 ~ ~-3 minecraft:dark_oak_fence
setblock ~-2 ~ ~-3 minecraft:dark_oak_fence
setblock ~2 ~ ~-3 minecraft:dark_oak_fence
setblock ~2 ~ ~-3 minecraft:dark_oak_fence
fill ~-2 ~1 ~-3 ~2 ~1 ~-3 minecraft:quartz_slab
setblock ~-6 ~3 ~-3 minecraft:end_rod["facing_direction":5]
setblock ~6 ~3 ~-3 minecraft:end_rod["facing_direction":4]
setblock ~-6 ~3 ~-6 minecraft:end_rod["facing_direction":5]
setblock ~6 ~3 ~-6 minecraft:end_rod["facing_direction":4]
setblock ~-6 ~3 ~-9 minecraft:end_rod["facing_direction":5]
setblock ~6 ~3 ~-9 minecraft:end_rod["facing_direction":4]
fill ~-6 ~1 ~-12 ~-1 ~5 ~-12 minecraft:black_concrete
fill ~-5 ~2 ~-12 ~-2 ~4 ~-12 myc:screen
setblock ~-6 ~1 ~-12 myc:control_panel
setblock ~-5 ~14 ~-11 minecraft:sea_lantern
setblock ~-2 ~14 ~-11 minecraft:sea_lantern
setblock ~1 ~14 ~-11 minecraft:sea_lantern
setblock ~4 ~14 ~-11 minecraft:sea_lantern
setblock ~-5 ~6 ~-2 minecraft:redstone_lamp
setblock ~-1 ~6 ~-2 minecraft:redstone_lamp
setblock ~3 ~6 ~-2 minecraft:redstone_lamp
setblock ~-5 ~4 ~-1 myc:alarm_light
setblock ~5 ~4 ~-1 myc:alarm_light
# --- 08 double-height living room ---
# Void over the living room
fill ~-18 ~7 ~-14 ~-8 ~7 ~-1 minecraft:air
fill ~-18 ~-1 ~-14 ~-8 ~-1 ~-1 minecraft:dark_oak_planks
fill ~-16 ~ ~-10 ~-10 ~ ~-4 minecraft:gray_carpet
# Sunken lounge seating - L-shaped sofa from stairs
setblock ~-16 ~ ~-11 minecraft:dark_oak_stairs["weirdo_direction":2,"upside_down_bit":false]
setblock ~-15 ~ ~-11 minecraft:dark_oak_stairs["weirdo_direction":2,"upside_down_bit":false]
setblock ~-14 ~ ~-11 minecraft:dark_oak_stairs["weirdo_direction":2,"upside_down_bit":false]
setblock ~-13 ~ ~-11 minecraft:dark_oak_stairs["weirdo_direction":2,"upside_down_bit":false]
setblock ~-12 ~ ~-11 minecraft:dark_oak_stairs["weirdo_direction":2,"upside_down_bit":false]
setblock ~-11 ~ ~-11 minecraft:dark_oak_stairs["weirdo_direction":2,"upside_down_bit":false]
setblock ~-10 ~ ~-11 minecraft:dark_oak_stairs["weirdo_direction":2,"upside_down_bit":false]
setblock ~-17 ~ ~-11 minecraft:gray_wool
setblock ~-9 ~ ~-11 minecraft:gray_wool
setblock ~-16 ~ ~-3 minecraft:dark_oak_stairs["weirdo_direction":3,"upside_down_bit":false]
setblock ~-15 ~ ~-3 minecraft:dark_oak_stairs["weirdo_direction":3,"upside_down_bit":false]
setblock ~-14 ~ ~-3 minecraft:dark_oak_stairs["weirdo_direction":3,"upside_down_bit":false]
setblock ~-13 ~ ~-3 minecraft:dark_oak_stairs["weirdo_direction":3,"upside_down_bit":false]
setblock ~-12 ~ ~-3 minecraft:dark_oak_stairs["weirdo_direction":3,"upside_down_bit":false]
setblock ~-11 ~ ~-3 minecraft:dark_oak_stairs["weirdo_direction":3,"upside_down_bit":false]
setblock ~-10 ~ ~-3 minecraft:dark_oak_stairs["weirdo_direction":3,"upside_down_bit":false]
setblock ~-17 ~ ~-3 minecraft:gray_wool
setblock ~-9 ~ ~-3 minecraft:gray_wool
setblock ~-17 ~ ~-10 minecraft:dark_oak_stairs["weirdo_direction":0,"upside_down_bit":false]
setblock ~-17 ~ ~-9 minecraft:dark_oak_stairs["weirdo_direction":0,"upside_down_bit":false]
setblock ~-17 ~ ~-8 minecraft:dark_oak_stairs["weirdo_direction":0,"upside_down_bit":false]
setblock ~-17 ~ ~-7 minecraft:dark_oak_stairs["weirdo_direction":0,"upside_down_bit":false]
setblock ~-17 ~ ~-6 minecraft:dark_oak_stairs["weirdo_direction":0,"upside_down_bit":false]
setblock ~-17 ~ ~-5 minecraft:dark_oak_stairs["weirdo_direction":0,"upside_down_bit":false]
setblock ~-17 ~ ~-4 minecraft:dark_oak_stairs["weirdo_direction":0,"upside_down_bit":false]
setblock ~-14 ~ ~-8 minecraft:dark_oak_fence
setblock ~-14 ~ ~-6 minecraft:dark_oak_fence
setblock ~-12 ~ ~-8 minecraft:dark_oak_fence
setblock ~-12 ~ ~-6 minecraft:dark_oak_fence
fill ~-14 ~1 ~-8 ~-12 ~1 ~-6 minecraft:quartz_slab
# Media wall
fill ~-17 ~1 ~-14 ~-9 ~6 ~-14 minecraft:black_concrete
fill ~-16 ~2 ~-14 ~-10 ~5 ~-14 myc:screen
fill ~-17 ~1 ~-14 ~-9 ~1 ~-14 minecraft:polished_blackstone_slab
setblock ~-17 ~2 ~-14 myc:control_panel
# Feature fireplace band and shelving
fill ~-18 ~1 ~-6 ~-18 ~3 ~-4 myc:clean_panel
setblock ~-18 ~1 ~-12 minecraft:bookshelf
setblock ~-18 ~1 ~-11 minecraft:chiseled_bookshelf
setblock ~-18 ~2 ~-12 minecraft:bookshelf
setblock ~-18 ~2 ~-11 minecraft:chiseled_bookshelf
setblock ~-18 ~3 ~-12 minecraft:bookshelf
setblock ~-18 ~3 ~-11 minecraft:chiseled_bookshelf
# Double-height lighting
setblock ~-16 ~14 ~-13 minecraft:sea_lantern
setblock ~-14 ~14 ~-13 minecraft:sea_lantern
setblock ~-12 ~14 ~-13 minecraft:sea_lantern
setblock ~-10 ~14 ~-13 minecraft:sea_lantern
setblock ~-9 ~9 ~-12 minecraft:lantern["hanging":true]
setblock ~-15 ~9 ~-12 minecraft:lantern["hanging":true]
setblock ~-9 ~9 ~-8 minecraft:lantern["hanging":true]
setblock ~-15 ~9 ~-8 minecraft:lantern["hanging":true]
setblock ~-9 ~9 ~-4 minecraft:lantern["hanging":true]
setblock ~-15 ~9 ~-4 minecraft:lantern["hanging":true]
setblock ~-16 ~6 ~-12 minecraft:redstone_lamp
setblock ~-13 ~6 ~-12 minecraft:redstone_lamp
setblock ~-10 ~6 ~-12 minecraft:redstone_lamp
setblock ~-17 ~4 ~-2 myc:alarm_light
# --- 09 designer kitchen + dining ---
fill ~8 ~-1 ~-20 ~18 ~-1 ~-1 minecraft:calcite
# Perimeter run
fill ~8 ~ ~-3 ~17 ~ ~-3 minecraft:warped_planks
fill ~8 ~1 ~-3 ~17 ~1 ~-3 minecraft:quartz_slab
fill ~17 ~ ~-10 ~17 ~ ~-3 minecraft:warped_planks
fill ~17 ~1 ~-10 ~17 ~1 ~-3 minecraft:quartz_slab
setblock ~12 ~ ~-3 minecraft:blast_furnace["minecraft:cardinal_direction":"south"]
setblock ~13 ~ ~-3 minecraft:smoker["minecraft:cardinal_direction":"south"]
setblock ~17 ~ ~-6 minecraft:furnace["minecraft:cardinal_direction":"west"]
setblock ~9 ~1 ~-3 minecraft:cauldron["cauldron_liquid":"water","fill_level":6]
setblock ~10 ~1 ~-3 minecraft:light_gray_stained_glass_pane
setblock ~12 ~1 ~-3 minecraft:light_gray_stained_glass_pane
setblock ~14 ~1 ~-3 minecraft:light_gray_stained_glass_pane
setblock ~16 ~1 ~-3 minecraft:light_gray_stained_glass_pane
# Island with breakfast bar
fill ~10 ~ ~-7 ~15 ~ ~-6 minecraft:polished_blackstone
fill ~10 ~1 ~-7 ~15 ~1 ~-6 minecraft:quartz_slab
setblock ~10 ~ ~-8 minecraft:dark_oak_stairs["weirdo_direction":3,"upside_down_bit":false]
setblock ~11 ~ ~-8 minecraft:dark_oak_stairs["weirdo_direction":3,"upside_down_bit":false]
setblock ~12 ~ ~-8 minecraft:dark_oak_stairs["weirdo_direction":3,"upside_down_bit":false]
setblock ~13 ~ ~-8 minecraft:dark_oak_stairs["weirdo_direction":3,"upside_down_bit":false]
setblock ~14 ~ ~-8 minecraft:dark_oak_stairs["weirdo_direction":3,"upside_down_bit":false]
setblock ~15 ~ ~-8 minecraft:dark_oak_stairs["weirdo_direction":3,"upside_down_bit":false]
setblock ~11 ~1 ~-7 minecraft:hopper
setblock ~14 ~1 ~-6 minecraft:crafting_table
# Tall units and pantry
fill ~8 ~ ~-2 ~8 ~3 ~-2 minecraft:warped_planks
fill ~9 ~ ~-2 ~9 ~3 ~-2 minecraft:warped_planks
fill ~10 ~ ~-2 ~10 ~3 ~-2 minecraft:warped_planks
fill ~11 ~ ~-2 ~11 ~3 ~-2 minecraft:warped_planks
setblock ~8 ~ ~-4 minecraft:barrel["facing_direction":3,"open_bit":false]
setblock ~9 ~ ~-4 minecraft:chest["minecraft:cardinal_direction":"south"]
# Dining area
setblock ~10 ~ ~-16 minecraft:dark_oak_fence
setblock ~10 ~ ~-13 minecraft:dark_oak_fence
setblock ~15 ~ ~-16 minecraft:dark_oak_fence
setblock ~15 ~ ~-13 minecraft:dark_oak_fence
fill ~10 ~1 ~-16 ~15 ~1 ~-13 minecraft:quartz_slab
setblock ~10 ~ ~-17 minecraft:dark_oak_stairs["weirdo_direction":3,"upside_down_bit":false]
setblock ~10 ~ ~-12 minecraft:dark_oak_stairs["weirdo_direction":2,"upside_down_bit":false]
setblock ~11 ~ ~-17 minecraft:dark_oak_stairs["weirdo_direction":3,"upside_down_bit":false]
setblock ~11 ~ ~-12 minecraft:dark_oak_stairs["weirdo_direction":2,"upside_down_bit":false]
setblock ~12 ~ ~-17 minecraft:dark_oak_stairs["weirdo_direction":3,"upside_down_bit":false]
setblock ~12 ~ ~-12 minecraft:dark_oak_stairs["weirdo_direction":2,"upside_down_bit":false]
setblock ~13 ~ ~-17 minecraft:dark_oak_stairs["weirdo_direction":3,"upside_down_bit":false]
setblock ~13 ~ ~-12 minecraft:dark_oak_stairs["weirdo_direction":2,"upside_down_bit":false]
setblock ~14 ~ ~-17 minecraft:dark_oak_stairs["weirdo_direction":3,"upside_down_bit":false]
setblock ~14 ~ ~-12 minecraft:dark_oak_stairs["weirdo_direction":2,"upside_down_bit":false]
setblock ~15 ~ ~-17 minecraft:dark_oak_stairs["weirdo_direction":3,"upside_down_bit":false]
setblock ~15 ~ ~-12 minecraft:dark_oak_stairs["weirdo_direction":2,"upside_down_bit":false]
fill ~9 ~ ~-18 ~16 ~ ~-11 minecraft:light_gray_carpet
setblock ~12 ~1 ~-14 minecraft:flower_pot
setblock ~13 ~1 ~-15 minecraft:decorated_pot
setblock ~9 ~6 ~-16 minecraft:sea_lantern
setblock ~12 ~6 ~-16 minecraft:sea_lantern
setblock ~15 ~6 ~-16 minecraft:sea_lantern
setblock ~9 ~6 ~-5 minecraft:redstone_lamp
setblock ~13 ~6 ~-5 minecraft:redstone_lamp
setblock ~12 ~5 ~-14 minecraft:lantern["hanging":true]
setblock ~12 ~5 ~-15 minecraft:lantern["hanging":true]
setblock ~17 ~4 ~-2 myc:alarm_light
# --- 10 guest bathroom + utility ---
fill ~-18 ~-1 ~-21 ~-12 ~-1 ~-16 minecraft:deepslate_tiles
fill ~-18 ~7 ~-21 ~-12 ~7 ~-16 minecraft:deepslate_tiles
fill ~-18 ~ ~-21 ~-12 ~6 ~-21 minecraft:light_gray_concrete
fill ~-18 ~ ~-16 ~-12 ~6 ~-16 minecraft:light_gray_concrete
fill ~-18 ~ ~-21 ~-18 ~6 ~-16 minecraft:light_gray_concrete
fill ~-12 ~ ~-21 ~-12 ~6 ~-16 minecraft:light_gray_concrete
fill ~-14 ~1 ~-16 ~-13 ~3 ~-16 minecraft:air
setblock ~-14 ~1 ~-16 minecraft:dark_oak_door["direction":2,"door_hinge_bit":false,"open_bit":false,"upper_block_bit":false]
setblock ~-14 ~2 ~-16 minecraft:dark_oak_door["direction":2,"door_hinge_bit":false,"open_bit":false,"upper_block_bit":true]
# Sanitary ware from blocks
setblock ~-17 ~ ~-20 minecraft:cauldron["cauldron_liquid":"water","fill_level":6]
setblock ~-17 ~1 ~-18 minecraft:quartz_slab
setblock ~-16 ~1 ~-18 minecraft:light_gray_stained_glass_pane
setblock ~-13 ~ ~-20 minecraft:quartz_stairs["weirdo_direction":1,"upside_down_bit":false]
setblock ~-13 ~1 ~-20 minecraft:trapdoor["direction":1,"open_bit":false,"upside_down_bit":false]
fill ~-15 ~ ~-20 ~-14 ~2 ~-20 minecraft:white_stained_glass
setblock ~-17 ~3 ~-19 minecraft:sea_lantern
setblock ~-14 ~4 ~-17 minecraft:redstone_lamp
# Utility / plant room
fill ~-18 ~-1 ~-25 ~-13 ~-1 ~-22 minecraft:deepslate_tiles
fill ~-18 ~7 ~-25 ~-13 ~7 ~-22 minecraft:deepslate_tiles
fill ~-18 ~ ~-25 ~-13 ~6 ~-25 minecraft:light_gray_concrete
fill ~-18 ~ ~-22 ~-13 ~6 ~-22 minecraft:light_gray_concrete
fill ~-18 ~ ~-25 ~-18 ~6 ~-22 minecraft:light_gray_concrete
fill ~-13 ~ ~-25 ~-13 ~6 ~-22 minecraft:light_gray_concrete
fill ~-16 ~1 ~-22 ~-15 ~3 ~-22 minecraft:air
setblock ~-17 ~ ~-24 minecraft:barrel["facing_direction":1,"open_bit":false]
setblock ~-16 ~ ~-24 minecraft:barrel["facing_direction":1,"open_bit":false]
setblock ~-15 ~ ~-24 minecraft:barrel["facing_direction":1,"open_bit":false]
setblock ~-14 ~ ~-24 minecraft:barrel["facing_direction":1,"open_bit":false]
setblock ~-17 ~ ~-23 minecraft:chest["minecraft:cardinal_direction":"south"]
setblock ~-15 ~1 ~-24 myc:control_panel
setblock ~-15 ~4 ~-22 myc:alarm_light
# Rear hall linking garden door to the main hall
