# part_72.mcfunction - generated by tools/gen_mansion.py, do not edit
# Relative coordinates only; run via execute positioned <x> <y> <z>
# (continued: 01 foundation + substructure excavation)
fill ~-13 ~-21 ~-19 ~13 ~-16 ~-5 minecraft:air
# Basement and bunker floor finishes
fill ~-16 ~-10 ~-24 ~16 ~-10 ~-3 minecraft:deepslate_tiles
fill ~-13 ~-22 ~-19 ~13 ~-22 ~-5 minecraft:deepslate_tiles
# --- 02 ground floor shell ---
fill ~-19 ~-1 ~-27 ~19 ~-1 ~ minecraft:quartz_block
fill ~-19 ~ ~-27 ~19 ~6 ~-27 minecraft:white_concrete
fill ~-19 ~ ~ ~19 ~6 ~ minecraft:white_concrete
fill ~-19 ~ ~-27 ~-19 ~6 ~ minecraft:white_concrete
fill ~19 ~ ~-27 ~19 ~6 ~ minecraft:white_concrete
fill ~-19 ~7 ~-27 ~19 ~7 ~ minecraft:polished_deepslate
# Corner piers
fill ~-19 ~ ~-27 ~-19 ~6 ~-27 minecraft:quartz_block["chisel_type":"lines"]
setblock ~-19 ~7 ~-27 minecraft:polished_blackstone_slab
fill ~-19 ~ ~ ~-19 ~6 ~ minecraft:quartz_block["chisel_type":"lines"]
setblock ~-19 ~7 ~ minecraft:polished_blackstone_slab
fill ~19 ~ ~-27 ~19 ~6 ~-27 minecraft:quartz_block["chisel_type":"lines"]
setblock ~19 ~7 ~-27 minecraft:polished_blackstone_slab
fill ~19 ~ ~ ~19 ~6 ~ minecraft:quartz_block["chisel_type":"lines"]
setblock ~19 ~7 ~ minecraft:polished_blackstone_slab
# Main entrance portal - PURE AIR, registered as a lockdown seal
fill ~-4 ~ ~ ~4 ~5 ~ minecraft:air
# Entrance reveal and threshold
fill ~-5 ~ ~ ~-5 ~5 ~ minecraft:polished_blackstone
fill ~5 ~ ~ ~5 ~5 ~ minecraft:polished_blackstone
fill ~-4 ~-1 ~ ~4 ~-1 ~ minecraft:deepslate_tiles
fill ~-4 ~6 ~ ~4 ~6 ~ myc:clean_panel
# --- 03 ground floor curtain walls ---
# West and east elevations - full-height glazing between piers
fill ~-19 ~1 ~-24 ~-19 ~5 ~-3 minecraft:light_blue_stained_glass
fill ~-19 ~1 ~-24 ~-19 ~5 ~-24 minecraft:polished_blackstone
fill ~-19 ~1 ~-20 ~-19 ~5 ~-20 minecraft:polished_blackstone
fill ~-19 ~1 ~-16 ~-19 ~5 ~-16 minecraft:polished_blackstone
fill ~-19 ~1 ~-12 ~-19 ~5 ~-12 minecraft:polished_blackstone
fill ~-19 ~1 ~-8 ~-19 ~5 ~-8 minecraft:polished_blackstone
fill ~-19 ~1 ~-4 ~-19 ~5 ~-4 minecraft:polished_blackstone
fill ~19 ~1 ~-24 ~19 ~5 ~-3 minecraft:light_blue_stained_glass
fill ~19 ~1 ~-24 ~19 ~5 ~-24 minecraft:polished_blackstone
fill ~19 ~1 ~-20 ~19 ~5 ~-20 minecraft:polished_blackstone
fill ~19 ~1 ~-16 ~19 ~5 ~-16 minecraft:polished_blackstone
fill ~19 ~1 ~-12 ~19 ~5 ~-12 minecraft:polished_blackstone
fill ~19 ~1 ~-8 ~19 ~5 ~-8 minecraft:polished_blackstone
fill ~19 ~1 ~-4 ~19 ~5 ~-4 minecraft:polished_blackstone
# North (rear) elevation glazing, split by the garden door
fill ~-17 ~1 ~-27 ~-4 ~5 ~-27 minecraft:light_blue_stained_glass
fill ~-17 ~1 ~-27 ~-17 ~5 ~-27 minecraft:polished_blackstone
fill ~-13 ~1 ~-27 ~-13 ~5 ~-27 minecraft:polished_blackstone
fill ~-9 ~1 ~-27 ~-9 ~5 ~-27 minecraft:polished_blackstone
fill ~-5 ~1 ~-27 ~-5 ~5 ~-27 minecraft:polished_blackstone
fill ~4 ~1 ~-27 ~17 ~5 ~-27 minecraft:light_blue_stained_glass
fill ~4 ~1 ~-27 ~4 ~5 ~-27 minecraft:polished_blackstone
fill ~8 ~1 ~-27 ~8 ~5 ~-27 minecraft:polished_blackstone
fill ~12 ~1 ~-27 ~12 ~5 ~-27 minecraft:polished_blackstone
fill ~16 ~1 ~-27 ~16 ~5 ~-27 minecraft:polished_blackstone
# Garden door opening - PURE AIR, seal
fill ~-3 ~ ~-27 ~3 ~4 ~-27 minecraft:air
fill ~-4 ~ ~-27 ~-4 ~4 ~-27 minecraft:polished_blackstone
fill ~4 ~ ~-27 ~4 ~4 ~-27 minecraft:polished_blackstone
# Front elevation glazing either side of the entrance
fill ~-17 ~1 ~ ~-6 ~5 ~ minecraft:light_blue_stained_glass
fill ~-17 ~1 ~ ~-17 ~5 ~ minecraft:polished_blackstone
fill ~-13 ~1 ~ ~-13 ~5 ~ minecraft:polished_blackstone
fill ~-9 ~1 ~ ~-9 ~5 ~ minecraft:polished_blackstone
fill ~6 ~1 ~ ~17 ~5 ~ minecraft:light_blue_stained_glass
fill ~6 ~1 ~ ~6 ~5 ~ minecraft:polished_blackstone
fill ~10 ~1 ~ ~10 ~5 ~ minecraft:polished_blackstone
fill ~14 ~1 ~ ~14 ~5 ~ minecraft:polished_blackstone
# Pool-side door on the east elevation - PURE AIR, seal
fill ~19 ~ ~-8 ~19 ~4 ~-4 minecraft:air
fill ~19 ~ ~-9 ~19 ~4 ~-9 minecraft:polished_blackstone
fill ~19 ~ ~-3 ~19 ~4 ~-3 minecraft:polished_blackstone
# --- 04 first floor shell ---
fill ~-19 ~7 ~-27 ~19 ~7 ~ minecraft:dark_oak_planks
fill ~-19 ~8 ~-27 ~19 ~14 ~-27 minecraft:white_concrete
fill ~-19 ~8 ~ ~19 ~14 ~ minecraft:white_concrete
fill ~-19 ~8 ~-27 ~-19 ~14 ~ minecraft:white_concrete
fill ~19 ~8 ~-27 ~19 ~14 ~ minecraft:white_concrete
fill ~-19 ~15 ~-27 ~19 ~15 ~ minecraft:polished_deepslate
fill ~-19 ~9 ~-24 ~-19 ~12 ~-3 minecraft:light_blue_stained_glass
fill ~-19 ~9 ~-24 ~-19 ~12 ~-24 minecraft:polished_blackstone
fill ~-19 ~9 ~-20 ~-19 ~12 ~-20 minecraft:polished_blackstone
fill ~-19 ~9 ~-16 ~-19 ~12 ~-16 minecraft:polished_blackstone
fill ~-19 ~9 ~-12 ~-19 ~12 ~-12 minecraft:polished_blackstone
fill ~-19 ~9 ~-8 ~-19 ~12 ~-8 minecraft:polished_blackstone
fill ~-19 ~9 ~-4 ~-19 ~12 ~-4 minecraft:polished_blackstone
fill ~19 ~9 ~-24 ~19 ~12 ~-3 minecraft:light_blue_stained_glass
fill ~19 ~9 ~-24 ~19 ~12 ~-24 minecraft:polished_blackstone
fill ~19 ~9 ~-20 ~19 ~12 ~-20 minecraft:polished_blackstone
fill ~19 ~9 ~-16 ~19 ~12 ~-16 minecraft:polished_blackstone
fill ~19 ~9 ~-12 ~19 ~12 ~-12 minecraft:polished_blackstone
fill ~19 ~9 ~-8 ~19 ~12 ~-8 minecraft:polished_blackstone
fill ~19 ~9 ~-4 ~19 ~12 ~-4 minecraft:polished_blackstone
fill ~-17 ~9 ~-27 ~17 ~12 ~-27 minecraft:light_blue_stained_glass
fill ~-17 ~9 ~-27 ~-17 ~12 ~-27 minecraft:polished_blackstone
fill ~-13 ~9 ~-27 ~-13 ~12 ~-27 minecraft:polished_blackstone
fill ~-9 ~9 ~-27 ~-9 ~12 ~-27 minecraft:polished_blackstone
fill ~-5 ~9 ~-27 ~-5 ~12 ~-27 minecraft:polished_blackstone
fill ~-1 ~9 ~-27 ~-1 ~12 ~-27 minecraft:polished_blackstone
fill ~3 ~9 ~-27 ~3 ~12 ~-27 minecraft:polished_blackstone
fill ~7 ~9 ~-27 ~7 ~12 ~-27 minecraft:polished_blackstone
fill ~11 ~9 ~-27 ~11 ~12 ~-27 minecraft:polished_blackstone
fill ~15 ~9 ~-27 ~15 ~12 ~-27 minecraft:polished_blackstone
fill ~-17 ~9 ~ ~-6 ~12 ~ minecraft:light_blue_stained_glass
fill ~-17 ~9 ~ ~-17 ~12 ~ minecraft:polished_blackstone
fill ~-13 ~9 ~ ~-13 ~12 ~ minecraft:polished_blackstone
fill ~-9 ~9 ~ ~-9 ~12 ~ minecraft:polished_blackstone
fill ~6 ~9 ~ ~17 ~12 ~ minecraft:light_blue_stained_glass
fill ~6 ~9 ~ ~6 ~12 ~ minecraft:polished_blackstone
fill ~10 ~9 ~ ~10 ~12 ~ minecraft:polished_blackstone
fill ~14 ~9 ~ ~14 ~12 ~ minecraft:polished_blackstone
# Balcony doors onto the front terrace (interior, not sealed)
fill ~-4 ~8 ~ ~4 ~11 ~ minecraft:air
# --- 05 second floor shell ---
